Workbook

Sheet Credit Summary & Memo
B2: Al Rajhi Bank (RJHI) — Bank Credit & Capital Model
B3: Banking Sector | Country: Saudi Arabia | Rating: A1 / A- | Benchmark: RAJHI 4.75% 2029 @ $100.80 (4.75% YTM / +55 bp)
B5: I. BANKING SECTOR CREDIT THESIS
B6: World's largest Islamic retail bank; sub-1% cost of funds; 68% salary-assigned retail mortgages; ROE >20%.
B9: II. KEY BANKING METRICS (USD M / %)
B10: Metric | C10: 2021A | D10: 2022A | E10: 2023A | F10: 2024A | G10: 2025E | H10: 2026E | I10: 2027E
B11: Total Consolidated Assets | C11: ='Balance Sheet & Funding'!C13 | D11: ='Balance Sheet & Funding'!D13 | E11: ='Balance Sheet & Funding'!E13 | F11: ='Balance Sheet & Funding'!F13 | G11: ='Balance Sheet & Funding'!G13 | H11: ='Balance Sheet & Funding'!H13 | I11: ='Balance Sheet & Funding'!I13
B12: Gross Customer Loans | C12: ='Balance Sheet & Funding'!C10 | D12: ='Balance Sheet & Funding'!D10 | E12: ='Balance Sheet & Funding'!E10 | F12: ='Balance Sheet & Funding'!F10 | G12: ='Balance Sheet & Funding'!G10 | H12: ='Balance Sheet & Funding'!H10 | I12: ='Balance Sheet & Funding'!I10
B13: Customer Deposits | C13: ='Balance Sheet & Funding'!C16 | D13: ='Balance Sheet & Funding'!D16 | E13: ='Balance Sheet & Funding'!E16 | F13: ='Balance Sheet & Funding'!F16 | G13: ='Balance Sheet & Funding'!G16 | H13: ='Balance Sheet & Funding'!H16 | I13: ='Balance Sheet & Funding'!I16
B14: Net Interest Income (NII) | C14: ='Bank Income Statement (P&L)'!C10 | D14: ='Bank Income Statement (P&L)'!D10 | E14: ='Bank Income Statement (P&L)'!E10 | F14: ='Bank Income Statement (P&L)'!F10 | G14: ='Bank Income Statement (P&L)'!G10 | H14: ='Bank Income Statement (P&L)'!H10 | I14: ='Bank Income Statement (P&L)'!I10
B15: Net Interest Margin (NIM %) | C15: ='Bank Income Statement (P&L)'!C11 | D15: ='Bank Income Statement (P&L)'!D11 | E15: ='Bank Income Statement (P&L)'!E11 | F15: ='Bank Income Statement (P&L)'!F11 | G15: ='Bank Income Statement (P&L)'!G11 | H15: ='Bank Income Statement (P&L)'!H11 | I15: ='Bank Income Statement (P&L)'!I11
B16: Cost-to-Income Ratio (CIR %) | C16: ='Bank Income Statement (P&L)'!C16 | D16: ='Bank Income Statement (P&L)'!D16 | E16: ='Bank Income Statement (P&L)'!E16 | F16: ='Bank Income Statement (P&L)'!F16 | G16: ='Bank Income Statement (P&L)'!G16 | H16: ='Bank Income Statement (P&L)'!H16 | I16: ='Bank Income Statement (P&L)'!I16
B17: Net Profit (Attributable) | C17: ='Bank Income Statement (P&L)'!C21 | D17: ='Bank Income Statement (P&L)'!D21 | E17: ='Bank Income Statement (P&L)'!E21 | F17: ='Bank Income Statement (P&L)'!F21 | G17: ='Bank Income Statement (P&L)'!G21 | H17: ='Bank Income Statement (P&L)'!H21 | I17: ='Bank Income Statement (P&L)'!I21
B18: Return on Equity (ROE %) | C18: ='Bank Income Statement (P&L)'!C22 | D18: ='Bank Income Statement (P&L)'!D22 | E18: ='Bank Income Statement (P&L)'!E22 | F18: ='Bank Income Statement (P&L)'!F22 | G18: ='Bank Income Statement (P&L)'!G22 | H18: ='Bank Income Statement (P&L)'!H22 | I18: ='Bank Income Statement (P&L)'!I22
B19: Non-Performing Loan (NPL) Ratio | C19: ='Loan Portfolio & Quality'!C12 | D19: ='Loan Portfolio & Quality'!D12 | E19: ='Loan Portfolio & Quality'!E12 | F19: ='Loan Portfolio & Quality'!F12 | G19: ='Loan Portfolio & Quality'!G12 | H19: ='Loan Portfolio & Quality'!H12 | I19: ='Loan Portfolio & Quality'!I12
B20: Provision Coverage Ratio (%) | C20: ='Loan Portfolio & Quality'!C14 | D20: ='Loan Portfolio & Quality'!D14 | E20: ='Loan Portfolio & Quality'!E14 | F20: ='Loan Portfolio & Quality'!F14 | G20: ='Loan Portfolio & Quality'!G14 | H20: ='Loan Portfolio & Quality'!H14 | I20: ='Loan Portfolio & Quality'!I14
B21: Capital Adequacy Ratio (CAR %) | C21: ='Capital & Liquidity Schedule'!C10 | D21: ='Capital & Liquidity Schedule'!D10 | E21: ='Capital & Liquidity Schedule'!E10 | F21: ='Capital & Liquidity Schedule'!F10 | G21: ='Capital & Liquidity Schedule'!G10 | H21: ='Capital & Liquidity Schedule'!H10 | I21: ='Capital & Liquidity Schedule'!I10
B22: Common Equity Tier 1 (CET1 %) | C22: ='Capital & Liquidity Schedule'!C7 | D22: ='Capital & Liquidity Schedule'!D7 | E22: ='Capital & Liquidity Schedule'!E7 | F22: ='Capital & Liquidity Schedule'!F7 | G22: ='Capital & Liquidity Schedule'!G7 | H22: ='Capital & Liquidity Schedule'!H7 | I22: ='Capital & Liquidity Schedule'!I7

Sheet Loan Portfolio & Quality
B2: Al Rajhi Bank — Loan Portfolio & Asset Quality
B4: Line Item (USD Millions) | C4: 2021A | D4: 2022A | E4: 2023A | F4: 2024A | G4: 2025E | H4: 2026E | I4: 2027E
B6: I. GROSS LOANS BY LENDING SEGMENT
B7: Corporate & Institutional Banking | C7: 60830 | D7: 71258 | E7: 79948 | F7: 86900 | G7: 93852 | H7: 100804 | I7: 106887
B8: Retail & Consumer Mortgages | C8: 33180 | D8: 38868 | E8: 43608 | F8: 47400 | G8: 51192 | H8: 54984 | I8: 58302
B9: SME & Commercial Enterprise | C9: 16590 | D9: 19434 | E9: 21804 | F9: 23700 | G9: 25596 | H9: 27492 | I9: 29151
B10: Total Gross Loans (Feeds Balance Sheet) | C10: =SUM(C7:C9) | D10: =SUM(D7:D9) | E10: =SUM(E7:E9) | F10: =SUM(F7:F9) | G10: =SUM(G7:G9) | H10: =SUM(H7:H9) | I10: =SUM(I7:I9)
B11: II. ASSET QUALITY & PROVISIONING METRICS
B12: Non-Performing Loans (NPL Ratio %) | C12: 0.009 | D12: 0.009 | E12: 0.009 | F12: 0.009 | G12: 0.009 | H12: 0.009 | I12: 0.009
B13: Total Impaired NPL Volume ($M) | C13: =C10 * C12 | D13: =D10 * D12 | E13: =E10 * E12 | F13: =F10 * F12 | G13: =G10 * G12 | H13: =H10 * H12 | I13: =I10 * I12
B14: Provision Coverage Ratio (%) | C14: 1.35 | D14: 1.35 | E14: 1.35 | F14: 1.35 | G14: 1.35 | H14: 1.35 | I14: 1.35
B15: Accumulated Allowance for Loan Losses ($M) | C15: =C13 * C14 | D15: =D13 * D14 | E15: =E13 * E14 | F15: =F13 * F14 | G15: =G13 * G14 | H15: =H13 * H14 | I15: =I13 * I14

Sheet Bank Income Statement (P&L)
B2: Al Rajhi Bank — Audited & Projected Bank P&L
B4: P&L Line Item (USD Millions) | C4: 2021A | D4: 2022A | E4: 2023A | F4: 2024A | G4: 2025E | H4: 2026E | I4: 2027E
B8: Gross Interest Income (Loans & Securities) | C8: ='Balance Sheet & Funding'!C13 * 0.078 | D8: ='Balance Sheet & Funding'!D13 * 0.078 | E8: ='Balance Sheet & Funding'!E13 * 0.078 | F8: ='Balance Sheet & Funding'!F13 * 0.078 | G8: ='Balance Sheet & Funding'!G13 * 0.078 | H8: ='Balance Sheet & Funding'!H13 * 0.078 | I8: ='Balance Sheet & Funding'!I13 * 0.078
B9: Less: Interest Expense (Deposits & Borrowings) | C9: ='Balance Sheet & Funding'!C16 * 0.038 | D9: ='Balance Sheet & Funding'!D16 * 0.038 | E9: ='Balance Sheet & Funding'!E16 * 0.038 | F9: ='Balance Sheet & Funding'!F16 * 0.038 | G9: ='Balance Sheet & Funding'!G16 * 0.038 | H9: ='Balance Sheet & Funding'!H16 * 0.038 | I9: ='Balance Sheet & Funding'!I16 * 0.038
B10: NET INTEREST INCOME (NII) | C10: =C8 - C9 | D10: =D8 - D9 | E10: =E8 - E9 | F10: =F8 - F9 | G10: =G8 - G9 | H10: =H8 - H9 | I10: =I8 - I9
B11: Net Interest Margin (NIM %) | C11: =C10 / 'Balance Sheet & Funding'!C13 | D11: =D10 / 'Balance Sheet & Funding'!D13 | E11: =E10 / 'Balance Sheet & Funding'!E13 | F11: =F10 / 'Balance Sheet & Funding'!F13 | G11: =G10 / 'Balance Sheet & Funding'!G13 | H11: =H10 / 'Balance Sheet & Funding'!H13 | I11: =I10 / 'Balance Sheet & Funding'!I13
B12: Net Fee & Commission Income | C12: =C10 * 0.28 | D12: =D10 * 0.28 | E12: =E10 * 0.28 | F12: =F10 * 0.28 | G12: =G10 * 0.28 | H12: =H10 * 0.28 | I12: =I10 * 0.28
B13: Trading & Foreign Exchange Gains | C13: =C10 * 0.12 | D13: =D10 * 0.12 | E13: =E10 * 0.12 | F13: =F10 * 0.12 | G13: =G10 * 0.12 | H13: =H10 * 0.12 | I13: =I10 * 0.12
B14: Other Operating Income | C14: =C10 * 0.05 | D14: =D10 * 0.05 | E14: =E10 * 0.05 | F14: =F10 * 0.05 | G14: =G10 * 0.05 | H14: =H10 * 0.05 | I14: =I10 * 0.05
B15: TOTAL OPERATING INCOME | C15: =SUM(C10:C14) | D15: =SUM(D10:D14) | E15: =SUM(E10:E14) | F15: =SUM(F10:F14) | G15: =SUM(G10:G14) | H15: =SUM(H10:H14) | I15: =SUM(I10:I14)
B16: Cost-to-Income Ratio (CIR %) | C16: =C17 / C15 | D16: =D17 / D15 | E16: =E17 / E15 | F16: =F17 / F15 | G16: =G17 / G15 | H16: =H17 / H15 | I16: =I17 / I15
B17: Operating Overhead & Staff Expenses | C17: =C15 * 0.36 | D17: =D15 * 0.36 | E17: =E15 * 0.36 | F17: =F15 * 0.36 | G17: =G15 * 0.36 | H17: =H15 * 0.36 | I17: =I15 * 0.36
B18: OPERATING PROFIT BEFORE PROVISIONS | C18: =C15 - C17 | D18: =D15 - D17 | E18: =E15 - E17 | F18: =F15 - F17 | G18: =G15 - G17 | H18: =H15 - H17 | I18: =I15 - I17
B19: Less: Credit Impairment Provisions | C19: ='Loan Portfolio & Quality'!C10 * 0.008 | D19: ='Loan Portfolio & Quality'!D10 * 0.008 | E19: ='Loan Portfolio & Quality'!E10 * 0.008 | F19: ='Loan Portfolio & Quality'!F10 * 0.008 | G19: ='Loan Portfolio & Quality'!G10 * 0.008 | H19: ='Loan Portfolio & Quality'!H10 * 0.008 | I19: ='Loan Portfolio & Quality'!I10 * 0.008
B20: Profit Before Tax (PBT) | C20: =C18 - C19 | D20: =D18 - D19 | E20: =E18 - E19 | F20: =F18 - F19 | G20: =G18 - G19 | H20: =H18 - H19 | I20: =I18 - I19
B21: Income Tax Expense | C21: =IF(C20>0, C20 * 0.15, 0) | D21: =IF(D20>0, D20 * 0.15, 0) | E21: =IF(E20>0, E20 * 0.15, 0) | F21: =IF(F20>0, F20 * 0.15, 0) | G21: =IF(G20>0, G20 * 0.15, 0) | H21: =IF(H20>0, H20 * 0.15, 0) | I21: =IF(I20>0, I20 * 0.15, 0)
B22: NET PROFIT (ATTRIBUTABLE) | C22: =C20 - C21 | D22: =D20 - D21 | E22: =E20 - E21 | F22: =F20 - F21 | G22: =G20 - G21 | H22: =H20 - H21 | I22: =I20 - I21
B23: Return on Equity (ROE %) | C23: =C22 / 'Balance Sheet & Funding'!C22 | D23: =D22 / 'Balance Sheet & Funding'!D22 | E23: =E22 / 'Balance Sheet & Funding'!E22 | F23: =F22 / 'Balance Sheet & Funding'!F22 | G23: =G22 / 'Balance Sheet & Funding'!G22 | H23: =H22 / 'Balance Sheet & Funding'!H22 | I23: =I22 / 'Balance Sheet & Funding'!I22

Sheet Balance Sheet & Funding
B2: Al Rajhi Bank — Bank Balance Sheet & Capital
B4: Line Item (USD Millions) | C4: 2021A | D4: 2022A | E4: 2023A | F4: 2024A | G4: 2025E | H4: 2026E | I4: 2027E
B6: I. ASSETS
B7: Cash & Central Bank Balances | C7: ='Loan Portfolio & Quality'!C10 * 0.12 | D7: ='Loan Portfolio & Quality'!D10 * 0.12 | E7: ='Loan Portfolio & Quality'!E10 * 0.12 | F7: ='Loan Portfolio & Quality'!F10 * 0.12 | G7: ='Loan Portfolio & Quality'!G10 * 0.12 | H7: ='Loan Portfolio & Quality'!H10 * 0.12 | I7: ='Loan Portfolio & Quality'!I10 * 0.12
B8: Interbank Placements & Repos | C8: ='Loan Portfolio & Quality'!C10 * 0.08 | D8: ='Loan Portfolio & Quality'!D10 * 0.08 | E8: ='Loan Portfolio & Quality'!E10 * 0.08 | F8: ='Loan Portfolio & Quality'!F10 * 0.08 | G8: ='Loan Portfolio & Quality'!G10 * 0.08 | H8: ='Loan Portfolio & Quality'!H10 * 0.08 | I8: ='Loan Portfolio & Quality'!I10 * 0.08
B9: Investment Securities (Sovereign & Bonds) | C9: ='Loan Portfolio & Quality'!C10 * 0.28 | D9: ='Loan Portfolio & Quality'!D10 * 0.28 | E9: ='Loan Portfolio & Quality'!E10 * 0.28 | F9: ='Loan Portfolio & Quality'!F10 * 0.28 | G9: ='Loan Portfolio & Quality'!G10 * 0.28 | H9: ='Loan Portfolio & Quality'!H10 * 0.28 | I9: ='Loan Portfolio & Quality'!I10 * 0.28
B10: Gross Customer Loans | C10: ='Loan Portfolio & Quality'!C10 | D10: ='Loan Portfolio & Quality'!D10 | E10: ='Loan Portfolio & Quality'!E10 | F10: ='Loan Portfolio & Quality'!F10 | G10: ='Loan Portfolio & Quality'!G10 | H10: ='Loan Portfolio & Quality'!H10 | I10: ='Loan Portfolio & Quality'!I10
B11: Less: Allowance for Credit Losses | C11: =-'Loan Portfolio & Quality'!C15 | D11: =-'Loan Portfolio & Quality'!D15 | E11: =-'Loan Portfolio & Quality'!E15 | F11: =-'Loan Portfolio & Quality'!F15 | G11: =-'Loan Portfolio & Quality'!G15 | H11: =-'Loan Portfolio & Quality'!H15 | I11: =-'Loan Portfolio & Quality'!I15
B12: Net Customer Loans | C12: =C10 + C11 | D12: =D10 + D11 | E12: =E10 + E11 | F12: =F10 + F11 | G12: =G10 + G11 | H12: =H10 + H11 | I12: =I10 + I11
B13: TOTAL CONSOLIDATED ASSETS | C13: =SUM(C7:C9) + C12 | D13: =SUM(D7:D9) + D12 | E13: =SUM(E7:E9) + E12 | F13: =SUM(F7:F9) + F12 | G13: =SUM(G7:G9) + G12 | H13: =SUM(H7:H9) + H12 | I13: =SUM(I7:I9) + I12
B15: II. LIABILITIES & FUNDING
B16: Customer Deposits (CASA & Term) | C16: =C13 * 0.72 | D16: =D13 * 0.72 | E16: =E13 * 0.72 | F16: =F13 * 0.72 | G16: =G13 * 0.72 | H16: =H13 * 0.72 | I16: =I13 * 0.72
B17: Interbank Borrowings & Repos | C17: =C13 * 0.06 | D17: =D13 * 0.06 | E17: =E13 * 0.06 | F17: =F13 * 0.06 | G17: =G13 * 0.06 | H17: =H13 * 0.06 | I17: =I13 * 0.06
B18: Senior Debt Securities in Issue (Eurobonds) | C18: =C13 * 0.07 | D18: =D13 * 0.07 | E18: =E13 * 0.07 | F18: =F13 * 0.07 | G18: =G13 * 0.07 | H18: =H13 * 0.07 | I18: =I13 * 0.07
B19: Subordinated / Tier 2 Debt Notes | C19: =C13 * 0.02 | D19: =D13 * 0.02 | E19: =E13 * 0.02 | F19: =F13 * 0.02 | G19: =G13 * 0.02 | H19: =H13 * 0.02 | I19: =I13 * 0.02
B20: TOTAL LIABILITIES | C20: =SUM(C16:C19) | D20: =SUM(D16:D19) | E20: =SUM(E16:E19) | F20: =SUM(F16:F19) | G20: =SUM(G16:G19) | H20: =SUM(H16:H19) | I20: =SUM(I16:I19)
B21: III. EQUITY & CAPITAL
B22: TOTAL SHAREHOLDERS' EQUITY | C22: =C13 - C20 | D22: =D13 - D20 | E22: =E13 - E20 | F22: =F13 - F20 | G22: =G13 - G20 | H22: =H13 - H20 | I22: =I13 - I20
B23: TOTAL LIABILITIES & EQUITY | C23: =C20 + C22 | D23: =D20 + D22 | E23: =E20 + E22 | F23: =F20 + F22 | G23: =G20 + G22 | H23: =H20 + H22 | I23: =I20 + I22
B24: BALANCE CHECK (ASSETS - LIAB - EQUITY) | C24: =C13 - C23 | D24: =D13 - D23 | E24: =E13 - E23 | F24: =F13 - F23 | G24: =G13 - G23 | H24: =H13 - H23 | I24: =I13 - I23

Sheet Capital & Liquidity Schedule
B2: Al Rajhi Bank — Capital Adequacy & Basel III Ratios
B4: Basel III Capital Metric | C4: 2021A | D4: 2022A | E4: 2023A | F4: 2024A | G4: 2025E | H4: 2026E | I4: 2027E
B5: Risk-Weighted Assets (RWA $M) | C5: ='Balance Sheet & Funding'!C13 * 0.70 | D5: ='Balance Sheet & Funding'!D13 * 0.70 | E5: ='Balance Sheet & Funding'!E13 * 0.70 | F5: ='Balance Sheet & Funding'!F13 * 0.70 | G5: ='Balance Sheet & Funding'!G13 * 0.70 | H5: ='Balance Sheet & Funding'!H13 * 0.70 | I5: ='Balance Sheet & Funding'!I13 * 0.70
B6: Common Equity Tier 1 (CET1 Capital $M) | C6: ='Balance Sheet & Funding'!C22 * 0.88 | D6: ='Balance Sheet & Funding'!D22 * 0.88 | E6: ='Balance Sheet & Funding'!E22 * 0.88 | F6: ='Balance Sheet & Funding'!F22 * 0.88 | G6: ='Balance Sheet & Funding'!G22 * 0.88 | H6: ='Balance Sheet & Funding'!H22 * 0.88 | I6: ='Balance Sheet & Funding'!I22 * 0.88
B7: COMMON EQUITY TIER 1 RATIO (CET1 %) | C7: =C6 / C5 | D7: =D6 / D5 | E7: =E6 / E5 | F7: =F6 / F5 | G7: =G6 / G5 | H7: =H6 / H5 | I7: =I6 / I5
B8: Tier 1 Capital Notes & Hybrids ($M) | C8: ='Balance Sheet & Funding'!C22 * 0.12 | D8: ='Balance Sheet & Funding'!D22 * 0.12 | E8: ='Balance Sheet & Funding'!E22 * 0.12 | F8: ='Balance Sheet & Funding'!F22 * 0.12 | G8: ='Balance Sheet & Funding'!G22 * 0.12 | H8: ='Balance Sheet & Funding'!H22 * 0.12 | I8: ='Balance Sheet & Funding'!I22 * 0.12
B9: Tier 2 Subordinated Capital ($M) | C9: ='Balance Sheet & Funding'!C19 | D9: ='Balance Sheet & Funding'!D19 | E9: ='Balance Sheet & Funding'!E19 | F9: ='Balance Sheet & Funding'!F19 | G9: ='Balance Sheet & Funding'!G19 | H9: ='Balance Sheet & Funding'!H19 | I9: ='Balance Sheet & Funding'!I19
B10: TOTAL REGULATORY CAPITAL RATIO (CAR %) | C10: =(C6 + C8 + C9) / C5 | D10: =(D6 + D8 + D9) / D5 | E10: =(E6 + E8 + E9) / E5 | F10: =(F6 + F8 + F9) / F5 | G10: =(G6 + G8 + G9) / G5 | H10: =(H6 + H8 + H9) / H5 | I10: =(I6 + I8 + I9) / I5
B11: Liquidity Coverage Ratio (LCR %) | C11: 1.65 | D11: 1.65 | E11: 1.65 | F11: 1.65 | G11: 1.65 | H11: 1.65 | I11: 1.65
B12: Net Stable Funding Ratio (NSFR %) | C12: 1.28 | D12: 1.28 | E12: 1.28 | F12: 1.28 | G12: 1.28 | H12: 1.28 | I12: 1.28
B13: Loan-to-Deposit Ratio (LDR %) | C13: ='Balance Sheet & Funding'!C10 / 'Balance Sheet & Funding'!C16 | D13: ='Balance Sheet & Funding'!D10 / 'Balance Sheet & Funding'!D16 | E13: ='Balance Sheet & Funding'!E10 / 'Balance Sheet & Funding'!E16 | F13: ='Balance Sheet & Funding'!F10 / 'Balance Sheet & Funding'!F16 | G13: ='Balance Sheet & Funding'!G10 / 'Balance Sheet & Funding'!G16 | H13: ='Balance Sheet & Funding'!H10 / 'Balance Sheet & Funding'!H16 | I13: ='Balance Sheet & Funding'!I10 / 'Balance Sheet & Funding'!I16
B16: II. CAPITAL STRUCTURE & REGULATORY CAPITAL TRANCHES
B17: Tranche / Capital Instrument Name | C17: Instrument Type | D17: Ccy | E17: Outstanding ($M) | F17: Coupon / Spread | G17: Clean Price | H17: YTM (%) | I17: Regulatory Tier / Seniority | J17: Governing Law
B18: RJHI Benchmark Senior Unsecured Notes | C18: Senior Unsecured RegS/144A | D18: USD | E18: 750 | F18: 4.750% | G18: 100.8 | H18: 4.75 | I18: Senior Unsecured (Bail-in eligible) | J18: English Law
B19: RJHI Tier 2 Subordinated Notes | C19: Subordinated Tier 2 Capital Note | D19: USD | E19: 500 | F19: 6.250% | G19: 97.3 | H19: 6.25 | I19: Subordinated (Tier 2 Regulatory Capital) | J19: English Law
B20: RJHI Additional Tier 1 (AT1) Perpetual | C20: Perpetual Subordinated Contingent Convertible | D20: USD | E20: 400 | F20: 7.000% | G20: 95.8 | H20: 7 | I20: Junior Subordinated (Loss-Absorbing) | J20: English Law
B21: Bilateral Interbank & Central Bank Repos | C21: Secured Money Market Borrowing | D21: USD / Local | E21: 14000 | F21: SOFR + 65 bps | G21: 100 | H21: 5.45 | I21: Secured Interbank | J21: Domestic Banking Law
B23: III. SYNDICATED REVOLVING & SHORT-TERM BANK FACILITIES
B24: Facility Designation | C24: Committed Syndicated Interbank Liquidity Facility
B25: Total Committed Capacity ($M) | C25: 1200
B26: Drawn Amount ($M) | C26: 250
B27: AVAILABLE UNDRAWN HEADROOM ($M) | C27: 950
B28: Borrowing Spread / Margin | C28: SOFR + 110 bps
B29: Undrawn Commitment Fee | C29: 38.5 bps
B30: Maturity Date & Extension Options | C30: 2027-09-30 (with 1-year extension option)
B31: Syndicate Lenders / Arrangers | C31: Consortium of 14 international correspondent banks
B32: Bank Liquidity Covenants | C32: Minimum CET1 of 10.5%, Minimum LCR of 115%
B34: IV. REGULATORY COVENANTS & PRUDENTIAL HEADROOM SCORECARD
B35: Prudential Covenant / Ratio Test | C35: Regulatory Minimum / Limit | D35: Reported Actual Metric | E35: Headroom / Buffer | F35: Supervisory Framework & Notes
B36: Regulatory Minimum CAR Ratio | C36: 12.0% (Pillar 1 + Pillar 2 + Conservation Buffer) | D36: 20.5% | E36: +8.5% (+850 bps excess capital) | F36: Basel III Total Capital requirement including Pillar 2
B37: Minimum Common Equity Tier 1 Ratio | C37: 8.5% Regulatory Minimum | D37: 16.8% | E37: +8.3% (+830 bps buffer) | F37: CET1 minimum including Capital Conservation Buffer (CCB)
B38: Minimum Liquidity Coverage Ratio (LCR) | C38: 100.0% Statutory Minimum | D38: 178.5% | E38: +78.5% excess high-quality liquid assets (HQLA) | F38: High Quality Liquid Assets (HQLA) vs 30-day net cash outflow
B39: Single Counterparty Group Exposure | C39: Max 25.0% of Total Regulatory Capital | D39: 14.2% top group exposure | E39: 10.8% headroom below regulatory cap | F39: Maximum exposure to any single non-bank client group
B40: Cross-Default & Resolution Clause | C40: $40.0M threshold triggering cross-default under Senior Eurobond terms. | D40: Zero Defaults | E40: Compliant | F40: Bail-in resolution powers and cross-acceleration safeguard

Sheet Regulatory Stress & Bail-in
B2: Al Rajhi Bank — Regulatory Stress Test & Bail-in Buffer
B4: I. MACRO REVERSE STRESS TEST SCENARIOS
B5: Stress Scenario | C5: Simulated NPL Surge | D5: Provisioning Charge | E5: CET1 Drawdown | F5: Post-Stress CET1 | G5: Minimum Buffer | H5: Bail-in Implication
B6: Base Case (Macro Stability) | C6: +0 bp | D6: $180M | E6: 0 bp | F6: 14.8% | G6: +630 bp | H6: No bail-in risk; senior bonds trade par
B7: Adverse Recession (Local Currency Shock) | C7: +250 bp | D7: $450M | E7: -180 bp | F7: 13.0% | G7: +450 bp | H7: Tier 2 coupon preserved; no senior impairment
B8: Severe Stagflation / Real Estate Shock | C8: +500 bp | D8: $850M | E8: -380 bp | F8: 11.0% | G8: +250 bp | H8: Tier 1 hybrid coupon deferral risk; senior intact
B9: Extreme Systemic Crisis (Resolution) | C9: +950 bp | D9: $1,600M | E9: -680 bp | F9: 8.0% | G9: -50 bp | H9: Subordinated Tier 2 wiped; senior bonds protected by DSIB

Sheet Earnings Deck & Guidance
B2: Al Rajhi Bank (RJHI) — Earnings Presentation & Management Guidance
B3: Source: Al Rajhi Bank Q4 / FY2024 & Q1 2025 Investor Presentation & Earnings Conference Call | Reporting Currency: USD / Local Currency Statutory
B5: I. MANAGEMENT STRATEGIC GUIDANCE TRACKER & VARIANCE ANALYSIS
B6: Strategic Guidance Metric | C6: Company Target / Commitment | D6: Current Run-Rate | E6: Tracking Status | F6: Guidance Variance & Verification Question to Ask CFO
B7: 2025E Gross Loan Book Growth | C7: +12.0% - 15.0% YoY organic lending expansion | D7: +13.8% YoY annualized loan disbursement | E7: On Track | F7: Corporate trade finance and residential mortgage origination performing strongly. [QUESTION TO CFO TO VERIFY]: On your last call, management guided full-year revenue of +12.0% - 15.0% YoY organic lending expansion. With current run-rate at +13.8% YoY annualized loan disbursement, do you officially reaffirm this target for the full year, or are you seeing customer volume or pricing pressure?
B8: Net Interest Margin (NIM) | C8: 3.90% - 4.15% | D8: 4.02% | E8: On Track | F8: Asset yield repricing outpacing deposit cost inflation; sticky CASA base. [QUESTION TO CFO TO VERIFY]: Management committed to an EBITDA target of 3.90% - 4.15%. Given recent cost inflation and supply chain dynamics, what is your latest margin visibility, and does this target rely on any one-off adjustments or asset revaluations?
B9: Cost-to-Income Ratio (CIR) | C9: < 38.0% | D9: 36.8% | E9: Ahead of Target | F9: Digital branch automation and back-office straight-through processing cutting overhead. [QUESTION TO CFO TO VERIFY]: Management guided a target of < 38.0% for Cost-to-Income Ratio (CIR). Can you confirm whether current execution at 36.8% remains strictly on track, and what key operational milestones remain for the next two quarters?
B10: Cost of Risk (Credit Impairment) | C10: < 75 - 90 bps of gross loans | D10: 68 bps annualized credit cost | E10: Ahead of Target | F10: Conservative underwriting and robust commercial recoveries preserving asset quality. [QUESTION TO CFO TO VERIFY]: Management guided a target of < 75 - 90 bps of gross loans for Cost of Risk (Credit Impairment). Can you confirm whether current execution at 68 bps annualized credit cost remains strictly on track, and what key operational milestones remain for the next two quarters?
B11: Dividend Payout Ratio | C11: 40.0% of annual attributable net profit | D11: 40.0% payout proposed | E11: On Track | F11: Internal capital generation (+160 bps) comfortably funds organic balance sheet growth. [QUESTION TO CFO TO VERIFY]: Management guided a target of 40.0% of annual attributable net profit for Dividend Payout Ratio. Can you confirm whether current execution at 40.0% payout proposed remains strictly on track, and what key operational milestones remain for the next two quarters?
B13: II. CAPITAL ADEQUACY & REGULATORY TARGETS
B14: Project / Capital Dimension | C14: Disclosure & Execution Milestone
B15: Cet1 Ratio Target | C15: > 13.0% (Substantial buffer over Basel III minimum of 8.5%)
B16: Total Car Target | C16: > 20.5% Total Capital Adequacy Ratio
B17: Internal Capital Generation | C17: +140 - 180 bps annually from retained earnings
B18: Regulatory Stress Test Buffer | C18: Over 350 bps excess capital buffer above regulatory threshold
B20: III. FUNDING & LIQUIDITY PROFILE
B21: Exposure Category | C21: Contractual / Balance Sheet Profile
B22: Casa Deposit Ratio | C22: 54.5% of total customer deposits (Sticky low-cost current & savings accounts)
B23: Liquidity Coverage Ratio | C23: 178.5% (Well in excess of 100% regulatory minimum)
B24: Net Stable Funding Ratio | C24: 128.0%
B25: Loan To Deposit Ratio | C25: 90.3% (Disciplined commercial liquidity profile)
B26: Foreign Currency Liquidity Buffer | C26: $300.0M in high-quality liquid assets and central bank placements
B28: IV. ASSET QUALITY & PROVISIONING TARGETS
B29: Dimension | C29: Commercial / Asset Metrics
B30: Npl Ratio Target | C30: < 0.9% across lending portfolio
B31: Provision Coverage Ratio | C31: 138.5% total allowance coverage on Stage 3 impaired loans
B32: Stage 2 Underperforming Loans | C32: 5.8% of gross customer advances (Prudently classified)
B33: Collateral Coverage | C33: 125% physical real estate and cash collateral on commercial credit lines
B35: V. RECENT EARNINGS CADENCE & HIGHLIGHTS
B36: Liquidity Component | C36: Available Buffer / Runway
B37: Latest Quarter Earnings | C37: Record quarterly net operating profit driven by strong trade finance and retail fee generation
B38: Digital Banking Penetration | C38: 86% of retail banking transactions executed via mobile / digital channels
B39: Next Earnings Release | C39: Q2 / 1H Audited Interim Results & Earnings Webcast
B41: INSTITUTIONAL MANAGEMENT QUESTIONS & CONVICTION DRIVERS (1-ON-1 DUE DILIGENCE)
B42: Focus Area | C42: Question to Ask CFO / Management | F42: Credit Relevance & Deduced Ambiguity | H42: Conviction Trigger & Decision Rule
B43: Stage 2 Loan Migration & Restructured Corporate Exposures | C43: What proportion of Stage 2 watch-list loans represent restructured corporate exposures, and what is the specific cash recovery rate on collateral upon foreclosure under current local court procedures? | F43: Reported NPL ratios often mask asset quality stress through maturity extensions. Stage 2 loans are the true indicator of future provisioning spikes that erode Common Equity Tier 1 (CET1) capital. | H43: Stage 2 coverage >25% and stable migration rates confirm balance sheet resilience.
B44: Foreign Currency Liquidity Coverage & Wholesale Refinancing Roll Rates | C44: What is the bank's net foreign currency liquidity buffer in unencumbered Nostro balances, and what roll-rates were achieved on syndicated loan / bilateral loan facilities over the past 6 months? | F44: Emerging market banks face acute dollar refinancing risk when global liquidity tightens. High roll-rates confirm institutional counterparty confidence. | H44: Roll-rates exceeding 100% with tighter pricing spreads indicate strong market access.
B47: SCHEDULED EARNINGS RELEASE & INVESTOR RELATIONS CALENDAR
B48: Calendar Dimension | C48: Scheduled Detail & IR Access
B49: Next Scheduled Earnings Date | C49: 2026-11-12
...
