Workbook

Sheet Annual and Quarterly
A1: €mm, Dec year-end | B1: FY18 | C1: FY19 | D1: FY20 | E1: FY21 | F1: FY22 | G1: FY23 | H1: FY24 | I1: FY25 | J1: LTM | K1: 1Q19 | L1: 2Q19 | M1: 3Q19 | N1: 4Q19 | O1: 1Q20 | P1: 2Q20 | Q1: 3Q20 | R1: 4Q20 | S1: 1Q21 | T1: 2Q21 | U1: 3Q21 | V1: 4Q21 | W1: 1Q22 | X1: 2Q22 | Y1: 3Q22 | Z1: 4Q22 | AA1: 1Q23 | AB1: 2Q23 | AC1: 3Q23 | AD1: 4Q23 | AE1: 1Q24 | AF1: 2Q24 | AG1: 3Q24 | AH1: 4Q24 | AI1: 1Q25 | AJ1: 2Q25 | AK1: 3Q25 | AL1: 4Q25 | AM1: 1Q26 | AN1: 2Q26 | AO1: Q/o/Q | AP1: Y/o/Y
A2: Income Statement
A3: Revenue | B3: 432.474 | C3: 607.3 | D3: 695.672 | E3: 1014.891 | F3: 1852.686 | G3: 2262.773 | H3: 2103.272 | I3: 2189.312 | J3: =I3+'Quarterly YTD'!AF3-'Quarterly YTD'!AB3 -> 2285.39 | K3: 93.496 | L3: ='Quarterly YTD'!D3-K3 -> 111.524 | M3: ='Quarterly YTD'!E3-'Quarterly YTD'!D3 -> 115.428 | N3: =C3-'Quarterly YTD'!E3 -> 286.852 | O3: 267.869 | P3: ='Quarterly YTD'!H3-O3 -> 132.978 | Q3: ='Quarterly YTD'!I3-'Quarterly YTD'!H3 -> 133.792 | R3: =D3-'Quarterly YTD'!I3 -> 161.033 | S3: 162.144 | T3: ='Quarterly YTD'!L3-S3 -> 206.427 | U3: ='Quarterly YTD'!M3-'Quarterly YTD'!L3 -> 299.715 | V3: =E3-'Quarterly YTD'!M3 -> 346.605 | W3: 317.129 | X3: ='Quarterly YTD'!P3-W3 -> 463.506 | Y3: ='Quarterly YTD'!Q3-'Quarterly YTD'!P3 -> 563.904 | Z3: =F3-'Quarterly YTD'!Q3 -> 508.147 | AA3: 404.776 | AB3: ='Quarterly YTD'!T3-AA3 -> 549.902 | AC3: ='Quarterly YTD'!U3-'Quarterly YTD'!T3 -> 687.535 | AD3: =G3-'Quarterly YTD'!U3 -> 620.56 | AE3: 508.778 | AF3: ='Quarterly YTD'!X3-AE3 -> 720.116 | AG3: ='Quarterly YTD'!Y3-'Quarterly YTD'!X3 -> 828.505 | AH3: =H3-'Quarterly YTD'!Y3 -> 45.873 | AI3: 457.491 | AJ3: ='Quarterly YTD'!AB3-AI3 -> 560.951 | AK3: ='Quarterly YTD'!AC3-'Quarterly YTD'!AB3+-164.005 -> 730.681 | AL3: =I3-'Quarterly YTD'!AC3 -> 276.184 | AM3: 522.848 | AN3: ='Quarterly YTD'!AF3-AM3 -> 591.672 | AO3: =IF(AND(AN3=0,AM3=0),0,IF(OR(AM3=0,AM3="NM",AN3="NM"),"NM",IF(AM3<0,-(AN3/AM3-1),AN3/AM3-1))) -> 0.1316329 | AP3: =IF(AND(AN3=0,AJ3=0),0,IF(OR(AJ3=0,AJ3="NM",AN3="NM"),"NM",IF(AJ3<0,-(AN3/AJ3-1),AN3/AJ3-1))) -> 0.054765924
A4: Other income | B4: 0.262 | C4: 0.879 | D4: 13.218 | E4: 3.332 | F4: 2.832 | G4: 3.466 | H4: 2.154 | I4: 6.403 | J4: =I4+'Quarterly YTD'!AF4-'Quarterly YTD'!AB4 -> 8.155 | K4: 0.16 | L4: ='Quarterly YTD'!D4-K4 -> 0.107 | M4: ='Quarterly YTD'!E4-'Quarterly YTD'!D4 -> 0.136 | N4: =C4-'Quarterly YTD'!E4 -> 0.476 | O4: 1.034 | P4: ='Quarterly YTD'!H4-O4 -> 11.009 | Q4: ='Quarterly YTD'!I4-'Quarterly YTD'!H4 -> 1.337 | R4: =D4-'Quarterly YTD'!I4 -> -0.162 | S4: 0.889 | T4: ='Quarterly YTD'!L4-S4 -> 1.869 | U4: ='Quarterly YTD'!M4-'Quarterly YTD'!L4 -> 1.428 | V4: =E4-'Quarterly YTD'!M4 -> -0.854 | W4: 0.746 | X4: ='Quarterly YTD'!P4-W4 -> 2.135 | Y4: ='Quarterly YTD'!Q4-'Quarterly YTD'!P4 -> 1.465 | Z4: =F4-'Quarterly YTD'!Q4 -> -1.514 | AA4: 0.783 | AB4: ='Quarterly YTD'!T4-AA4 -> 0.413 | AC4: ='Quarterly YTD'!U4-'Quarterly YTD'!T4 -> 3.566 | AD4: =G4-'Quarterly YTD'!U4 -> -1.296 | AE4: 1.109 | AF4: ='Quarterly YTD'!X4-AE4 -> 1.058 | AG4: ='Quarterly YTD'!Y4-'Quarterly YTD'!X4 -> 0.741 | AH4: =H4-'Quarterly YTD'!Y4 -> -0.754 | AI4: 0.771 | AJ4: ='Quarterly YTD'!AB4-AI4 -> 0.977 | AK4: ='Quarterly YTD'!AC4-'Quarterly YTD'!AB4+-0.332 -> 1.166 | AL4: =I4-'Quarterly YTD'!AC4 -> 3.157 | AM4: 1.269 | AN4: ='Quarterly YTD'!AF4-AM4 -> 2.231 | AO4: =IF(AND(AN4=0,AM4=0),0,IF(OR(AM4=0,AM4="NM",AN4="NM"),"NM",IF(AM4<0,-(AN4/AM4-1),AN4/AM4-1))) -> 0.75807723 | AP4: =IF(AND(AN4=0,AJ4=0),0,IF(OR(AJ4=0,AJ4="NM",AN4="NM"),"NM",IF(AJ4<0,-(AN4/AJ4-1),AN4/AJ4-1))) -> 1.283521
A5: Cost of services and goods | B5: -312.579 | C5: -412.602 | D5: -418.367 | E5: -615.285 | F5: -1193.407 | G5: -1406.56 | H5: -1187.448 | I5: -1202.791 | J5: =I5+'Quarterly YTD'!AF5-'Quarterly YTD'!AB5 -> -1321.335 | K5: -62.428 | L5: ='Quarterly YTD'!D5-K5 -> -75.67 | M5: ='Quarterly YTD'!E5-'Quarterly YTD'!D5 -> -80.875 | N5: =C5-'Quarterly YTD'!E5 -> -193.629 | O5: -185.272 | P5: ='Quarterly YTD'!H5-O5 -> -63.699 | Q5: ='Quarterly YTD'!I5-'Quarterly YTD'!H5 -> -74.874 | R5: =D5-'Quarterly YTD'!I5 -> -94.522 | S5: -95.058 | T5: ='Quarterly YTD'!L5-S5 -> -127.924 | U5: ='Quarterly YTD'!M5-'Quarterly YTD'!L5 -> -184.206 | V5: =E5-'Quarterly YTD'!M5 -> -208.097 | W5: -208.777 | X5: ='Quarterly YTD'!P5-W5 -> -307.233 | Y5: ='Quarterly YTD'!Q5-'Quarterly YTD'!P5 -> -347.418 | Z5: =F5-'Quarterly YTD'!Q5 -> -329.979 | AA5: -278.055 | AB5: ='Quarterly YTD'!T5-AA5 -> -327.317 | AC5: ='Quarterly YTD'!U5-'Quarterly YTD'!T5 -> -388.084 | AD5: =G5-'Quarterly YTD'!U5 -> -413.104 | AE5: -360.502 | AF5: ='Quarterly YTD'!X5-AE5 -> -402.589 | AG5: ='Quarterly YTD'!Y5-'Quarterly YTD'!X5 -> -444.051 | AH5: =H5-'Quarterly YTD'!Y5 -> 19.694 | AI5: -290.996 | AJ5: ='Quarterly YTD'!AB5-AI5 -> -290.214 | AK5: ='Quarterly YTD'!AC5-'Quarterly YTD'!AB5+152.816 -> -360.316 | AL5: =I5-'Quarterly YTD'!AC5 -> -108.449 | AM5: -327.944 | AN5: ='Quarterly YTD'!AF5-AM5 -> -371.81 | AO5: =IF(AND(AN5=0,AM5=0),0,IF(OR(AM5=0,AM5="NM",AN5="NM"),"NM",IF(AM5<0,(AN5/AM5-1),-(AN5/AM5-1)))) -> 0.13376064 | AP5: =IF(AND(AN5=0,AJ5=0),0,IF(OR(AJ5=0,AJ5="NM",AN5="NM"),"NM",IF(AJ5<0,(AN5/AJ5-1),-(AN5/AJ5-1)))) -> 0.28115804
A6: Depreciation and amortisation | B6: -6.853 | C6: -34.732 | D6: -99.205 | E6: -74.338 | F6: -114.781 | G6: -239.28 | H6: -220.229 | I6: -265.414 | J6: =I6+'Quarterly YTD'!AF6-'Quarterly YTD'!AB6 -> -268.039 | K6: -2.936 | L6: ='Quarterly YTD'!D6-K6 -> -3.23 | M6: ='Quarterly YTD'!E6-'Quarterly YTD'!D6 -> -3.427 | N6: =C6-'Quarterly YTD'!E6 -> -25.139 | O6: -26.639 | P6: ='Quarterly YTD'!H6-O6 -> -26.592 | Q6: ='Quarterly YTD'!I6-'Quarterly YTD'!H6 -> -24.388 | R6: =D6-'Quarterly YTD'!I6 -> -21.586 | S6: -18.04 | T6: ='Quarterly YTD'!L6-S6 -> -17.06 | U6: ='Quarterly YTD'!M6-'Quarterly YTD'!L6 -> -19.107 | V6: =E6-'Quarterly YTD'!M6 -> -20.131 | W6: -21.68 | X6: ='Quarterly YTD'!P6-W6 -> -26.51 | Y6: ='Quarterly YTD'!Q6-'Quarterly YTD'!P6 -> -36.201 | Z6: =F6-'Quarterly YTD'!Q6 -> -30.39 | AA6: -41.974 | AB6: ='Quarterly YTD'!T6-AA6 -> -50.043 | AC6: ='Quarterly YTD'!U6-'Quarterly YTD'!T6 -> -64.571 | AD6: =G6-'Quarterly YTD'!U6 -> -82.692 | AE6: -81.707 | AF6: ='Quarterly YTD'!X6-AE6 -> -89.611 | AG6: ='Quarterly YTD'!Y6-'Quarterly YTD'!X6 -> -93.959 | AH6: =H6-'Quarterly YTD'!Y6 -> 45.048 | AI6: -62.883 | AJ6: ='Quarterly YTD'!AB6-AI6 -> -60.352 | AK6: ='Quarterly YTD'!AC6-'Quarterly YTD'!AB6+69.598 -> -91.364 | AL6: =I6-'Quarterly YTD'!AC6 -> 18.783 | AM6: -72.539 | AN6: ='Quarterly YTD'!AF6-AM6 -> -53.321 | AO6: =IF(AND(AN6=0,AM6=0),0,IF(OR(AM6=0,AM6="NM",AN6="NM"),"NM",IF(AM6<0,(AN6/AM6-1),-(AN6/AM6-1)))) -> -0.26493335 | AP6: =IF(AND(AN6=0,AJ6=0),0,IF(OR(AJ6=0,AJ6="NM",AN6="NM"),"NM",IF(AJ6<0,(AN6/AJ6-1),-(AN6/AJ6-1)))) -> -0.11649987
A7: Employee related expenses | B7: -71.907 | C7: -96.702 | D7: -145.734 | E7: -200.189 | F7: -306.593 | G7: -395.763 | H7: -470.48 | I7: -519.925 | J7: =I7+'Quarterly YTD'!AF7-'Quarterly YTD'!AB7 -> -544.752 | K7: -20.556 | L7: ='Quarterly YTD'!D7-K7 -> -21.033 | M7: ='Quarterly YTD'!E7-'Quarterly YTD'!D7 -> -20.334 | N7: =C7-'Quarterly YTD'!E7 -> -34.779 | O7: -39.977 | P7: ='Quarterly YTD'!H7-O7 -> -32.471 | Q7: ='Quarterly YTD'!I7-'Quarterly YTD'!H7 -> -36.27 | R7: =D7-'Quarterly YTD'!I7 -> -37.016 | S7: -38.995 | T7: ='Quarterly YTD'!L7-S7 -> -43.33 | U7: ='Quarterly YTD'!M7-'Quarterly YTD'!L7 -> -51.99 | V7: =E7-'Quarterly YTD'!M7 -> -65.874 | W7: -66.068 | X7: ='Quarterly YTD'!P7-W7 -> -76.555 | Y7: ='Quarterly YTD'!Q7-'Quarterly YTD'!P7 -> -78.453 | Z7: =F7-'Quarterly YTD'!Q7 -> -85.517 | AA7: -85.755 | AB7: ='Quarterly YTD'!T7-AA7 -> -96.142 | AC7: ='Quarterly YTD'!U7-'Quarterly YTD'!T7 -> -101.075 | AD7: =G7-'Quarterly YTD'!U7 -> -112.791 | AE7: -115.571 | AF7: ='Quarterly YTD'!X7-AE7 -> -124.509 | AG7: ='Quarterly YTD'!Y7-'Quarterly YTD'!X7 -> -123.482 | AH7: =H7-'Quarterly YTD'!Y7 -> -106.918 | AI7: -128.452 | AJ7: ='Quarterly YTD'!AB7-AI7 -> -125.638 | AK7: ='Quarterly YTD'!AC7-'Quarterly YTD'!AB7+21.036 -> -127.091 | AL7: =I7-'Quarterly YTD'!AC7 -> -117.708 | AM7: -141.944 | AN7: ='Quarterly YTD'!AF7-AM7 -> -136.973 | AO7: =IF(AND(AN7=0,AM7=0),0,IF(OR(AM7=0,AM7="NM",AN7="NM"),"NM",IF(AM7<0,(AN7/AM7-1),-(AN7/AM7-1)))) -> -0.035020853 | AP7: =IF(AND(AN7=0,AJ7=0),0,IF(OR(AJ7=0,AJ7="NM",AN7="NM"),"NM",IF(AJ7<0,(AN7/AJ7-1),-(AN7/AJ7-1)))) -> 0.09021952
A8: Other operating expenses | B8: -22.952 | C8: -34.741 | D8: -46.596 | E8: -68.488 | F8: -79.919 | G8: -97.36 | H8: -121.492 | I8: -127.501 | J8: =I8+'Quarterly YTD'!AF8-'Quarterly YTD'!AB8 -> -124.382 | K8: -5.566 | L8: ='Quarterly YTD'!D8-K8 -> -6.585 | M8: ='Quarterly YTD'!E8-'Quarterly YTD'!D8 -> -6.353 | N8: =C8-'Quarterly YTD'!E8 -> -16.237 | O8: -12.328 | P8: ='Quarterly YTD'!H8-O8 -> -9.956 | Q8: ='Quarterly YTD'!I8-'Quarterly YTD'!H8 -> -10.507 | R8: =D8-'Quarterly YTD'!I8 -> -13.805 | S8: -11.52 | T8: ='Quarterly YTD'!L8-S8 -> -12.516 | U8: ='Quarterly YTD'!M8-'Quarterly YTD'!L8 -> -14.059 | V8: =E8-'Quarterly YTD'!M8 -> -30.393 | W8: -17.336 | X8: ='Quarterly YTD'!P8-W8 -> -17.552 | Y8: ='Quarterly YTD'!Q8-'Quarterly YTD'!P8 -> -23.516 | Z8: =F8-'Quarterly YTD'!Q8 -> -21.515 | AA8: -21.85 | AB8: ='Quarterly YTD'!T8-AA8 -> -19.899 | AC8: ='Quarterly YTD'!U8-'Quarterly YTD'!T8 -> -24.453 | AD8: =G8-'Quarterly YTD'!U8 -> -31.158 | AE8: -32.188 | AF8: ='Quarterly YTD'!X8-AE8 -> -31.398 | AG8: ='Quarterly YTD'!Y8-'Quarterly YTD'!X8 -> -34.249 | AH8: =H8-'Quarterly YTD'!Y8 -> -23.657 | AI8: -33.392 | AJ8: ='Quarterly YTD'!AB8-AI8 -> -23.246 | AK8: ='Quarterly YTD'!AC8-'Quarterly YTD'!AB8+12.706 -> -32.074 | AL8: =I8-'Quarterly YTD'!AC8 -> -26.083 | AM8: -26.695 | AN8: ='Quarterly YTD'!AF8-AM8 -> -26.824 | AO8: =IF(AND(AN8=0,AM8=0),0,IF(OR(AM8=0,AM8="NM",AN8="NM"),"NM",IF(AM8<0,(AN8/AM8-1),-(AN8/AM8-1)))) -> 0.0048323656 | AP8: =IF(AND(AN8=0,AJ8=0),0,IF(OR(AJ8=0,AJ8="NM",AN8="NM"),"NM",IF(AJ8<0,(AN8/AJ8-1),-(AN8/AJ8-1)))) -> 0.15391895
A9: (Increase)/decrease in the provision for impairment of financial assets | B9: -1.558 | C9: -1.389 | D9: -21.9 | E9: -12.438 | F9: -12.251 | G9: -0.919 | H9: -3.33 | I9: -159.559 | J9: =I9+'Quarterly YTD'!AF9-'Quarterly YTD'!AB9 -> -191.655 | K9: -0.219 | L9: ='Quarterly YTD'!D9-K9 -> 0.022 | M9: ='Quarterly YTD'!E9-'Quarterly YTD'!D9 -> -0.479 | N9: =C9-'Quarterly YTD'!E9 -> -0.713 | O9: -1.37 | P9: ='Quarterly YTD'!H9-O9 -> -6.218 | Q9: ='Quarterly YTD'!I9-'Quarterly YTD'!H9 -> -0.261 | R9: =D9-'Quarterly YTD'!I9 -> -14.051 | S9: -0.236 | T9: ='Quarterly YTD'!L9-S9 -> -1.563 | U9: ='Quarterly YTD'!M9-'Quarterly YTD'!L9 -> -0.6 | V9: =E9-'Quarterly YTD'!M9 -> -10.039 | W9: -9.311 | X9: ='Quarterly YTD'!P9-W9 -> -0.364 | Y9: ='Quarterly YTD'!Q9-'Quarterly YTD'!P9 -> 0.741 | Z9: =F9-'Quarterly YTD'!Q9 -> -3.317 | AA9: -0.133 | AB9: ='Quarterly YTD'!T9-AA9 -> 2.165 | AC9: ='Quarterly YTD'!U9-'Quarterly YTD'!T9 -> -1.828 | AD9: =G9-'Quarterly YTD'!U9 -> -1.123 | AE9: 1.105 | AF9: ='Quarterly YTD'!X9-AE9 -> -0.382 | AG9: ='Quarterly YTD'!Y9-'Quarterly YTD'!X9 -> -0.215 | AH9: =H9-'Quarterly YTD'!Y9 -> -3.838 | AI9: -2.974 | AJ9: ='Quarterly YTD'!AB9-AI9 -> 4.707 | AK9: ='Quarterly YTD'!AC9-'Quarterly YTD'!AB9+-6.357 -> -1.895 | AL9: =I9-'Quarterly YTD'!AC9 -> -165.754 | AM9: -1.113 | AN9: ='Quarterly YTD'!AF9-AM9 -> -29.25 | AO9: =IF(AND(AN9=0,AM9=0),0,IF(OR(AM9=0,AM9="NM",AN9="NM"),"NM",IF(AM9<0,(AN9/AM9-1),-(AN9/AM9-1)))) -> 25.280323 | AP9: =IF(AND(AN9=0,AJ9=0),0,IF(OR(AJ9=0,AJ9="NM",AN9="NM"),"NM",IF(AJ9<0,(AN9/AJ9-1),-(AN9/AJ9-1)))) -> 7.2141491
A10: (Increase)/decrease in the provision for impairment of non-financial assets | B10: -2.365 | C10: -3.536 | D10: -7.344 | E10: -5.714 | F10: -13.635 | G10: -3.303 | H10: -12.561 | I10: -4.535 | J10: =I10+'Quarterly YTD'!AF10-'Quarterly YTD'!AB10 -> -22.55 | K10: -0.407 | L10: ='Quarterly YTD'!D10-K10 -> -0.346 | M10: ='Quarterly YTD'!E10-'Quarterly YTD'!D10 -> -0.41 | N10: =C10-'Quarterly YTD'!E10 -> -2.373 | O10: -0.256 | P10: ='Quarterly YTD'!H10-O10 -> -2.263 | Q10: ='Quarterly YTD'!I10-'Quarterly YTD'!H10 -> -1.945 | R10: =D10-'Quarterly YTD'!I10 -> -2.88 | S10: -0.632 | T10: ='Quarterly YTD'!L10-S10 -> -0.624 | U10: ='Quarterly YTD'!M10-'Quarterly YTD'!L10 -> -0.335 | V10: =E10-'Quarterly YTD'!M10 -> -4.123 | W10: -6.106 | X10: ='Quarterly YTD'!P10-W10 -> 1.916 | Y10: ='Quarterly YTD'!Q10-'Quarterly YTD'!P10 -> -0.472 | Z10: =F10-'Quarterly YTD'!Q10 -> -8.973 | AA10: 0.017 | AB10: ='Quarterly YTD'!T10-AA10 -> -1.599 | AC10: ='Quarterly YTD'!U10-'Quarterly YTD'!T10 -> -0.426 | AD10: =G10-'Quarterly YTD'!U10 -> -1.295 | AE10: -0.82 | AF10: ='Quarterly YTD'!X10-AE10 -> -1.506 | AG10: ='Quarterly YTD'!Y10-'Quarterly YTD'!X10 -> -1.526 | AH10: =H10-'Quarterly YTD'!Y10 -> -8.709 | AI10: -0.225 | AJ10: ='Quarterly YTD'!AB10-AI10 -> 6.594 | AK10: ='Quarterly YTD'!AC10-'Quarterly YTD'!AB10+0.274 -> -4.774 | AL10: =I10-'Quarterly YTD'!AC10 -> -5.856 | AM10: -0.89 | AN10: ='Quarterly YTD'!AF10-AM10 -> -10.756 | AO10: =IF(AND(AN10=0,AM10=0),0,IF(OR(AM10=0,AM10="NM",AN10="NM"),"NM",IF(AM10<0,(AN10/AM10-1),-(AN10/AM10-1)))) -> 11.085393 | AP10: =IF(AND(AN10=0,AJ10=0),0,IF(OR(AJ10=0,AJ10="NM",AN10="NM"),"NM",IF(AJ10<0,(AN10/AJ10-1),-(AN10/AJ10-1)))) -> 2.6311799
A11: Other gains - net | B11: 0.016 | C11: 1.29 | D11: 12.021 | E11: 38.199 | F11: 27.045 | G11: 36.603 | H11: 3.219 | I11: 17.514 | J11: =I11+'Quarterly YTD'!AF11-'Quarterly YTD'!AB11 -> 26.043 | K11: 0.657 | L11: ='Quarterly YTD'!D11-K11 -> -0.068 | M11: ='Quarterly YTD'!E11-'Quarterly YTD'!D11 -> -0.132 | N11: =C11-'Quarterly YTD'!E11 -> 0.833 | O11: 0.377 | P11: ='Quarterly YTD'!H11-O11 -> 6.823 | Q11: ='Quarterly YTD'!I11-'Quarterly YTD'!H11 -> 3.439 | R11: =D11-'Quarterly YTD'!I11 -> 1.382 | S11: 13.473 | T11: ='Quarterly YTD'!L11-S11 -> 10.821 | U11: ='Quarterly YTD'!M11-'Quarterly YTD'!L11 -> 6.019 | V11: =E11-'Quarterly YTD'!M11 -> 7.886 | W11: 19.732 | X11: ='Quarterly YTD'!P11-W11 -> 7.784 | Y11: ='Quarterly YTD'!Q11-'Quarterly YTD'!P11 -> 14.526 | Z11: =F11-'Quarterly YTD'!Q11 -> -14.997 | AA11: 3.463 | AB11: ='Quarterly YTD'!T11-AA11 -> 3.992 | AC11: ='Quarterly YTD'!U11-'Quarterly YTD'!T11 -> 7.368 | AD11: =G11-'Quarterly YTD'!U11 -> 21.78 | AE11: 10.448 | AF11: ='Quarterly YTD'!X11-AE11 -> 5.899 | AG11: ='Quarterly YTD'!Y11-'Quarterly YTD'!X11 -> 2.2 | AH11: =H11-'Quarterly YTD'!Y11 -> -15.328 | AI11: -1.645 | AJ11: ='Quarterly YTD'!AB11-AI11 -> 3.756 | AK11: ='Quarterly YTD'!AC11-'Quarterly YTD'!AB11+-2.995 -> 4.889 | AL11: =I11-'Quarterly YTD'!AC11 -> 7.519 | AM11: 1.756 | AN11: ='Quarterly YTD'!AF11-AM11 -> 8.884 | AO11: =IF(AND(AN11=0,AM11=0),0,IF(OR(AM11=0,AM11="NM",AN11="NM"),"NM",IF(AM11<0,-(AN11/AM11-1),AN11/AM11-1))) -> 4.0592255 | AP11: =IF(AND(AN11=0,AJ11=0),0,IF(OR(AJ11=0,AJ11="NM",AN11="NM"),"NM",IF(AJ11<0,-(AN11/AJ11-1),AN11/AJ11-1))) -> 1.3652822
A12: Operating (loss)/profit | B12: =SUM(B3:B11) -> 14.538 | C12: =SUM(C3:C11) -> 25.767 | D12: =SUM(D3:D11) -> -18.235 | E12: =SUM(E3:E11) -> 79.97 | F12: =SUM(F3:F11) -> 161.977 | G12: =SUM(G3:G11) -> 159.657 | H12: =SUM(H3:H11) -> 93.105 | I12: =SUM(I3:I11) -> -66.496 | J12: =I12+'Quarterly YTD'!AF12-'Quarterly YTD'!AB12 -> -153.125 | K12: =SUM(K3:K11) -> 2.201 | L12: =SUM(L3:L11) -> 4.721 | M12: =SUM(M3:M11) -> 3.554 | N12: =SUM(N3:N11) -> 15.291 | O12: =SUM(O3:O11) -> 3.438 | P12: =SUM(P3:P11) -> 9.611 | Q12: =SUM(Q3:Q11) -> -9.677 | R12: =SUM(R3:R11) -> -21.607 | ... AN12: =SUM(AN3:AN11) -> -26.147 | AO12: =IF(AND(AN12=0,AM12=0),0,IF(OR(AM12=0,AM12="NM",AN12="NM"),"NM",IF(AM12<0,-(AN12/AM12-1),AN12/AM12-1))) -> 0.42219128 | AP12: =IF(AND(AN12=0,AJ12=0),0,IF(OR(AJ12=0,AJ12="NM",AN12="NM"),"NM",IF(AJ12<0,-(AN12/AJ12-1),AN12/AJ12-1))) -> -1.3372283
A13: Finance income | B13: 0.067 | C13: 3.05 | D13: 12.271 | E13: 2.919 | F13: 3.901 | G13: 24.747 | H13: 58.254 | I13: 15.295 | J13: =I13+'Quarterly YTD'!AF13-'Quarterly YTD'!AB13 -> -2.247 | K13: 0.003 | L13: ='Quarterly YTD'!D13-K13 -> 0.029 | M13: ='Quarterly YTD'!E13-'Quarterly YTD'!D13 -> 0.324 | N13: =C13-'Quarterly YTD'!E13 -> 2.694 | O13: 1.059 | P13: ='Quarterly YTD'!H13-O13 -> 4.12 | Q13: ='Quarterly YTD'!I13-'Quarterly YTD'!H13 -> -0.444 | R13: =D13-'Quarterly YTD'!I13 -> 7.536 | S13: 2.403 | T13: ='Quarterly YTD'!L13-S13 -> 0.767 | U13: ='Quarterly YTD'!M13-'Quarterly YTD'!L13 -> -0.503 | V13: =E13-'Quarterly YTD'!M13 -> 0.252 | W13: 0.094 | X13: ='Quarterly YTD'!P13-W13 -> 0.098 | Y13: ='Quarterly YTD'!Q13-'Quarterly YTD'!P13 -> 2.105 | Z13: =F13-'Quarterly YTD'!Q13 -> 1.604 | AA13: 6.358 | AB13: ='Quarterly YTD'!T13-AA13 -> 0.726 | AC13: ='Quarterly YTD'!U13-'Quarterly YTD'!T13 -> -2.508 | AD13: =G13-'Quarterly YTD'!U13 -> 20.171 | AE13: 0.593 | AF13: ='Quarterly YTD'!X13-AE13 -> 54.219 | AG13: ='Quarterly YTD'!Y13-'Quarterly YTD'!X13 -> 9.149 | AH13: =H13-'Quarterly YTD'!Y13 -> -5.707 | AI13: 7.109 | AJ13: ='Quarterly YTD'!AB13-AI13 -> 11.567 | AK13: ='Quarterly YTD'!AC13-'Quarterly YTD'!AB13+-2.071 -> 0.33 | AL13: =I13-'Quarterly YTD'!AC13 -> -5.782 | AM13: 0.412 | AN13: ='Quarterly YTD'!AF13-AM13 -> 0.722 | AO13: =IF(AND(AN13=0,AM13=0),0,IF(OR(AM13=0,AM13="NM",AN13="NM"),"NM",IF(AM13<0,-(AN13/AM13-1),AN13/AM13-1))) -> 0.75242718 | AP13: =IF(AND(AN13=0,AJ13=0),0,IF(OR(AJ13=0,AJ13="NM",AN13="NM"),"NM",IF(AJ13<0,-(AN13/AJ13-1),AN13/AJ13-1))) -> -0.93758105
A14: Finance costs | B14: -1.962 | C14: -9.948 | D14: -38.655 | E14: -39.719 | F14: -83.341 | G14: -114.979 | H14: -92.387 | I14: -93.369 | J14: =I14+'Quarterly YTD'!AF14-'Quarterly YTD'!AB14 -> -97.204 | K14: -1.155 | L14: ='Quarterly YTD'!D14-K14 -> -0.876 | M14: ='Quarterly YTD'!E14-'Quarterly YTD'!D14 -> -1.34 | N14: =C14-'Quarterly YTD'!E14 -> -6.577 | O14: -10.943 | P14: ='Quarterly YTD'!H14-O14 -> -9.827 | Q14: ='Quarterly YTD'!I14-'Quarterly YTD'!H14 -> -10.166 | R14: =D14-'Quarterly YTD'!I14 -> -7.719 | S14: -8.494 | T14: ='Quarterly YTD'!L14-S14 -> -7.849 | U14: ='Quarterly YTD'!M14-'Quarterly YTD'!L14 -> -10.5 | V14: =E14-'Quarterly YTD'!M14 -> -12.876 | W14: -18.259 | X14: ='Quarterly YTD'!P14-W14 -> -22.488 | Y14: ='Quarterly YTD'!Q14-'Quarterly YTD'!P14 -> -35.845 | Z14: =F14-'Quarterly YTD'!Q14 -> -6.749 | AA14: -24.175 | AB14: ='Quarterly YTD'!T14-AA14 -> -26.558 | AC14: ='Quarterly YTD'!U14-'Quarterly YTD'!T14 -> -34.404 | AD14: =G14-'Quarterly YTD'!U14 -> -29.842 | AE14: -41.744 | AF14: ='Quarterly YTD'!X14-AE14 -> -27.3 | AG14: ='Quarterly YTD'!Y14-'Quarterly YTD'!X14 -> -35.932 | AH14: =H14-'Quarterly YTD'!Y14 -> 12.589 | AI14: -23.988 | AJ14: ='Quarterly YTD'!AB14-AI14 -> -16.27 | AK14: ='Quarterly YTD'!AC14-'Quarterly YTD'!AB14+25.892 -> -27.691 | AL14: =I14-'Quarterly YTD'!AC14 -> 0.472 | AM14: -23.556 | AN14: ='Quarterly YTD'!AF14-AM14 -> -20.537 | AO14: =IF(AND(AN14=0,AM14=0),0,IF(OR(AM14=0,AM14="NM",AN14="NM"),"NM",IF(AM14<0,(AN14/AM14-1),-(AN14/AM14-1)))) -> -0.12816268 | AP14: =IF(AND(AN14=0,AJ14=0),0,IF(OR(AJ14=0,AJ14="NM",AN14="NM"),"NM",IF(AJ14<0,(AN14/AJ14-1),-(AN14/AJ14-1)))) -> 0.26226183
A15: Finance costs – net | B15: =SUM(B13:B14) -> -1.895 | C15: =SUM(C13:C14) -> -6.898 | D15: =SUM(D13:D14) -> -26.384 | E15: =SUM(E13:E14) -> -36.8 | F15: =SUM(F13:F14) -> -79.44 | G15: =SUM(G13:G14) -> -90.232 | H15: =SUM(H13:H14) -> -34.133 | I15: =SUM(I13:I14) -> -78.074 | ... AN15: =SUM(AN13:AN14) -> -19.815 | AO15: =IF(AND(AN15=0,AM15=0),0,IF(OR(AM15=0,AM15="NM",AN15="NM"),"NM",IF(AM15<0,(AN15/AM15-1),-(AN15/AM15-1)))) -> -0.14383858 | AP15: =IF(AND(AN15=0,AJ15=0),0,IF(OR(AJ15=0,AJ15="NM",AN15="NM"),"NM",IF(AJ15<0,(AN15/AJ15-1),-(AN15/AJ15-1)))) -> 3.2132681
A16: Share of profit of equity-accounted investees | B16: 0 | C16: -1.027 | D16: -1.19 | E16: 1.458 | F16: -55.091 | G16: 2.706 | H16: 0.013 | I16: -0.255 | J16: =I16+'Quarterly YTD'!AF16-'Quarterly YTD'!AB16 -> -0.262 | K16: -0.054 | L16: ='Quarterly YTD'!D16-K16 -> -0.025 | M16: ='Quarterly YTD'!E16-'Quarterly YTD'!D16 -> -0.859 | N16: =C16-'Quarterly YTD'!E16 -> -0.089 | O16: 0.84 | P16: ='Quarterly YTD'!H16-O16 -> 1.009 | Q16: ='Quarterly YTD'!I16-'Quarterly YTD'!H16 -> 1.562 | R16: =D16-'Quarterly YTD'!I16 -> -4.601 | S16: 0.022 | T16: ='Quarterly YTD'!L16-S16 -> -0.004 | U16: ='Quarterly YTD'!M16-'Quarterly YTD'!L16 -> -0.067 | V16: =E16-'Quarterly YTD'!M16 -> 1.507 | W16: 0.023 | X16: ='Quarterly YTD'!P16-W16 -> -0.03 | Y16: ='Quarterly YTD'!Q16-'Quarterly YTD'!P16 -> -0.006 | Z16: =F16-'Quarterly YTD'!Q16 -> -55.078 | AA16: 0.004 | AB16: ='Quarterly YTD'!T16-AA16 -> 2.093 | AC16: ='Quarterly YTD'!U16-'Quarterly YTD'!T16 -> 0.381 | AD16: =G16-'Quarterly YTD'!U16 -> 0.228 | AE16: 0.004 | AF16: ='Quarterly YTD'!X16-AE16 -> 0 | AG16: ='Quarterly YTD'!Y16-'Quarterly YTD'!X16 -> 0.001 | AH16: =H16-'Quarterly YTD'!Y16 -> 0.008 | AI16: 0 | AJ16: ='Quarterly YTD'!AB16-AI16 -> 0.012 | AK16: ='Quarterly YTD'!AC16-'Quarterly YTD'!AB16 -> 0 | AL16: =I16-'Quarterly YTD'!AC16 -> -0.267 | AM16: 0 | AN16: ='Quarterly YTD'!AF16-AM16 -> 0.005 | AO16: =IF(AND(AN16=0,AM16=0),0,IF(OR(AM16=0,AM16="NM",AN16="NM"),"NM",IF(AM16<0,-(AN16/AM16-1),AN16/AM16-1))) -> NM | AP16: =IF(AND(AN16=0,AJ16=0),0,IF(OR(AJ16=0,AJ16="NM",AN16="NM"),"NM",IF(AJ16<0,-(AN16/AJ16-1),AN16/AJ16-1))) -> -0.58333333
A17: Loss before income tax | B17: =B12+SUM(B15:B16) -> 12.643 | C17: =C12+SUM(C15:C16) -> 17.842 | D17: =D12+SUM(D15:D16) -> -45.809 | E17: =E12+SUM(E15:E16) -> 44.628 | F17: =F12+SUM(F15:F16) -> 27.446 | G17: =G12+SUM(G15:G16) -> 72.131 | H17: =H12+SUM(H15:H16) -> 58.985 | I17: =I12+SUM(I15:I16) -> -144.825 | ... AN17: =AN12+SUM(AN15:AN16) -> -45.957 | AO17: =IF(AND(AN17=0,AM17=0),0,IF(OR(AM17=0,AM17="NM",AN17="NM"),"NM",IF(AM17<0,-(AN17/AM17-1),AN17/AM17-1))) -> 0.32807474 | AP17: =IF(AND(AN17=0,AJ17=0),0,IF(OR(AJ17=0,AJ17="NM",AN17="NM"),"NM",IF(AJ17<0,-(AN17/AJ17-1),AN17/AJ17-1))) -> -1.6308962
A18: Income tax credit | B18: -2.952 | C18: -5.712 | D18: -5.796 | E18: -10.26 | F18: -15.779 | G18: -3.945 | H18: -4.73 | I18: -0.124 | J18: =I18+'Quarterly YTD'!AF18-'Quarterly YTD'!AB18 -> 9.975 | K18: -0.408 | L18: ='Quarterly YTD'!D18-K18 -> -0.799 | M18: ='Quarterly YTD'!E18-'Quarterly YTD'!D18 -> -0.529 | N18: =C18-'Quarterly YTD'!E18 -> -3.976 | O18: -1.795 | P18: ='Quarterly YTD'!H18-O18 -> -4.259 | Q18: ='Quarterly YTD'!I18-'Quarterly YTD'!H18 -> 0.902 | R18: =D18-'Quarterly YTD'!I18 -> -0.644 | S18: -4.202 | T18: ='Quarterly YTD'!L18-S18 -> 3.819 | U18: ='Quarterly YTD'!M18-'Quarterly YTD'!L18 -> -3.74 | V18: =E18-'Quarterly YTD'!M18 -> -6.137 | W18: -3.154 | X18: ='Quarterly YTD'!P18-W18 -> -6.655 | Y18: ='Quarterly YTD'!Q18-'Quarterly YTD'!P18 -> -10.666 | Z18: =F18-'Quarterly YTD'!Q18 -> 4.696 | AA18: 3 | AB18: ='Quarterly YTD'!T18-AA18 -> -7.123 | AC18: ='Quarterly YTD'!U18-'Quarterly YTD'!T18 -> -7.781 | AD18: =G18-'Quarterly YTD'!U18 -> 7.959 | AE18: 12.94 | AF18: ='Quarterly YTD'!X18-AE18 -> -7.471 | AG18: ='Quarterly YTD'!Y18-'Quarterly YTD'!X18 -> -22.827 | AH18: =H18-'Quarterly YTD'!Y18 -> 12.628 | AI18: 16.991 | AJ18: ='Quarterly YTD'!AB18-AI18 -> -15.524 | AK18: ='Quarterly YTD'!AC18-'Quarterly YTD'!AB18+-0.41 -> -20.878 | AL18: =I18-'Quarterly YTD'!AC18 -> 18.877 | AM18: 8.482 | AN18: ='Quarterly YTD'!AF18-AM18 -> 3.084 | AO18: =IF(AND(AN18=0,AM18=0),0,IF(OR(AM18=0,AM18="NM",AN18="NM"),"NM",IF(AM18<0,(AN18/AM18-1),-(AN18/AM18-1)))) -> 0.63640651 | AP18: =IF(AND(AN18=0,AJ18=0),0,IF(OR(AJ18=0,AJ18="NM",AN18="NM"),"NM",IF(AJ18<0,(AN18/AJ18-1),-(AN18/AJ18-1)))) -> -1.1986601
A19: Loss for the period | B19: =SUM(B17:B18) -> 9.691 | C19: =SUM(C17:C18) -> 12.13 | D19: =SUM(D17:D18) -> -51.605 | E19: =SUM(E17:E18) -> 34.368 | F19: =SUM(F17:F18) -> 11.667 | G19: =SUM(G17:G18) -> 68.186 | H19: =SUM(H17:H18) -> 54.255 | I19: =SUM(I17:I18) -> -144.949 | ... AN19: =SUM(AN17:AN18) -> -42.873 | AO19: =IF(AND(AN19=0,AM19=0),0,IF(OR(AM19=0,AM19="NM",AN19="NM"),"NM",IF(AM19<0,-(AN19/AM19-1),AN19/AM19-1))) -> 0.28442434 | AP19: =IF(AND(AN19=0,AJ19=0),0,IF(OR(AJ19=0,AJ19="NM",AN19="NM"),"NM",IF(AJ19<0,-(AN19/AJ19-1),AN19/AJ19-1))) -> -1.7479588
A20: Gain/(loss) for the period from discontinued operations | B20: 0 | C20: 0 | D20: 0 | E20: 0 | F20: 0 | G20: 0 | H20: -116.838 | I20: 81.382 | J20: =I20+'Quarterly YTD'!AF20-'Quarterly YTD'!AB20 -> 208.488 | K20: 0 | L20: ='Quarterly YTD'!D20-K20 -> 0 | M20: ='Quarterly YTD'!E20-'Quarterly YTD'!D20 -> 0 | N20: =C20-'Quarterly YTD'!E20 -> 0 | O20: 0 | P20: ='Quarterly YTD'!H20-O20 -> 0 | Q20: ='Quarterly YTD'!I20-'Quarterly YTD'!H20 -> 0 | R20: =D20-'Quarterly YTD'!I20 -> 0 | S20: 0 | T20: ='Quarterly YTD'!L20-S20 -> 0 | U20: ='Quarterly YTD'!M20-'Quarterly YTD'!L20 -> 0 | V20: =E20-'Quarterly YTD'!M20 -> 0 | W20: 0 | X20: ='Quarterly YTD'!P20-W20 -> 0 | Y20: ='Quarterly YTD'!Q20-'Quarterly YTD'!P20 -> 0 | Z20: =F20-'Quarterly YTD'!Q20 -> 0 | AA20: 0 | AB20: ='Quarterly YTD'!T20-AA20 -> 0 | AC20: ='Quarterly YTD'!U20-'Quarterly YTD'!T20 -> 0 | AD20: =G20-'Quarterly YTD'!U20 -> 0 | AE20: 0 | AF20: ='Quarterly YTD'!X20-AE20 -> 0 | AG20: ='Quarterly YTD'!Y20-'Quarterly YTD'!X20 -> 0 | AH20: =H20-'Quarterly YTD'!Y20 -> -116.838 | AI20: -59.905 | AJ20: ='Quarterly YTD'!AB20-AI20 -> -46.247 | AK20: ='Quarterly YTD'!AC20-'Quarterly YTD'!AB20+-106.152 -> 0 | AL20: =I20-'Quarterly YTD'!AC20 -> 81.382 | AM20: 0 | AN20: ='Quarterly YTD'!AF20-AM20 -> 20.954 | AO20: =IF(AND(AN20=0,AM20=0),0,IF(OR(AM20=0,AM20="NM",AN20="NM"),"NM",IF(AM20<0,-(AN20/AM20-1),AN20/AM20-1))) -> NM | AP20: =IF(AND(AN20=0,AJ20=0),0,IF(OR(AJ20=0,AJ20="NM",AN20="NM"),"NM",IF(AJ20<0,-(AN20/AJ20-1),AN20/AJ20-1))) -> 1.4530888
A21: Loss for the period | B21: =SUM(B19:B20) -> 9.691 | C21: =C19 -> 12.13 | D21: =D19 -> -51.605 | E21: =E19 -> 34.368 | F21: =F19 -> 11.667 | G21: =G19 -> 68.186 | H21: =SUM(H19:H20) -> -62.583 | I21: =SUM(I19:I20) -> -63.567 | J21: =SUM(J19:J20) -> -34.375 | K21: =K19 -> 0.587 | L21: =SUM(L19:L20) -> 3.05 | M21: =SUM(M19:M20) -> 1.15 | N21: =SUM(N19:N20) -> 7.343 | O21: =O19 -> -7.401 | P21: =SUM(P19:P20) -> 0.654 | Q21: =SUM(Q19:Q20) -> -17.823 | R21: =SUM(R19:R20) -> -27.035 | S21: =S19 -> 1.754 | T21: =SUM(T19:T20) -> 12.833 | U21: =SUM(U19:U20) -> 22.055 | V21: =SUM(V19:V20) -> -2.274 | W21: =W19 -> -12.967 | X21: =SUM(X19:X20) -> 18.052 | Y21: =SUM(Y19:Y20) -> 50.164 | Z21: =SUM(Z19:Z20) -> -43.582 | AA21: =AA19 -> -33.541 | AB21: =SUM(AB19:AB20) -> 30.61 | AC21: =SUM(AC19:AC20) -> 73.72 | AD21: =SUM(AD19:AD20) -> -2.603 | AE21: =AE19 -> -97.555 | AF21: =SUM(AF19:AF20) -> 96.526 | AG21: =SUM(AG19:AG20) -> 84.355 | AH21: =SUM(AH19:AH20) -> -145.909 | AI21: =SUM(AI19:AI20) -> -122.098 | AJ21: =SUM(AJ19:AJ20) -> 11.073 | AK21: =SUM(AK19:AK20) -> 70.983 | AL21: =SUM(AL19:AL20) -> -23.525 | AM21: =SUM(AM19:AM20) -> -59.914 | AN21: =SUM(AN19:AN20) -> -21.919 | AO21: =IF(AND(AN21=0,AM21=0),0,IF(OR(AM21=0,AM21="NM",AN21="NM"),"NM",IF(AM21<0,-(AN21/AM21-1),AN21/AM21-1))) -> 0.63415896 | AP21: =IF(AND(AN21=0,AJ21=0),0,IF(OR(AJ21=0,AJ21="NM",AN21="NM"),"NM",IF(AJ21<0,-(AN21/AJ21-1),AN21/AJ21-1))) -> -2.9794997
A23: Cash Flow Statement
A24: Loss for the period | B24: 9.691 | C24: 12.13 | D24: -51.605 | E24: 34.368 | F24: 11.667 | G24: 68.186 | H24: -62.583 | I24: -63.567 | J24: =I24+'Quarterly YTD'!AF24-'Quarterly YTD'!AB24 -> -34.375 | K24: 0.587 | L24: ='Quarterly YTD'!D24-K24 -> 3.05 | M24: ='Quarterly YTD'!E24-'Quarterly YTD'!D24 -> 1.15 | N24: =C24-'Quarterly YTD'!E24 -> 7.343 | O24: -7.401 | P24: ='Quarterly YTD'!H24-O24 -> 0.654 | Q24: ='Quarterly YTD'!I24-'Quarterly YTD'!H24 -> -17.823 | R24: =D24-'Quarterly YTD'!I24 -> -27.035 | S24: 1.754 | T24: ='Quarterly YTD'!L24-S24 -> 12.833 | U24: ='Quarterly YTD'!M24-'Quarterly YTD'!L24 -> 22.055 | V24: =E24-'Quarterly YTD'!M24 -> -2.274 | W24: -12.967 | X24: ='Quarterly YTD'!P24-W24 -> 18.052 | Y24: ='Quarterly YTD'!Q24-'Quarterly YTD'!P24 -> 50.164 | Z24: =F24-'Quarterly YTD'!Q24 -> -43.582 | AA24: -33.541 | AB24: ='Quarterly YTD'!T24-AA24 -> 30.61 | AC24: ='Quarterly YTD'!U24-'Quarterly YTD'!T24 -> 73.72 | AD24: =G24-'Quarterly YTD'!U24 -> -2.603 | AE24: -97.555 | AF24: ='Quarterly YTD'!X24-AE24 -> 96.525 | AG24: ='Quarterly YTD'!Y24-'Quarterly YTD'!X24 -> 84.356 | AH24: =H24-'Quarterly YTD'!Y24 -> -145.909 | AI24: -122.098 | AJ24: ='Quarterly YTD'!AB24-AI24 -> 11.073 | AK24: ='Quarterly YTD'!AC24-'Quarterly YTD'!AB24 -> 70.983 | AL24: =I24-'Quarterly YTD'!AC24 -> -23.525 | AM24: -59.914 | AN24: ='Quarterly YTD'!AF24-AM24 -> -21.919
A25: Income tax (credit) | B25: 2.952 | C25: 5.712 | D25: 5.796 | E25: 10.26 | F25: 15.779 | G25: 3.945 | H25: -2.197 | I25: 3.712 | J25: =I25+'Quarterly YTD'!AF25-'Quarterly YTD'!AB25 -> -1.707 | K25: 0.408 | L25: ='Quarterly YTD'!D25-K25 -> 0.799 | M25: ='Quarterly YTD'!E25-'Quarterly YTD'!D25 -> 0.529 | N25: =C25-'Quarterly YTD'!E25 -> 3.976 | O25: 1.795 | P25: ='Quarterly YTD'!H25-O25 -> 4.259 | Q25: ='Quarterly YTD'!I25-'Quarterly YTD'!H25 -> -0.902 | R25: =D25-'Quarterly YTD'!I25 -> 0.644 | S25: 4.202 | T25: ='Quarterly YTD'!L25-S25 -> -3.819 | U25: ='Quarterly YTD'!M25-'Quarterly YTD'!L25 -> 3.74 | V25: =E25-'Quarterly YTD'!M25 -> 6.137 | W25: 3.154 | X25: ='Quarterly YTD'!P25-W25 -> 6.655 | Y25: ='Quarterly YTD'!Q25-'Quarterly YTD'!P25 -> 10.666 | Z25: =F25-'Quarterly YTD'!Q25 -> -4.696 | AA25: -3 | AB25: ='Quarterly YTD'!T25-AA25 -> 7.123 | AC25: ='Quarterly YTD'!U25-'Quarterly YTD'!T25 -> 7.781 | AD25: =G25-'Quarterly YTD'!U25 -> -7.959 | AE25: -12.94 | AF25: ='Quarterly YTD'!X25-AE25 -> 7.471 | AG25: ='Quarterly YTD'!Y25-'Quarterly YTD'!X25 -> 22.827 | AH25: =H25-'Quarterly YTD'!Y25 -> -19.555 | AI25: -16.582 | AJ25: ='Quarterly YTD'!AB25-AI25 -> 14.705 | AK25: ='Quarterly YTD'!AC25-'Quarterly YTD'!AB25 -> 20.878 | AL25: =I25-'Quarterly YTD'!AC25 -> -15.289 | AM25: -8.482 | AN25: ='Quarterly YTD'!AF25-AM25 -> 1.186
A26: Depreciation and amortisation | B26: 6.853 | C26: 34.732 | D26: 99.205 | E26: 74.338 | F26: 114.781 | G26: 239.28 | H26: 364.599 | I26: 353.946 | J26: =I26+'Quarterly YTD'!AF26-'Quarterly YTD'!AB26 -> 292.857 | K26: 2.936 | L26: ='Quarterly YTD'!D26-K26 -> 3.23 | M26: ='Quarterly YTD'!E26-'Quarterly YTD'!D26 -> 3.427 | N26: =C26-'Quarterly YTD'!E26 -> 25.139 | O26: 26.639 | P26: ='Quarterly YTD'!H26-O26 -> 26.592 | Q26: ='Quarterly YTD'!I26-'Quarterly YTD'!H26 -> 24.388 | R26: =D26-'Quarterly YTD'!I26 -> 21.586 | S26: 18.04 | T26: ='Quarterly YTD'!L26-S26 -> 17.06 | U26: ='Quarterly YTD'!M26-'Quarterly YTD'!L26 -> 19.107 | V26: =E26-'Quarterly YTD'!M26 -> 20.131 | W26: 21.68 | X26: ='Quarterly YTD'!P26-W26 -> 26.51 | Y26: ='Quarterly YTD'!Q26-'Quarterly YTD'!P26 -> 36.201 | Z26: =F26-'Quarterly YTD'!Q26 -> 30.39 | AA26: 41.974 | AB26: ='Quarterly YTD'!T26-AA26 -> 50.043 | AC26: ='Quarterly YTD'!U26-'Quarterly YTD'!T26 -> 64.571 | AD26: =G26-'Quarterly YTD'!U26 -> 82.692 | AE26: 81.707 | AF26: ='Quarterly YTD'!X26-AE26 -> 89.611 | AG26: ='Quarterly YTD'!Y26-'Quarterly YTD'!X26 -> 93.959 | AH26: =H26-'Quarterly YTD'!Y26 -> 99.322 | AI26: 102.318 | AJ26: ='Quarterly YTD'!AB26-AI26 -> 90.515 | AK26: ='Quarterly YTD'!AC26-'Quarterly YTD'!AB26 -> 91.364 | AL26: =I26-'Quarterly YTD'!AC26 -> 69.749 | AM26: 72.539 | AN26: ='Quarterly YTD'!AF26-AM26 -> 59.205
A27: Increase/(decrease) in the provision for impairment of financial and non-financial assets | B27: 3.923 | C27: 4.925 | D27: 29.244 | E27: 18.152 | F27: 25.886 | G27: 4.222 | H27: 64.234 | I27: 161.607 | J27: =I27+'Quarterly YTD'!AF27-'Quarterly YTD'!AB27 -> 225.411 | K27: 0.626 | L27: ='Quarterly YTD'!D27-K27 -> 0.324 | M27: ='Quarterly YTD'!E27-'Quarterly YTD'!D27 -> 0.889 | N27: =C27-'Quarterly YTD'!E27 -> 3.086 | O27: 1.626 | P27: ='Quarterly YTD'!H27-O27 -> 8.481 | Q27: ='Quarterly YTD'!I27-'Quarterly YTD'!H27 -> 2.206 | R27: =D27-'Quarterly YTD'!I27 -> 16.931 | S27: 0.868 | T27: ='Quarterly YTD'!L27-S27 -> 2.187 | U27: ='Quarterly YTD'!M27-'Quarterly YTD'!L27 -> 0.935 | V27: =E27-'Quarterly YTD'!M27 -> 14.162 | W27: 15.417 | X27: ='Quarterly YTD'!P27-W27 -> -1.552 | Y27: ='Quarterly YTD'!Q27-'Quarterly YTD'!P27 -> -0.269 | Z27: =F27-'Quarterly YTD'!Q27 -> 12.29 | AA27: 0.116 | AB27: ='Quarterly YTD'!T27-AA27 -> -0.566 | AC27: ='Quarterly YTD'!U27-'Quarterly YTD'!T27 -> 2.254 | AD27: =G27-'Quarterly YTD'!U27 -> 2.418 | AE27: -0.285 | AF27: ='Quarterly YTD'!X27-AE27 -> 1.888 | AG27: ='Quarterly YTD'!Y27-'Quarterly YTD'!X27 -> 1.741 | AH27: =H27-'Quarterly YTD'!Y27 -> 60.89 | AI27: -3.851 | AJ27: ='Quarterly YTD'!AB27-AI27 -> -10.334 | AK27: ='Quarterly YTD'!AC27-'Quarterly YTD'!AB27 -> 6.669 | AL27: =I27-'Quarterly YTD'!AC27 -> 169.123 | AM27: 2.003 | AN27: ='Quarterly YTD'!AF27-AM27 -> 47.616
A28: Interest expenses | B28: 1.512 | C28: 8.969 | D28: 38.784 | E28: 33.432 | F28: 47.69 | G28: 82.481 | H28: 137.997 | I28: 114.609 | J28: =I28+'Quarterly YTD'!AF28-'Quarterly YTD'!AB28 -> 93.373 | K28: 0.833 | L28: ='Quarterly YTD'!D28-K28 -> 0.83 | M28: ='Quarterly YTD'!E28-'Quarterly YTD'!D28 -> 0.975 | N28: =C28-'Quarterly YTD'!E28 -> 6.331 | O28: 9.986 | P28: ='Quarterly YTD'!H28-O28 -> 9.192 | Q28: ='Quarterly YTD'!I28-'Quarterly YTD'!H28 -> 10.406 | R28: =D28-'Quarterly YTD'!I28 -> 9.2 | S28: 8.209 | T28: ='Quarterly YTD'!L28-S28 -> 7.375 | U28: ='Quarterly YTD'!M28-'Quarterly YTD'!L28 -> 9.239 | V28: =E28-'Quarterly YTD'!M28 -> 8.609 | W28: 10.146 | X28: ='Quarterly YTD'!P28-W28 -> 11.42 | Y28: ='Quarterly YTD'!Q28-'Quarterly YTD'!P28 -> 13.087 | Z28: =F28-'Quarterly YTD'!Q28 -> 13.037 | AA28: 16.243 | AB28: ='Quarterly YTD'!T28-AA28 -> 18.467 | AC28: ='Quarterly YTD'!U28-'Quarterly YTD'!T28 -> 23.285 | AD28: =G28-'Quarterly YTD'!U28 -> 24.486 | AE28: 29.16 | AF28: ='Quarterly YTD'!X28-AE28 -> 35.895 | AG28: ='Quarterly YTD'!Y28-'Quarterly YTD'!X28 -> 36.123 | AH28: =H28-'Quarterly YTD'!Y28 -> 36.819 | AI28: 35.468 | AJ28: ='Quarterly YTD'!AB28-AI28 -> 29.417 | AK28: ='Quarterly YTD'!AC28-'Quarterly YTD'!AB28 -> 27.632 | AL28: =I28-'Quarterly YTD'!AC28 -> 22.092 | AM28: 22.628 | AN28: ='Quarterly YTD'!AF28-AM28 -> 21.021
A29: Foreign exchange loss | B29: -0.04 | C29: -2.354 | D29: -15.434 | E29: 14.492 | F29: 7.001 | G29: -16.743 | H29: 7.308 | I29: -11.84 | J29: =I29+'Quarterly YTD'!AF29-'Quarterly YTD'!AB29 -> 2.802 | K29: 0.352 | L29: ='Quarterly YTD'!D29-K29 -> -0.549 | M29: ='Quarterly YTD'!E29-'Quarterly YTD'!D29 -> 0.359 | N29: =C29-'Quarterly YTD'!E29 -> -2.516 | O29: 2.687 | P29: ='Quarterly YTD'!H29-O29 -> -3.103 | Q29: ='Quarterly YTD'!I29-'Quarterly YTD'!H29 -> -4.435 | R29: =D29-'Quarterly YTD'!I29 -> -10.583 | S29: 6.477 | T29: ='Quarterly YTD'!L29-S29 -> -3.794 | U29: ='Quarterly YTD'!M29-'Quarterly YTD'!L29 -> 4.813 | V29: =E29-'Quarterly YTD'!M29 -> 6.996 | W29: 0.659 | X29: ='Quarterly YTD'!P29-W29 -> 18.179 | Y29: ='Quarterly YTD'!Q29-'Quarterly YTD'!P29 -> 26.379 | Z29: =F29-'Quarterly YTD'!Q29 -> -38.216 | AA29: -8.876 | AB29: ='Quarterly YTD'!T29-AA29 -> 4.988 | AC29: ='Quarterly YTD'!U29-'Quarterly YTD'!T29 -> 10.772 | AD29: =G29-'Quarterly YTD'!U29 -> -23.627 | AE29: 3.824 | AF29: ='Quarterly YTD'!X29-AE29 -> 1.755 | AG29: ='Quarterly YTD'!Y29-'Quarterly YTD'!X29 -> -12.949 | AH29: =H29-'Quarterly YTD'!Y29 -> 14.678 | AI29: 1.148 | AJ29: ='Quarterly YTD'!AB29-AI29 -> -12.753 | AK29: ='Quarterly YTD'!AC29-'Quarterly YTD'!AB29 -> -2.11 | AL29: =I29-'Quarterly YTD'!AC29 -> 1.875 | AM29: 1.791 | AN29: ='Quarterly YTD'!AF29-AM29 -> 1.246
A30: Discounting effect on financial assets | B30: 0.008 | C30: 0.29 | D30: -0.812 | E30: -1.281 | F30: 3.26 | G30: 3.01 | H30: 2.566 | I30: -0.804 | J30: =I30+'Quarterly YTD'!AF30-'Quarterly YTD'!AB30 -> 0.103 | K30: 0.002 | L30: ='Quarterly YTD'!D30-K30 -> 0 | M30: ='Quarterly YTD'!E30-'Quarterly YTD'!D30 -> 0.113 | N30: =C30-'Quarterly YTD'!E30 -> 0.175 | O30: -0.073 | P30: ='Quarterly YTD'!H30-O30 -> -0.441 | Q30: ='Quarterly YTD'!I30-'Quarterly YTD'!H30 -> -0.049 | R30: =D30-'Quarterly YTD'!I30 -> -0.249 | S30: -0.287 | T30: ='Quarterly YTD'!L30-S30 -> 0.201 | U30: ='Quarterly YTD'!M30-'Quarterly YTD'!L30 -> 0.177 | V30: =E30-'Quarterly YTD'!M30 -> -1.372 | W30: 0.769 | X30: ='Quarterly YTD'!P30-W30 -> 0.432 | Y30: ='Quarterly YTD'!Q30-'Quarterly YTD'!P30 -> 1.939 | Z30: =F30-'Quarterly YTD'!Q30 -> 0.12 | AA30: 1.391 | AB30: ='Quarterly YTD'!T30-AA30 -> 1.398 | AC30: ='Quarterly YTD'!U30-'Quarterly YTD'!T30 -> 0.74 | AD30: =G30-'Quarterly YTD'!U30 -> -0.519 | AE30: 1.308 | AF30: ='Quarterly YTD'!X30-AE30 -> 0.184 | AG30: ='Quarterly YTD'!Y30-'Quarterly YTD'!X30 -> 0.529 | AH30: =H30-'Quarterly YTD'!Y30 -> 0.545 | AI30: -0.006 | AJ30: ='Quarterly YTD'!AB30-AI30 -> -2.4 | AK30: ='Quarterly YTD'!AC30-'Quarterly YTD'!AB30 -> -0.139 | AL30: =I30-'Quarterly YTD'!AC30 -> 1.741 | AM30: -0.252 | AN30: ='Quarterly YTD'!AF30-AM30 -> -1.247
A31: Fair value loss on derivative financial instruments | B31: 0 | C31: 0 | D31: 0 | E31: 0 | F31: 0 | G31: 0 | H31: 0 | I31: 0 | J31: =I31+'Quarterly YTD'!AF31-'Quarterly YTD'!AB31 -> 0 | K31: 0 | L31: ='Quarterly YTD'!D31-K31 -> 0 | M31: ='Quarterly YTD'!E31-'Quarterly YTD'!D31 -> 0 | N31: =C31-'Quarterly YTD'!E31 -> 0 | O31: 0 | P31: ='Quarterly YTD'!H31-O31 -> 0 | Q31: ='Quarterly YTD'!I31-'Quarterly YTD'!H31 -> 0 | R31: =D31-'Quarterly YTD'!I31 -> 0 | S31: 0 | T31: ='Quarterly YTD'!L31-S31 -> 0 | U31: ='Quarterly YTD'!M31-'Quarterly YTD'!L31 -> 0 | V31: =E31-'Quarterly YTD'!M31 -> 0 | W31: 0 | X31: ='Quarterly YTD'!P31-W31 -> 0 | Y31: ='Quarterly YTD'!Q31-'Quarterly YTD'!P31 -> 0 | Z31: =F31-'Quarterly YTD'!Q31 -> 0 | AA31: 0 | AB31: ='Quarterly YTD'!T31-AA31 -> 0 | AC31: ='Quarterly YTD'!U31-'Quarterly YTD'!T31 -> 0 | AD31: =G31-'Quarterly YTD'!U31 -> 0 | AE31: 0 | AF31: ='Quarterly YTD'!X31-AE31 -> 0 | AG31: ='Quarterly YTD'!Y31-'Quarterly YTD'!X31 -> 0 | AH31: =H31-'Quarterly YTD'!Y31 -> 0 | AI31: 0 | AJ31: ='Quarterly YTD'!AB31-AI31 -> 0 | AK31: ='Quarterly YTD'!AC31-'Quarterly YTD'!AB31 -> 0 | AL31: =I31-'Quarterly YTD'!AC31 -> 0 | AM31: 0 | AN31: ='Quarterly YTD'!AF31-AM31 -> 0
A32: Fair value loss | B32: 0.002 | C32: -0.003 | D32: -0.66 | E32: -0.474 | F32: 26.441 | G32: 26.685 | H32: -52.388 | I32: 0.01 | J32: =I32+'Quarterly YTD'!AF32-'Quarterly YTD'!AB32 -> -0.761 | K32: 0 | L32: ='Quarterly YTD'!D32-K32 -> 0 | M32: ='Quarterly YTD'!E32-'Quarterly YTD'!D32 -> 0 | N32: =C32-'Quarterly YTD'!E32 -> -0.003 | O32: 0 | P32: ='Quarterly YTD'!H32-O32 -> 0 | Q32: ='Quarterly YTD'!I32-'Quarterly YTD'!H32 -> -0.003 | R32: =D32-'Quarterly YTD'!I32 -> -0.657 | S32: -1.958 | T32: ='Quarterly YTD'!L32-S32 -> -0.44 | U32: ='Quarterly YTD'!M32-'Quarterly YTD'!L32 -> -0.08 | V32: =E32-'Quarterly YTD'!M32 -> 2.004 | W32: 5.983 | X32: ='Quarterly YTD'!P32-W32 -> 6.122 | Y32: ='Quarterly YTD'!Q32-'Quarterly YTD'!P32 -> 6.36 | Z32: =F32-'Quarterly YTD'!Q32 -> 7.976 | AA32: 6.425 | AB32: ='Quarterly YTD'!T32-AA32 -> 6.625 | AC32: ='Quarterly YTD'!U32-'Quarterly YTD'!T32 -> 6.757 | AD32: =G32-'Quarterly YTD'!U32 -> 6.878 | AE32: 7.032 | AF32: ='Quarterly YTD'!X32-AE32 -> -59.608 | AG32: ='Quarterly YTD'!Y32-'Quarterly YTD'!X32 -> 0 | AH32: =H32-'Quarterly YTD'!Y32 -> 0.188 | AI32: 0.009 | AJ32: ='Quarterly YTD'!AB32-AI32 -> 0.794 | AK32: ='Quarterly YTD'!AC32-'Quarterly YTD'!AB32 -> -0.425 | AL32: =I32-'Quarterly YTD'!AC32 -> -0.368 | AM32: 0.033 | AN32: ='Quarterly YTD'!AF32-AM32 -> -0.001
A33: Hedging initial transaction costs | B33: 0 | C33: 0 | D33: 0 | E33: 0 | F33: 0 | G33: 0 | H33: 1.574 | I33: 1.137 | J33: =I33+'Quarterly YTD'!AF33-'Quarterly YTD'!AB33 -> 0 | K33: 0 | L33: ='Quarterly YTD'!D33-K33 -> 0 | M33: ='Quarterly YTD'!E33-'Quarterly YTD'!D33 -> 0 | N33: =C33-'Quarterly YTD'!E33 -> 0 | O33: 0 | P33: ='Quarterly YTD'!H33-O33 -> 0 | Q33: ='Quarterly YTD'!I33-'Quarterly YTD'!H33 -> 0 | R33: =D33-'Quarterly YTD'!I33 -> 0 | S33: 0 | T33: ='Quarterly YTD'!L33-S33 -> 0 | U33: ='Quarterly YTD'!M33-'Quarterly YTD'!L33 -> 0 | V33: =E33-'Quarterly YTD'!M33 -> 0 | W33: 0 | X33: ='Quarterly YTD'!P33-W33 -> 0 | Y33: ='Quarterly YTD'!Q33-'Quarterly YTD'!P33 -> 0 | Z33: =F33-'Quarterly YTD'!Q33 -> 0 | AA33: 0 | AB33: ='Quarterly YTD'!T33-AA33 -> 0 | AC33: ='Quarterly YTD'!U33-'Quarterly YTD'!T33 -> 0 | AD33: =G33-'Quarterly YTD'!U33 -> 0 | AE33: 0 | AF33: ='Quarterly YTD'!X33-AE33 -> 0 | AG33: ='Quarterly YTD'!Y33-'Quarterly YTD'!X33 -> 1.511 | AH33: =H33-'Quarterly YTD'!Y33 -> 0.063 | AI33: 1.137 | AJ33: ='Quarterly YTD'!AB33-AI33 -> 0 | AK33: ='Quarterly YTD'!AC33-'Quarterly YTD'!AB33 -> 0 | AL33: =I33-'Quarterly YTD'!AC33 -> 0 | AM33: 0 | AN33: ='Quarterly YTD'!AF33-AM33 -> 0
A34: Changes in other reserves | B34: 0 | C34: 0.06 | D34: 0.271 | E34: 0.265 | F34: 0.265 | G34: 1.134 | H34: 0 | I34: 0 | J34: =I34+'Quarterly YTD'!AF34-'Quarterly YTD'!AB34 -> 0 | K34: 0 | L34: ='Quarterly YTD'!D34-K34 -> 0 | M34: ='Quarterly YTD'!E34-'Quarterly YTD'!D34 -> -0.002 | N34: =C34-'Quarterly YTD'!E34 -> 0.062 | O34: 0.072 | P34: ='Quarterly YTD'!H34-O34 -> 0.066 | Q34: ='Quarterly YTD'!I34-'Quarterly YTD'!H34 -> 0.067 | R34: =D34-'Quarterly YTD'!I34 -> 0.066 | S34: 0.066 | T34: ='Quarterly YTD'!L34-S34 -> 0.066 | U34: ='Quarterly YTD'!M34-'Quarterly YTD'!L34 -> 0.067 | V34: =E34-'Quarterly YTD'!M34 -> 0.066 | W34: 0.066 | X34: ='Quarterly YTD'!P34-W34 -> 0.066 | Y34: ='Quarterly YTD'!Q34-'Quarterly YTD'!P34 -> 0.067 | Z34: =F34-'Quarterly YTD'!Q34 -> 0.066 | AA34: 0.066 | AB34: ='Quarterly YTD'!T34-AA34 -> 0.067 | AC34: ='Quarterly YTD'!U34-'Quarterly YTD'!T34 -> 0.066 | AD34: =G34-'Quarterly YTD'!U34 -> 0.935 | AE34: 0.204 | AF34: ='Quarterly YTD'!X34-AE34 -> 0.203 | AG34: ='Quarterly YTD'!Y34-'Quarterly YTD'!X34 -> 0.205 | AH34: =H34-'Quarterly YTD'!Y34 -> -0.612 | AI34: 0 | AJ34: ='Quarterly YTD'!AB34-AI34 -> 0 | AK34: ='Quarterly YTD'!AC34-'Quarterly YTD'!AB34 -> 0 | AL34: =I34-'Quarterly YTD'!AC34 -> 0 | AM34: 0 | AN34: ='Quarterly YTD'!AF34-AM34 -> 0
A35: (Gain)/loss on property, plant and equipment disposals and write-offs | B35: 0.108 | C35: -0.879 | D35: 0.588 | E35: -4.902 | F35: -14.615 | G35: -8.391 | H35: -14.771 | I35: -1.151 | J35: =I35+'Quarterly YTD'!AF35-'Quarterly YTD'!AB35 -> 1.131 | K35: -0.272 | L35: ='Quarterly YTD'!D35-K35 -> 0.449 | M35: ='Quarterly YTD'!E35-'Quarterly YTD'!D35 -> -0.55 | N35: =C35-'Quarterly YTD'!E35 -> -0.506 | O35: 0.289 | P35: ='Quarterly YTD'!H35-O35 -> -0.183 | Q35: ='Quarterly YTD'!I35-'Quarterly YTD'!H35 -> 1.216 | R35: =D35-'Quarterly YTD'!I35 -> -0.734 | S35: 0.445 | T35: ='Quarterly YTD'!L35-S35 -> 0.184 | U35: ='Quarterly YTD'!M35-'Quarterly YTD'!L35 -> 3.033 | V35: =E35-'Quarterly YTD'!M35 -> -8.564 | W35: -15.095 | X35: ='Quarterly YTD'!P35-W35 -> 0.014 | Y35: ='Quarterly YTD'!Q35-'Quarterly YTD'!P35 -> -13.925 | Z35: =F35-'Quarterly YTD'!Q35 -> 14.391 | AA35: 0.366 | AB35: ='Quarterly YTD'!T35-AA35 -> -0.194 | AC35: ='Quarterly YTD'!U35-'Quarterly YTD'!T35 -> 0.352 | AD35: =G35-'Quarterly YTD'!U35 -> -8.915 | AE35: -8.902 | AF35: ='Quarterly YTD'!X35-AE35 -> -2.798 | AG35: ='Quarterly YTD'!Y35-'Quarterly YTD'!X35 -> -4.446 | AH35: =H35-'Quarterly YTD'!Y35 -> 1.375 | AI35: 0.018 | AJ35: ='Quarterly YTD'!AB35-AI35 -> -2.739 | AK35: ='Quarterly YTD'!AC35-'Quarterly YTD'!AB35 -> 0.412 | AL35: =I35-'Quarterly YTD'!AC35 -> 1.158 | AM35: -0.162 | AN35: ='Quarterly YTD'!AF35-AM35 -> -0.277
... A54: Security deposits received | B54: 0.014 | C54: 1.345 | D54: 1.965 | E54: 2.677 | F54: 9.332 | G54: 10.664 | H54: 15.497 | I54: 12.113 | J54: =I54+'Quarterly YTD'!AF54-'Quarterly YTD'!AB54 -> 10.807 | K54: 0.036 | L54: ='Quarterly YTD'!D54-K54 -> 0.288 | M54: ='Quarterly YTD'!E54-'Quarterly YTD'!D54 -> 0.143 | N54: =C54-'Quarterly YTD'!E54 -> 0.878 | O54: 1.434 | P54: ='Quarterly YTD'!H54-O54 -> 0.691 | Q54: ='Quarterly YTD'!I54-'Quarterly YTD'!H54 -> -0.425 | R54: =D54-'Quarterly YTD'!I54 -> 0.265 | S54: 0.041 | T54: ='Quarterly YTD'!L54-S54 -> 2.629 | U54: ='Quarterly YTD'!M54-'Quarterly YTD'!L54 -> -0.799 | V54: =E54-'Quarterly YTD'!M54 -> 0.806 | W54: 4.128 | X54: ='Quarterly YTD'!P54-W54 -> 4.05 | Y54: ='Quarterly YTD'!Q54-'Quarterly YTD'!P54 -> 2.992 | Z54: =F54-'Quarterly YTD'!Q54 -> -1.838 | AA54: 4.345 | AB54: ='Quarterly YTD'!T54-AA54 -> 9.912 | AC54: ='Quarterly YTD'!U54-'Quarterly YTD'!T54 -> -1.408 | AD54: =G54-'Quarterly YTD'!U54 -> -2.185 | AE54: 21.742 | AF54: ='Quarterly YTD'!X54-AE54 -> -10.244 | AG54: ='Quarterly YTD'!Y54-'Quarterly YTD'!X54 -> 2.833 | AH54: =H54-'Quarterly YTD'!Y54 -> 1.166 | AI54: 1.585 | AJ54: ='Quarterly YTD'!AB54-AI54 -> 5.475 | AK54: ='Quarterly YTD'!AC54-'Quarterly YTD'!AB54 -> 1.886 | AL54: =I54-'Quarterly YTD'!AC54 -> 3.167 | AM54: 4.438 | AN54: ='Quarterly YTD'!AF54-AM54 -> 1.316
A55: Cash generated from operating activities | B55: =SUM(B24:B30)+B32+SUM(B34:B35)+B43+SUM(B45:B46)+SUM(B48:B54) -> 22.857 | C55: =SUM(C24:C30)+C32+SUM(C34:C35)+SUM(C37:C38)+SUM(C42:C43)+SUM(C45:C46)+SUM(C48:C54) -> 50.447 | D55: =SUM(D24:D30)+D32+SUM(D34:D35)+SUM(D37:D38)+SUM(D42:D43)+SUM(D45:D46)+SUM(D48:D54) -> 132.888 | E55: =SUM(E24:E30)+E32+SUM(E34:E35)+SUM(E37:E38)+SUM(E42:E43)+SUM(E45:E46)+SUM(E48:E54) -> 84.745 | F55: =SUM(F24:F30)+F32+SUM(F34:F35)+SUM(F37:F38)+SUM(F42:F43)+SUM(F45:F46)+SUM(F48:F54) -> 235.793 | G55: =SUM(G24:G30)+SUM(G32:G35)+G38+SUM(G40:G43)+SUM(G45:G46)+SUM(G48:G54) -> 367.304 | H55: =SUM(H24:H30)+SUM(H32:H33)+H35+H38+SUM(H40:H41)+H43+SUM(H45:H47)+SUM(H49:H51)+SUM(H53:H54) -> 431.774 | I55: =SUM(I24:I30)+SUM(I32:I33)+I35+I38+SUM(I40:I41)+I43+SUM(I45:I47)+SUM(I49:I51)+SUM(I53:I54) -> 370.204 | J55: =I55+'Quarterly YTD'!AF55-'Quarterly YTD'!AB55 -> 292.216 | K55: =SUM(K24:K30)+SUM(K34:K35)+SUM(K45:K46)+SUM(K48:K50)+SUM(K52:K54) -> 6.971 | L55: =SUM(L24:L54) -> 6.297 | M55: =SUM(M24:M54) -> -2.32 | N55: =SUM(N24:N54) -> 39.499 | O55: =SUM(O24:O30)+O32+SUM(O34:O35)+O38+O42+SUM(O45:O46)+SUM(O48:O54) -> 61.513 | P55: =SUM(P24:P54) -> 72.297 | Q55: =SUM(Q24:Q54) -> -40.216 | R55: =SUM(R24:R54) -> 39.294 | S55: =SUM(S24:S30)+S32+SUM(S34:S35)+SUM(S38:S39)+SUM(S42:S43)+SUM(S45:S46)+SUM(S48:S54) -> 18.472 | T55: =SUM(T24:T54) -> 14.883 | U55: =SUM(U24:U54) -> 27.682 | V55: =SUM(V24:V54) -> 23.708 | W55: =SUM(W24:W30)+W32+SUM(W34:W35)+W38+SUM(W42:W43)+SUM(W45:W46)+SUM(W48:W54) -> 49.747 | X55: =SUM(X24:X54) -> 48.655 | Y55: =SUM(Y24:Y54) -> 102.353 | Z55: =SUM(Z24:Z54) -> 35.038 | AA55: =SUM(AA24:AA30)+AA32+SUM(AA34:AA35)+AA38+AA43+SUM(AA45:AA46)+SUM(AA48:AA54) -> 24.817 | AB55: =SUM(AB24:AB54) -> 116.7 | AC55: =SUM(AC24:AC54) -> 130.213 | AD55: =SUM(AD24:AD54) -> 95.574 | AE55: =SUM(AE24:AE30)+SUM(AE32:AE35)+AE38+AE41+AE46+SUM(AE48:AE51)+SUM(AE53:AE54) -> 85.338 | AF55: =SUM(AF24:AF54) -> 133.14 | AG55: =SUM(AG24:AG54) -> 176.844 | AH55: =SUM(AH24:AH54) -> 36.452 | AI55: =SUM(AI24:AI30)+SUM(AI32:AI33)+AI35+AI38+AI41+SUM(AI45:AI46)+SUM(AI49:AI51)+SUM(AI53:AI54) -> 52.193 | AJ55: =SUM(AJ24:AJ54) -> 157.087 | AK55: =SUM(AK24:AK54) -> 181.991 | AL55: =SUM(AL24:AL54) -> -21.067 | AM55: =SUM(AM24:AM30)+SUM(AM32:AM33)+AM35+AM38+AM41+SUM(AM45:AM46)+SUM(AM49:AM51)+SUM(AM53:AM54) -> 51.785 | AN55: =SUM(AN24:AN54) -> 79.507
A56: Interest received | B56: 0.001 | C56: 0.002 | D56: 0.952 | E56: 1.711 | F56: 2.337 | G56: 5.272 | H56: 7.141 | I56: 2.114 | J56: =I56+'Quarterly YTD'!AF56-'Quarterly YTD'!AB56 -> 1.455 | K56: 0 | L56: ='Quarterly YTD'!D56-K56 -> 0.027 | M56: ='Quarterly YTD'!E56-'Quarterly YTD'!D56 -> 0.001 | N56: =C56-'Quarterly YTD'!E56 -> -0.026 | O56: 0 | P56: ='Quarterly YTD'!H56-O56 -> 0.397 | Q56: ='Quarterly YTD'!I56-'Quarterly YTD'!H56 -> 0.029 | R56: =D56-'Quarterly YTD'!I56 -> 0.526 | S56: -2.072 | T56: ='Quarterly YTD'!L56-S56 -> 2.909 | U56: ='Quarterly YTD'!M56-'Quarterly YTD'!L56 -> 0.009 | V56: =E56-'Quarterly YTD'!M56 -> 0.865 | W56: 0.095 | X56: ='Quarterly YTD'!P56-W56 -> -0.082 | Y56: ='Quarterly YTD'!Q56-'Quarterly YTD'!P56 -> 1.466 | Z56: =F56-'Quarterly YTD'!Q56 -> 0.858 | AA56: 0.192 | AB56: ='Quarterly YTD'!T56-AA56 -> 0.065 | AC56: ='Quarterly YTD'!U56-'Quarterly YTD'!T56 -> 0.017 | AD56: =G56-'Quarterly YTD'!U56 -> 4.998 | AE56: 0.607 | AF56: ='Quarterly YTD'!X56-AE56 -> 2.544 | AG56: ='Quarterly YTD'!Y56-'Quarterly YTD'!X56 -> 1.454 | AH56: =H56-'Quarterly YTD'!Y56 -> 2.536 | AI56: 0.65 | AJ56: ='Quarterly YTD'!AB56-AI56 -> 0.368 | AK56: ='Quarterly YTD'!AC56-'Quarterly YTD'!AB56 -> 0.632 | AL56: =I56-'Quarterly YTD'!AC56 -> 0.464 | AM56: 0.18 | AN56: ='Quarterly YTD'!AF56-AM56 -> 0.179
A57: Interest paid | B57: -1.456 | C57: -7.718 | D57: -29.584 | E57: -27.567 | F57: -44.188 | G57: -79.833 | H57: -131.204 | I57: -110.568 | J57: =I57+'Quarterly YTD'!AF57-'Quarterly YTD'!AB57 -> -89.314 | K57: -0.726 | L57: ='Quarterly YTD'!D57-K57 -> -0.414 | M57: ='Quarterly YTD'!E57-'Quarterly YTD'!D57 -> -0.705 | N57: =C57-'Quarterly YTD'!E57 -> -5.873 | O57: -4.566 | P57: ='Quarterly YTD'!H57-O57 -> -14.899 | Q57: ='Quarterly YTD'!I57-'Quarterly YTD'!H57 -> 3.757 | R57: =D57-'Quarterly YTD'!I57 -> -13.876 | S57: 0.005 | T57: ='Quarterly YTD'!L57-S57 -> -13.42 | U57: ='Quarterly YTD'!M57-'Quarterly YTD'!L57 -> -3.06 | V57: =E57-'Quarterly YTD'!M57 -> -11.092 | W57: -3.275 | X57: ='Quarterly YTD'!P57-W57 -> -14.314 | Y57: ='Quarterly YTD'!Q57-'Quarterly YTD'!P57 -> -8.762 | Z57: =F57-'Quarterly YTD'!Q57 -> -17.837 | AA57: -9.784 | AB57: ='Quarterly YTD'!T57-AA57 -> -22.233 | AC57: ='Quarterly YTD'!U57-'Quarterly YTD'!T57 -> -16.214 | AD57: =G57-'Quarterly YTD'!U57 -> -31.602 | AE57: -24.293 | AF57: ='Quarterly YTD'!X57-AE57 -> -33.548 | AG57: ='Quarterly YTD'!Y57-'Quarterly YTD'!X57 -> -29.518 | AH57: =H57-'Quarterly YTD'!Y57 -> -43.845 | AI57: -25.054 | AJ57: ='Quarterly YTD'!AB57-AI57 -> -37.196 | AK57: ='Quarterly YTD'!AC57-'Quarterly YTD'!AB57 -> -20.744 | AL57: =I57-'Quarterly YTD'!AC57 -> -27.574 | AM57: -13.015 | AN57: ='Quarterly YTD'!AF57-AM57 -> -27.981
A58: Income tax paid | B58: -0.931 | C58: -3.536 | D58: -6.885 | E58: -16.208 | F58: -20.421 | G58: -24.529 | H58: -14.017 | I58: -17.702 | J58: =I58+'Quarterly YTD'!AF58-'Quarterly YTD'!AB58 -> -13.607 | K58: -0.067 | L58: ='Quarterly YTD'!D58-K58 -> -1.61 | M58: ='Quarterly YTD'!E58-'Quarterly YTD'!D58 -> 0.11 | N58: =C58-'Quarterly YTD'!E58 -> -1.969 | O58: -0.16 | P58: ='Quarterly YTD'!H58-O58 -> -0.814 | Q58: ='Quarterly YTD'!I58-'Quarterly YTD'!H58 -> -0.354 | R58: =D58-'Quarterly YTD'!I58 -> -5.557 | S58: -4.986 | T58: ='Quarterly YTD'!L58-S58 -> -1.939 | U58: ='Quarterly YTD'!M58-'Quarterly YTD'!L58 -> -10.076 | V58: =E58-'Quarterly YTD'!M58 -> 0.793 | W58: -3.411 | X58: ='Quarterly YTD'!P58-W58 -> -6.827 | Y58: ='Quarterly YTD'!Q58-'Quarterly YTD'!P58 -> -4.432 | Z58: =F58-'Quarterly YTD'!Q58 -> -5.751 | AA58: -11.307 | AB58: ='Quarterly YTD'!T58-AA58 -> 3.794 | AC58: ='Quarterly YTD'!U58-'Quarterly YTD'!T58 -> -12.193 | AD58: =G58-'Quarterly YTD'!U58 -> -4.823 | AE58: -2.367 | AF58: ='Quarterly YTD'!X58-AE58 -> -2.469 | AG58: ='Quarterly YTD'!Y58-'Quarterly YTD'!X58 -> -4.594 | AH58: =H58-'Quarterly YTD'!Y58 -> -4.587 | AI58: -1.631 | AJ58: ='Quarterly YTD'!AB58-AI58 -> -7.657 | AK58: ='Quarterly YTD'!AC58-'Quarterly YTD'!AB58 -> -4.444 | AL58: =I58-'Quarterly YTD'!AC58 -> -3.97 | AM58: -1.405 | AN58: ='Quarterly YTD'!AF58-AM58 -> -3.788
A59: Net cash generated from (used in) operating activities from continuing operations | B59: =SUM(B55:B58) -> 20.471 | C59: =SUM(C55:C58) -> 39.195 | D59: =SUM(D55:D58) -> 97.371 | E59: =SUM(E55:E58) -> 42.681 | F59: =SUM(F55:F58) -> 173.521 | G59: =SUM(G55:G58) -> 268.214 | H59: =SUM(H55:H58) -> 293.694 | I59: =SUM(I55:I58) -> 244.048 | J59: =SUM(J55:J58) -> 190.75 | K59: =K55+SUM(K57:K58) -> 6.178 | L59: =SUM(L55:L58) -> 4.3 | M59: =SUM(M55:M58) -> -2.914 | N59: =SUM(N55:N58) -> 31.631 | O59: =SUM(O55:O58) -> 56.787 | P59: =SUM(P55:P58) -> 56.981 | Q59: =SUM(Q55:Q58) -> -36.784 | R59: =SUM(R55:R58) -> 20.387 | S59: =SUM(S55:S58) -> 11.419 | ... AN59: =SUM(AN55:AN58) -> 47.917
...

Sheet Quarterly YTD
A1: €mm, Dec year-end | B1: FY18 | C1: 1Q19 | D1: 1H19 | E1: 3Q19 | F1: FY19 | G1: 1Q20 | H1: 1H20 | I1: 3Q20 | J1: FY20 | K1: 1Q21 | L1: 1H21 | M1: 3Q21 | N1: FY21 | O1: 1Q22 | P1: 1H22 | Q1: 3Q22 | R1: FY22 | S1: 1Q23 | T1: 1H23 | U1: 3Q23 | V1: FY23 | W1: 1Q24 | X1: 1H24 | Y1: 3Q24 | Z1: FY24 | AA1: 1Q25 | AB1: 1H25 | AC1: 3Q25 | AD1: FY25 | AE1: 1Q26 | AF1: 1H26
A2: Income Statement
A3: Revenue | B3: 432.474 | C3: 93.496 | D3: 205.02 | E3: 320.448 | F3: 607.3 | G3: 267.869 | H3: 400.847 | I3: 534.639 | J3: 695.672 | K3: 162.144 | L3: 368.571 | M3: 668.286 | N3: 1014.891 | O3: 317.129 | P3: 780.635 | Q3: 1344.539 | R3: 1852.686 | S3: 404.776 | T3: 954.678 | U3: 1642.213 | V3: 2262.773 | W3: 508.778 | X3: 1228.894 | Y3: 2057.399 | Z3: 2103.272 | AA3: 457.491 | AB3: 1018.442 | AC3: 1913.128 | AD3: 2189.312 | AE3: 522.848 | AF3: 1114.52
A4: Other income | B4: 0.262 | C4: 0.16 | D4: 0.267 | E4: 0.403 | F4: 0.879 | G4: 1.034 | H4: 12.043 | I4: 13.38 | J4: 13.218 | K4: 0.889 | L4: 2.758 | M4: 4.186 | N4: 3.332 | O4: 0.746 | P4: 2.881 | Q4: 4.346 | R4: 2.832 | S4: 0.783 | T4: 1.196 | U4: 4.762 | V4: 3.466 | W4: 1.109 | X4: 2.167 | Y4: 2.908 | Z4: 2.154 | AA4: 0.771 | AB4: 1.748 | AC4: 3.246 | AD4: 6.403 | AE4: 1.269 | AF4: 3.5
A5: Cost of services and goods | B5: -312.579 | C5: -62.428 | D5: -138.098 | E5: -218.973 | F5: -412.602 | G5: -185.272 | H5: -248.971 | I5: -323.845 | J5: -418.367 | K5: -95.058 | L5: -222.982 | M5: -407.188 | N5: -615.285 | O5: -208.777 | P5: -516.01 | Q5: -863.428 | R5: -1193.407 | S5: -278.055 | T5: -605.372 | U5: -993.456 | V5: -1406.56 | W5: -360.502 | X5: -763.091 | Y5: -1207.142 | Z5: -1187.448 | AA5: -290.996 | AB5: -581.21 | AC5: -1094.342 | AD5: -1202.791 | AE5: -327.944 | AF5: -699.754
A6: Depreciation and amortisation | B6: -6.853 | C6: -2.936 | D6: -6.166 | E6: -9.593 | F6: -34.732 | G6: -26.639 | H6: -53.231 | I6: -77.619 | J6: -99.205 | K6: -18.04 | L6: -35.1 | M6: -54.207 | N6: -74.338 | O6: -21.68 | P6: -48.19 | Q6: -84.391 | R6: -114.781 | S6: -41.974 | T6: -92.017 | U6: -156.588 | V6: -239.28 | W6: -81.707 | X6: -171.318 | Y6: -265.277 | Z6: -220.229 | AA6: -62.883 | AB6: -123.235 | AC6: -284.197 | AD6: -265.414 | AE6: -72.539 | AF6: -125.86
A7: Employee related expenses | B7: -71.907 | C7: -20.556 | D7: -41.589 | E7: -61.923 | F7: -96.702 | G7: -39.977 | H7: -72.448 | I7: -108.718 | J7: -145.734 | K7: -38.995 | L7: -82.325 | M7: -134.315 | N7: -200.189 | O7: -66.068 | P7: -142.623 | Q7: -221.076 | R7: -306.593 | S7: -85.755 | T7: -181.897 | U7: -282.972 | V7: -395.763 | W7: -115.571 | X7: -240.08 | Y7: -363.562 | Z7: -470.48 | AA7: -128.452 | AB7: -254.09 | AC7: -402.217 | AD7: -519.925 | AE7: -141.944 | AF7: -278.917
A8: Other operating expenses | B8: -22.952 | C8: -5.566 | D8: -12.151 | E8: -18.504 | F8: -34.741 | G8: -12.328 | H8: -22.284 | I8: -32.791 | J8: -46.596 | K8: -11.52 | L8: -24.036 | M8: -38.095 | N8: -68.488 | O8: -17.336 | P8: -34.888 | Q8: -58.404 | R8: -79.919 | S8: -21.85 | T8: -41.749 | U8: -66.202 | V8: -97.36 | W8: -32.188 | X8: -63.586 | Y8: -97.835 | Z8: -121.492 | AA8: -33.392 | AB8: -56.638 | AC8: -101.418 | AD8: -127.501 | AE8: -26.695 | AF8: -53.519
A9: (Increase)/decrease in the provision for impairment of financial assets | B9: -1.558 | C9: -0.219 | D9: -0.197 | E9: -0.676 | F9: -1.389 | G9: -1.37 | H9: -7.588 | I9: -7.849 | J9: -21.9 | K9: -0.236 | L9: -1.799 | M9: -2.399 | N9: -12.438 | O9: -9.311 | P9: -9.675 | Q9: -8.934 | R9: -12.251 | S9: -0.133 | T9: 2.032 | U9: 0.204 | V9: -0.919 | W9: 1.105 | X9: 0.723 | Y9: 0.508 | Z9: -3.33 | AA9: -2.974 | AB9: 1.733 | AC9: 6.195 | AD9: -159.559 | AE9: -1.113 | AF9: -30.363
A10: (Increase)/decrease in the provision for impairment of non-financial assets | B10: -2.365 | C10: -0.407 | D10: -0.753 | E10: -1.163 | F10: -3.536 | G10: -0.256 | H10: -2.519 | I10: -4.464 | J10: -7.344 | K10: -0.632 | L10: -1.256 | M10: -1.591 | N10: -5.714 | O10: -6.106 | P10: -4.19 | Q10: -4.662 | R10: -13.635 | S10: 0.017 | T10: -1.582 | U10: -2.008 | V10: -3.303 | W10: -0.82 | X10: -2.326 | Y10: -3.852 | Z10: -12.561 | AA10: -0.225 | AB10: 6.369 | AC10: 1.321 | AD10: -4.535 | AE10: -0.89 | AF10: -11.646
A11: Other gains - net | B11: 0.016 | C11: 0.657 | D11: 0.589 | E11: 0.457 | F11: 1.29 | G11: 0.377 | H11: 7.2 | I11: 10.639 | J11: 12.021 | K11: 13.473 | L11: 24.294 | M11: 30.313 | N11: 38.199 | O11: 19.732 | P11: 27.516 | Q11: 42.042 | R11: 27.045 | S11: 3.463 | T11: 7.455 | U11: 14.823 | V11: 36.603 | W11: 10.448 | X11: 16.347 | Y11: 18.547 | Z11: 3.219 | AA11: -1.645 | AB11: 2.111 | AC11: 9.995 | AD11: 17.514 | AE11: 1.756 | AF11: 10.64
A12: Operating (loss)/profit | B12: =SUM(B3:B11) -> 14.538 | C12: =SUM(C3:C11) -> 2.201 | D12: =SUM(D3:D11) -> 6.922 | E12: =SUM(E3:E11) -> 10.476 | F12: =SUM(F3:F11) -> 25.767 | G12: =SUM(G3:G11) -> 3.438 | H12: =SUM(H3:H11) -> 13.049 | I12: =SUM(I3:I11) -> 3.372 | ... AF12: =SUM(AF3:AF11) -> -71.399
A13: Finance income | B13: 0.067 | C13: 0.003 | D13: 0.032 | E13: 0.356 | F13: 3.05 | G13: 1.059 | H13: 5.179 | I13: 4.735 | J13: 12.271 | K13: 2.403 | L13: 3.17 | M13: 2.667 | N13: 2.919 | O13: 0.094 | P13: 0.192 | Q13: 2.297 | R13: 3.901 | S13: 6.358 | T13: 7.084 | U13: 4.576 | V13: 24.747 | W13: 0.593 | X13: 54.812 | Y13: 63.961 | Z13: 58.254 | AA13: 7.109 | AB13: 18.676 | AC13: 21.077 | AD13: 15.295 | AE13: 0.412 | AF13: 1.134
A14: Finance costs | B14: -1.962 | C14: -1.155 | D14: -2.031 | E14: -3.371 | F14: -9.948 | G14: -10.943 | H14: -20.77 | I14: -30.936 | J14: -38.655 | K14: -8.494 | L14: -16.343 | M14: -26.843 | N14: -39.719 | O14: -18.259 | P14: -40.747 | Q14: -76.592 | R14: -83.341 | S14: -24.175 | T14: -50.733 | U14: -85.137 | V14: -114.979 | W14: -41.744 | X14: -69.044 | Y14: -104.976 | Z14: -92.387 | AA14: -23.988 | AB14: -40.258 | AC14: -93.841 | AD14: -93.369 | AE14: -23.556 | AF14: -44.093
A15: Finance costs – net | B15: =SUM(B13:B14) -> -1.895 | C15: =SUM(C13:C14) -> -1.152 | D15: =SUM(D13:D14) -> -1.999 | E15: =SUM(E13:E14) -> -3.015 | F15: =SUM(F13:F14) -> -6.898 | G15: =SUM(G13:G14) -> -9.884 | H15: =SUM(H13:H14) -> -15.591 | I15: =SUM(I13:I14) -> -26.201 | ... AF15: =SUM(AF13:AF14) -> -42.959
A16: Share of profit of equity-accounted investees | B16: 0 | C16: -0.054 | D16: -0.079 | E16: -0.938 | F16: -1.027 | G16: 0.84 | H16: 1.849 | I16: 3.411 | J16: -1.19 | K16: 0.022 | L16: 0.018 | M16: -0.049 | N16: 1.458 | O16: 0.023 | P16: -0.007 | Q16: -0.013 | R16: -55.091 | S16: 0.004 | T16: 2.097 | U16: 2.478 | V16: 2.706 | W16: 0.004 | X16: 0.004 | Y16: 0.005 | Z16: 0.013 | AA16: 0 | AB16: 0.012 | AC16: 0.012 | AD16: -0.255 | AE16: 0 | AF16: 0.005
A17: Loss before income tax | B17: =B12+SUM(B15:B16) -> 12.643 | C17: =C12+SUM(C15:C16) -> 0.995 | D17: =D12+SUM(D15:D16) -> 4.844 | E17: =E12+SUM(E15:E16) -> 6.523 | F17: =F12+SUM(F15:F16) -> 17.842 | G17: =G12+SUM(G15:G16) -> -5.606 | H17: =H12+SUM(H15:H16) -> -0.693 | I17: =I12+SUM(I15:I16) -> -19.418 | ... AF17: =AF12+SUM(AF15:AF16) -> -114.353
A18: Income tax credit | B18: -2.952 | C18: -0.408 | D18: -1.207 | E18: -1.736 | F18: -5.712 | G18: -1.795 | H18: -6.054 | I18: -5.152 | J18: -5.796 | K18: -4.202 | L18: -0.383 | M18: -4.123 | N18: -10.26 | O18: -3.154 | P18: -9.809 | Q18: -20.475 | R18: -15.779 | S18: 3 | T18: -4.123 | U18: -11.904 | V18: -3.945 | W18: 12.94 | X18: 5.469 | Y18: -17.358 | Z18: -4.73 | AA18: 16.991 | AB18: 1.467 | AC18: -19.001 | AD18: -0.124 | AE18: 8.482 | AF18: 11.566
A19: Loss for the period | B19: =SUM(B17:B18) -> 9.691 | C19: =SUM(C17:C18) -> 0.587 | D19: =SUM(D17:D18) -> 3.637 | E19: =SUM(E17:E18) -> 4.787 | F19: =SUM(F17:F18) -> 12.13 | G19: =SUM(G17:G18) -> -7.401 | H19: =SUM(H17:H18) -> -6.747 | I19: =SUM(I17:I18) -> -24.57 | ... AF19: =SUM(AF17:AF18) -> -102.787
A20: Gain/(loss) for the period from discontinued operations | B20: 0 | C20: 0 | D20: 0 | E20: 0 | F20: 0 | G20: 0 | H20: 0 | I20: 0 | J20: 0 | K20: 0 | L20: 0 | M20: 0 | N20: 0 | O20: 0 | P20: 0 | Q20: 0 | R20: 0 | S20: 0 | T20: 0 | U20: 0 | V20: 0 | W20: 0 | X20: 0 | Y20: 0 | Z20: -116.838 | AA20: -59.905 | AB20: -106.152 | AC20: 0 | AD20: 81.382 | AE20: 0 | AF20: 20.954
A21: Loss for the period | B21: =SUM(B19:B20) -> 9.691 | C21: =C19 -> 0.587 | D21: =D19 -> 3.637 | E21: =E19 -> 4.787 | F21: =F19 -> 12.13 | G21: =G19 -> -7.401 | H21: =H19 -> -6.747 | I21: =I19 -> -24.57 | J21: =J19 -> -51.605 | ... Y21: =Y19 -> 83.326 | Z21: =SUM(Z19:Z20) -> -62.583 | AA21: =SUM(AA19:AA20) -> -122.098 | AB21: =SUM(AB19:AB20) -> -111.025 | AC21: =AC19 -> -40.042 | AD21: =SUM(AD19:AD20) -> -63.567 | AE21: =SUM(AE19:AE20) -> -59.914 | AF21: =SUM(AF19:AF20) -> -81.833
A23: Cash Flow Statement
