Workbook

Sheet Annual and Quarterly
A1: $mm, Dec year-end | B1: FY22 | C1: FY23 | D1: FY24 | E1: FY25 | F1: LTM | G1: 3Q23 | H1: 4Q23 | I1: 1Q24 | J1: 2Q24 | K1: 3Q24 | L1: 4Q24 | M1: 1Q25 | N1: 2Q25 | O1: 3Q25 | P1: 4Q25 | Q1: 1Q26 | R1: 2Q26 | S1: Q/o/Q | T1: Y/o/Y
A2: Income Statement
A3: Revenues | B3: 308.10876 | C3: 356.19708 | D3: 355.99368 | E3: 408.64877 | F3: =E3+'Quarterly YTD'!O3-'Quarterly YTD'!K3 -> 445.67177 | G3: 71.173501 | H3: =C3-'Quarterly YTD'!D3 -> 92.106065 | I3: 85.804548 | J3: 88.795866 | K3: 88.056758 | L3: =D3-'Quarterly YTD'!H3 -> 93.33651 | M3: 93.498313 | N3: 100.30978 | O3: 106.75608 | P3: =E3-'Quarterly YTD'!L3 -> 108.0846 | Q3: 114.34153 | R3: 116.48956 | S3: =IF(AND(R3=0,Q3=0),0,IF(OR(Q3=0,Q3="NM",R3="NM"),"NM",IF(Q3<0,-(R3/Q3-1),R3/Q3-1))) -> 0.018786061 | T3: =IF(AND(R3=0,N3=0),0,IF(OR(N3=0,N3="NM",R3="NM"),"NM",IF(N3<0,-(R3/N3-1),R3/N3-1))) -> 0.16129816
A4: Operating costs and commissions | B4: -136.08515 | C4: -139.63505 | D4: -145.86452 | E4: -144.11926 | F4: =E4+'Quarterly YTD'!O4-'Quarterly YTD'!K4 -> -149.35098 | G4: -29.166475 | H4: =C4-'Quarterly YTD'!D4 -> -31.506634 | I4: -31.334551 | J4: -37.769739 | K4: -41.459787 | L4: =D4-'Quarterly YTD'!H4 -> -35.30044 | M4: -34.165761 | N4: -35.956565 | O4: -35.515765 | P4: =E4-'Quarterly YTD'!L4 -> -38.481171 | Q4: -37.420421 | R4: -37.933622 | S4: =IF(AND(R4=0,Q4=0),0,IF(OR(Q4=0,Q4="NM",R4="NM"),"NM",IF(Q4<0,(R4/Q4-1),-(R4/Q4-1)))) -> 0.013714464 | T4: =IF(AND(R4=0,N4=0),0,IF(OR(N4=0,N4="NM",R4="NM"),"NM",IF(N4<0,(R4/N4-1),-(R4/N4-1)))) -> 0.05498459
A5: Administrative, marketing and selling expenses | B5: -108.12485 | C5: -115.29811 | D5: -130.95791 | E5: -130.081 | F5: =E5+'Quarterly YTD'!O5-'Quarterly YTD'!K5 -> -142.36757 | G5: -20.450035 | H5: =C5-'Quarterly YTD'!D5 -> -35.695191 | I5: -28.487093 | J5: -28.482691 | K5: -31.407928 | L5: =D5-'Quarterly YTD'!H5 -> -42.580194 | M5: -30.456847 | N5: -34.716748 | O5: -26.436797 | P5: =E5-'Quarterly YTD'!L5 -> -38.470608 | Q5: -37.877638 | R5: -39.582525 | S5: =IF(AND(R5=0,Q5=0),0,IF(OR(Q5=0,Q5="NM",R5="NM"),"NM",IF(Q5<0,(R5/Q5-1),-(R5/Q5-1)))) -> 0.045010383 | T5: =IF(AND(R5=0,N5=0),0,IF(OR(N5=0,N5="NM",R5="NM"),"NM",IF(N5<0,(R5/N5-1),-(R5/N5-1)))) -> 0.14015647
A6: Depreciation of tangible assets | B6: -42.745142 | C6: -47.380285 | D6: -48.614609 | E6: -50.741037 | F6: =E6+'Quarterly YTD'!O6-'Quarterly YTD'!K6 -> -56.226568 | G6: -10.386751 | H6: =C6-'Quarterly YTD'!D6 -> -11.997254 | I6: -12.244525 | J6: -13.211034 | K6: -10.236228 | L6: =D6-'Quarterly YTD'!H6 -> -12.922822 | M6: -12.306473 | N6: -11.951909 | O6: -13.19391 | P6: =E6-'Quarterly YTD'!L6 -> -13.288745 | Q6: -15.027019 | R6: -14.716894 | S6: =IF(AND(R6=0,Q6=0),0,IF(OR(Q6=0,Q6="NM",R6="NM"),"NM",IF(Q6<0,(R6/Q6-1),-(R6/Q6-1)))) -> -0.020637826 | T6: =IF(AND(R6=0,N6=0),0,IF(OR(N6=0,N6="NM",R6="NM"),"NM",IF(N6<0,(R6/N6-1),-(R6/N6-1)))) -> 0.23134254
A7: Amortization of intangible assets | B7: -11.955373 | C7: -15.925177 | D7: -20.609792 | E7: -19.385894 | F7: =E7+'Quarterly YTD'!O7-'Quarterly YTD'!K7 -> -18.961141 | G7: -4.173107 | H7: =C7-'Quarterly YTD'!D7 -> -4.928568 | I7: -5.009905 | J7: -5.304571 | K7: -5.122623 | L7: =D7-'Quarterly YTD'!H7 -> -5.172693 | M7: -4.898694 | N7: -5.10543 | O7: -5.151362 | P7: =E7-'Quarterly YTD'!L7 -> -4.230408 | Q7: -4.784049 | R7: -4.795322 | S7: =IF(AND(R7=0,Q7=0),0,IF(OR(Q7=0,Q7="NM",R7="NM"),"NM",IF(Q7<0,(R7/Q7-1),-(R7/Q7-1)))) -> 0.0023563722 | T7: =IF(AND(R7=0,N7=0),0,IF(OR(N7=0,N7="NM",R7="NM"),"NM",IF(N7<0,(R7/N7-1),-(R7/N7-1)))) -> -0.060740819
A8: (Provision)/write-back for expected credit losses on trade receivables | B8: 0 | C8: 0 | D8: 0 | E8: 0 | F8: =E8+'Quarterly YTD'!O8-'Quarterly YTD'!K8 -> 0 | G8: 0 | H8: =C8-'Quarterly YTD'!D8 -> 0 | I8: 0 | J8: 0 | K8: 0 | L8: =D8-'Quarterly YTD'!H8 -> 0 | M8: 0.039965 | N8: 0 | O8: 0 | P8: =E8-'Quarterly YTD'!L8 -> 0 | Q8: -0.115606 | R8: 0 | S8: =IF(AND(R8=0,Q8=0),0,IF(OR(Q8=0,Q8="NM",R8="NM"),"NM",IF(Q8<0,(R8/Q8-1),-(R8/Q8-1)))) -> -1 | T8: =IF(AND(R8=0,N8=0),0,IF(OR(N8=0,N8="NM",R8="NM"),"NM",IF(N8<0,(R8/N8-1),-(R8/N8-1)))) -> 0
A9: Write-back/(provision) for expected credit losses on trade receivables | B9: -1.660354 | C9: 1.024685 | D9: -0.904712 | E9: -0.605485 | F9: =E9+'Quarterly YTD'!O9-'Quarterly YTD'!K9 -> -0.218586 | G9: -0.008508 | H9: =C9-'Quarterly YTD'!D9 -> 1.056003 | I9: -0.008613 | J9: -0.07367 | K9: -0.455058 | L9: =D9-'Quarterly YTD'!H9 -> -0.367371 | M9: 0 | N9: -0.005824 | O9: -0.03522 | P9: =E9-'Quarterly YTD'!L9 -> -0.604406 | Q9: 0 | R9: 0.536646 | S9: =IF(AND(R9=0,Q9=0),0,IF(OR(Q9=0,Q9="NM",R9="NM"),"NM",IF(Q9<0,-(R9/Q9-1),R9/Q9-1))) -> NM | T9: =IF(AND(R9=0,N9=0),0,IF(OR(N9=0,N9="NM",R9="NM"),"NM",IF(N9<0,-(R9/N9-1),R9/N9-1))) -> 93.143887
A10: Provision for expected credit losses on balances due from related parties | B10: -0.390413 | C10: 0 | D10: -0.12936 | E10: -0.065328 | F10: =E10+'Quarterly YTD'!O10-'Quarterly YTD'!K10 -> -0.432576 | G10: 0 | H10: =C10-'Quarterly YTD'!D10 -> 0 | I10: 0 | J10: 0 | K10: -0.12936 | L10: =D10-'Quarterly YTD'!H10 -> 0 | M10: 0 | N10: -0.013296 | O10: -0.013345 | P10: =E10-'Quarterly YTD'!L10 -> -0.013296 | Q10: -0.338567 | R10: -0.067368 | S10: =IF(AND(R10=0,Q10=0),0,IF(OR(Q10=0,Q10="NM",R10="NM"),"NM",IF(Q10<0,-(R10/Q10-1),R10/Q10-1))) -> 0.80102018 | T10: =IF(AND(R10=0,N10=0),0,IF(OR(N10=0,N10="NM",R10="NM"),"NM",IF(N10<0,-(R10/N10-1),R10/N10-1))) -> -4.066787
A11: Receivables written off | B11: 0 | C11: 0 | D11: -0.072471 | E11: -0.06976 | F11: =E11+'Quarterly YTD'!O11-'Quarterly YTD'!K11 -> -0.084892 | G11: 0 | H11: =C11-'Quarterly YTD'!D11 -> 0 | I11: 0 | J11: 0 | K11: 0 | L11: =D11-'Quarterly YTD'!H11 -> -0.072471 | M11: 0 | N11: 0 | O11: 0 | P11: =E11-'Quarterly YTD'!L11 -> -0.06976 | Q11: 0 | R11: -0.015132 | S11: =IF(AND(R11=0,Q11=0),0,IF(OR(Q11=0,Q11="NM",R11="NM"),"NM",IF(Q11<0,(R11/Q11-1),-(R11/Q11-1)))) -> NM | T11: =IF(AND(R11=0,N11=0),0,IF(OR(N11=0,N11="NM",R11="NM"),"NM",IF(N11<0,(R11/N11-1),-(R11/N11-1)))) -> NM
A12: Other gain/(loss), net | B12: 8.760054 | C12: 12.047365 | D12: 1.444997 | E12: 4.922003 | F12: =E12+'Quarterly YTD'!O12-'Quarterly YTD'!K12 -> 5.827131 | G12: 0.649341 | H12: =C12-'Quarterly YTD'!D12 -> 11.983504 | I12: 0.289148 | J12: -0.703136 | K12: 1.788856 | L12: =D12-'Quarterly YTD'!H12 -> 0.070129 | M12: 0.095351 | N12: -0.20662 | O12: 1.138677 | P12: =E12-'Quarterly YTD'!L12 -> 3.869204 | Q12: -0.272845 | R12: 1.092095 | S12: =IF(AND(R12=0,Q12=0),0,IF(OR(Q12=0,Q12="NM",R12="NM"),"NM",IF(Q12<0,-(R12/Q12-1),R12/Q12-1))) -> 5.0026205 | T12: =IF(AND(R12=0,N12=0),0,IF(OR(N12=0,N12="NM",R12="NM"),"NM",IF(N12<0,-(R12/N12-1),R12/N12-1))) -> 6.2855242
A13: OPERATING PROFIT | B13: =SUM(B3:B7)+SUM(B9:B10)+B12 -> 15.907529 | C13: =SUM(C3:C7)+SUM(C9:C12) -> 51.030502 | D13: =SUM(D3:D7)+SUM(D9:D12) -> 10.285312 | E13: =SUM(E3:E7)+SUM(E9:E12) -> 68.503009 | F13: =E13+'Quarterly YTD'!O13-'Quarterly YTD'!K13 -> 83.856592 | G13: =SUM(G3:G7)+SUM(G9:G10)+G12 -> 7.637966 | H13: =SUM(H3:H12) -> 21.017925 | I13: =SUM(I3:I7)+I9+I12 -> 9.009009 | J13: =SUM(J3:J7)+J9+J12 -> 3.251025 | K13: =SUM(K3:K7)+SUM(K9:K10)+K12 -> 1.03463 | L13: =SUM(L3:L12) -> -3.009352 | M13: =SUM(M3:M8)+M10+M12 -> 11.805854 | N13: =SUM(N3:N7)+SUM(N9:N12) -> 12.353383 | O13: =SUM(O3:O7)+SUM(O9:O10)+O12 -> 27.54836 | P13: =SUM(P3:P12) -> 16.795412 | Q13: =SUM(Q3:Q8)+Q10+Q12 -> 18.505385 | R13: =SUM(R3:R7)+SUM(R9:R12) -> 21.007435 | S13: =IF(AND(R13=0,Q13=0),0,IF(OR(Q13=0,Q13="NM",R13="NM"),"NM",IF(Q13<0,-(R13/Q13-1),R13/Q13-1))) -> 0.13520659 | T13: =IF(AND(R13=0,N13=0),0,IF(OR(N13=0,N13="NM",R13="NM"),"NM",IF(N13<0,-(R13/N13-1),R13/N13-1))) -> 0.70054106
A14: Interest income on balances due from related parties | B14: 1.932958 | C14: 2.126254 | D14: 2.33888 | E14: 2.572767 | F14: =E14+'Quarterly YTD'!O14-'Quarterly YTD'!K14 -> 2.572767 | G14: 0 | H14: =C14-'Quarterly YTD'!D14 -> 2.126254 | I14: 0 | J14: 0 | K14: 0 | L14: =D14-'Quarterly YTD'!H14 -> 2.33888 | M14: 0 | N14: 0 | O14: 0 | P14: =E14-'Quarterly YTD'!L14 -> 2.572767 | Q14: 0 | R14: 0 | S14: =IF(AND(R14=0,Q14=0),0,IF(OR(Q14=0,Q14="NM",R14="NM"),"NM",IF(Q14<0,-(R14/Q14-1),R14/Q14-1))) -> 0 | T14: =IF(AND(R14=0,N14=0),0,IF(OR(N14=0,N14="NM",R14="NM"),"NM",IF(N14<0,-(R14/N14-1),R14/N14-1))) -> 0
A15: Interest income on balances due from a related party | B15: 0 | C15: 0 | D15: 0 | E15: 0 | F15: =E15+'Quarterly YTD'!O15-'Quarterly YTD'!K15 -> 0.128638 | G15: 0.531564 | H15: =C15-'Quarterly YTD'!D15 -> -1.594691 | I15: 0.58472 | J15: 0.58472 | K15: 0.58472 | L15: =D15-'Quarterly YTD'!H15 -> -1.75416 | M15: 0.643189 | N15: 0.643195 | O15: 0.643192 | P15: =E15-'Quarterly YTD'!L15 -> -1.929576 | Q15: 0.707511 | R15: 0.707511 | S15: =IF(AND(R15=0,Q15=0),0,IF(OR(Q15=0,Q15="NM",R15="NM"),"NM",IF(Q15<0,-(R15/Q15-1),R15/Q15-1))) -> 0 | T15: =IF(AND(R15=0,N15=0),0,IF(OR(N15=0,N15="NM",R15="NM"),"NM",IF(N15<0,-(R15/N15-1),R15/N15-1))) -> 0.099994558
A16: Other interest income | B16: 0.187722 | C16: 0.156096 | D16: 0.329062 | E16: 0.269998 | F16: =E16+'Quarterly YTD'!O16-'Quarterly YTD'!K16 -> 0.501385 | G16: 0.038724 | H16: =C16-'Quarterly YTD'!D16 -> 0.040954 | I16: 0.040809 | J16: 0.038332 | K16: 0.037117 | L16: =D16-'Quarterly YTD'!H16 -> 0.212804 | M16: 0.109547 | N16: 0.047734 | O16: 0.072899 | P16: =E16-'Quarterly YTD'!L16 -> 0.039818 | Q16: 0.236924 | R16: 0.151744 | S16: =IF(AND(R16=0,Q16=0),0,IF(OR(Q16=0,Q16="NM",R16="NM"),"NM",IF(Q16<0,-(R16/Q16-1),R16/Q16-1))) -> -0.35952457 | T16: =IF(AND(R16=0,N16=0),0,IF(OR(N16=0,N16="NM",R16="NM"),"NM",IF(N16<0,-(R16/N16-1),R16/N16-1))) -> 2.17895
A17: Finance costs, net | B17: -55.213244 | C17: -64.737849 | D17: -74.276529 | E17: -71.039195 | F17: =E17+'Quarterly YTD'!O17-'Quarterly YTD'!K17 -> -77.784129 | G17: -13.691071 | H17: =C17-'Quarterly YTD'!D17 -> -16.487628 | I17: -15.328047 | J17: -15.410468 | K17: -15.632486 | L17: =D17-'Quarterly YTD'!H17 -> -27.905528 | M17: -17.043553 | N17: -17.184806 | O17: -17.741476 | P17: =E17-'Quarterly YTD'!L17 -> -19.06936 | Q17: -20.252271 | R17: -20.721022 | S17: =IF(AND(R17=0,Q17=0),0,IF(OR(Q17=0,Q17="NM",R17="NM"),"NM",IF(Q17<0,(R17/Q17-1),-(R17/Q17-1)))) -> 0.023145602 | T17: =IF(AND(R17=0,N17=0),0,IF(OR(N17=0,N17="NM",R17="NM"),"NM",IF(N17<0,(R17/N17-1),-(R17/N17-1)))) -> 0.20577573
A18: Loss on exchange, net | B18: -24.108535 | C18: -114.15174 | D18: -39.271284 | E18: 37.680522 | F18: =E18+'Quarterly YTD'!O18-'Quarterly YTD'!K18 -> 33.66656 | G18: 2.115323 | H18: =C18-'Quarterly YTD'!D18 -> -30.669429 | I18: -12.388792 | J18: -10.767847 | K18: -10.3553 | L18: =D18-'Quarterly YTD'!H18 -> -5.759345 | M18: -5.577573 | N18: -7.600561 | O18: 15.383757 | P18: =E18-'Quarterly YTD'!L18 -> 35.474899 | Q18: -13.410153 | R18: -3.781943 | S18: =IF(AND(R18=0,Q18=0),0,IF(OR(Q18=0,Q18="NM",R18="NM"),"NM",IF(Q18<0,(R18/Q18-1),-(R18/Q18-1)))) -> -0.71797913 | T18: =IF(AND(R18=0,N18=0),0,IF(OR(N18=0,N18="NM",R18="NM"),"NM",IF(N18<0,(R18/N18-1),-(R18/N18-1)))) -> -0.50241265
A19: Net (loss)/gain on net monetary position | B19: 0 | C19: 21.543365 | D19: 3.558212 | E19: -1.599516 | F19: =E19+'Quarterly YTD'!O19-'Quarterly YTD'!K19 -> 1.419819 | G19: -3.066506 | H19: =C19-'Quarterly YTD'!D19 -> -7.755996 | I19: 3.717688 | J19: 0.254449 | K19: -1.266755 | L19: =D19-'Quarterly YTD'!H19 -> 0.85283 | M19: -0.211588 | N19: -0.017313 | O19: 0.6408 | P19: =E19-'Quarterly YTD'!L19 -> -2.011415 | Q19: 2.791561 | R19: -0.001127 | S19: =IF(AND(R19=0,Q19=0),0,IF(OR(Q19=0,Q19="NM",R19="NM"),"NM",IF(Q19<0,-(R19/Q19-1),R19/Q19-1))) -> -1.0004037 | T19: =IF(AND(R19=0,N19=0),0,IF(OR(N19=0,N19="NM",R19="NM"),"NM",IF(N19<0,-(R19/N19-1),R19/N19-1))) -> 0.93490441
A20: LOSS BEFORE INCOME TAX FROM CONTINUING OPERATIONS | B20: =SUM(B13:B14)+SUM(B16:B18) -> -61.29357 | C20: =SUM(C13:C14)+SUM(C16:C19) -> -104.03337 | D20: =SUM(D13:D14)+SUM(D16:D19) -> -97.036347 | E20: =SUM(E13:E14)+SUM(E16:E19) -> 36.387585 | F20: =E20+'Quarterly YTD'!O20-'Quarterly YTD'!K20 -> 44.361632 | G20: =G13+SUM(G15:G19) -> -6.434 | H20: =SUM(H13:H19) -> -33.322611 | I20: =I13+SUM(I15:I19) -> -14.364613 | J20: =J13+SUM(J15:J19) -> -22.049789 | K20: =K13+SUM(K15:K19) -> -25.598074 | L20: =SUM(L13:L19) -> -35.023871 | M20: =M13+SUM(M15:M19) -> -10.274124 | N20: =N13+SUM(N15:N19) -> -11.758368 | O20: =O13+SUM(O15:O19) -> 26.547532 | P20: =SUM(P13:P19) -> 31.872545 | Q20: =Q13+SUM(Q15:Q19) -> -11.421043 | R20: =R13+SUM(R15:R19) -> -2.637402 | S20: =IF(AND(R20=0,Q20=0),0,IF(OR(Q20=0,Q20="NM",R20="NM"),"NM",IF(Q20<0,-(R20/Q20-1),R20/Q20-1))) -> 0.76907521 | T20: =IF(AND(R20=0,N20=0),0,IF(OR(N20=0,N20="NM",R20="NM"),"NM",IF(N20<0,-(R20/N20-1),R20/N20-1))) -> 0.7757
A21: Income tax expense | B21: -0.891378 | C21: -11.454357 | D21: -6.737506 | E21: -6.007564 | F21: =E21+'Quarterly YTD'!O21-'Quarterly YTD'!K21 -> -9.937987 | G21: 3.536041 | H21: =C21-'Quarterly YTD'!D21 -> -5.868704 | I21: -1.168225 | J21: -1.159625 | K21: -1.888589 | L21: =D21-'Quarterly YTD'!H21 -> -2.521067 | M21: -0.619647 | N21: -0.722561 | O21: -2.98096 | P21: =E21-'Quarterly YTD'!L21 -> -1.684396 | Q21: -2.331424 | R21: -2.941207 | S21: =IF(AND(R21=0,Q21=0),0,IF(OR(Q21=0,Q21="NM",R21="NM"),"NM",IF(Q21<0,(R21/Q21-1),-(R21/Q21-1)))) -> 0.26154959 | T21: =IF(AND(R21=0,N21=0),0,IF(OR(N21=0,N21="NM",R21="NM"),"NM",IF(N21<0,(R21/N21-1),-(R21/N21-1)))) -> 3.0705311
A22: LOSS FOR THE PERIOD FROM CONTINUING OPERATIONS | B22: =SUM(B20:B21) -> -62.184948 | C22: =SUM(C20:C21) -> -115.48772 | D22: =SUM(D20:D21) -> -103.77385 | E22: =SUM(E20:E21) -> 30.380021 | F22: =SUM(F20:F21) -> 34.423645 | G22: =SUM(G20:G21) -> -2.897959 | H22: =SUM(H20:H21) -> -39.191315 | I22: =SUM(I20:I21) -> -15.532838 | ... R22: =SUM(R20:R21) -> -5.578609 | S22: =IF(AND(R22=0,Q22=0),0,IF(OR(Q22=0,Q22="NM",R22="NM"),"NM",IF(Q22<0,-(R22/Q22-1),R22/Q22-1))) -> 0.59435576 | T22: =IF(AND(R22=0,N22=0),0,IF(OR(N22=0,N22="NM",R22="NM"),"NM",IF(N22<0,-(R22/N22-1),R22/N22-1))) -> 0.55302935
A23: Profit/(loss) for the period from discontinued operations | B23: 0.397799 | C23: 0.001763 | D23: 0.042832 | E23: 0.042544 | F23: =E23+'Quarterly YTD'!O23-'Quarterly YTD'!K23 -> 0.003499 | G23: -0.0208 | H23: =C23-'Quarterly YTD'!D23 -> 0.01314 | I23: -0.026877 | J23: 0.029646 | K23: 0.003847 | L23: =D23-'Quarterly YTD'!H23 -> 0.036216 | M23: 0.00869 | N23: 0.026362 | O23: -0.039343 | P23: =E23-'Quarterly YTD'!L23 -> 0.046835 | Q23: -0.005043 | R23: 0.00105 | S23: =IF(AND(R23=0,Q23=0),0,IF(OR(Q23=0,Q23="NM",R23="NM"),"NM",IF(Q23<0,-(R23/Q23-1),R23/Q23-1))) -> 1.2082094 | T23: =IF(AND(R23=0,N23=0),0,IF(OR(N23=0,N23="NM",R23="NM"),"NM",IF(N23<0,-(R23/N23-1),R23/N23-1))) -> -0.96016994
A24: LOSS FOR THE PERIOD | B24: =SUM(B22:B23) -> -61.787149 | C24: =SUM(C22:C23) -> -115.48596 | D24: =SUM(D22:D23) -> -103.73102 | E24: =SUM(E22:E23) -> 30.422565 | F24: =SUM(F22:F23) -> 34.427144 | G24: =SUM(G22:G23) -> -2.918759 | H24: =SUM(H22:H23) -> -39.178175 | I24: =SUM(I22:I23) -> -15.559715 | ... R24: =SUM(R22:R23) -> -5.577559 | S24: =IF(AND(R24=0,Q24=0),0,IF(OR(Q24=0,Q24="NM",R24="NM"),"NM",IF(Q24<0,-(R24/Q24-1),R24/Q24-1))) -> 0.59458078 | T24: =IF(AND(R24=0,N24=0),0,IF(OR(N24=0,N24="NM",R24="NM"),"NM",IF(N24<0,-(R24/N24-1),R24/N24-1))) -> 0.55216757
A25: Equity holders of the Company | B25: -61.744696 | C25: -115.46815 | D25: -103.75874 | E25: 30.417809 | F25: =E25+'Quarterly YTD'!O25-'Quarterly YTD'!K25 -> 34.470036 | G25: -2.894362 | H25: =C25-'Quarterly YTD'!D25 -> -39.171689 | I25: -15.532933 | J25: -23.226568 | K25: -27.487553 | L25: =D25-'Quarterly YTD'!H25 -> -37.511688 | M25: -10.890588 | N25: -12.47359 | O25: 23.497866 | P25: =E25-'Quarterly YTD'!L25 -> 30.284121 | Q25: -13.714641 | R25: -5.59731 | S25: =IF(AND(R25=0,Q25=0),0,IF(OR(Q25=0,Q25="NM",R25="NM"),"NM",IF(Q25<0,-(R25/Q25-1),R25/Q25-1))) -> 0.59187339 | T25: =IF(AND(R25=0,N25=0),0,IF(OR(N25=0,N25="NM",R25="NM"),"NM",IF(N25<0,-(R25/N25-1),R25/N25-1))) -> 0.55126712
A26: Non-controlling interests | B26: -0.042453 | C26: -0.017809 | D26: 0.027721 | E26: 0.004756 | F26: =E26+'Quarterly YTD'!O26-'Quarterly YTD'!K26 -> -0.042892 | G26: -0.024397 | H26: =C26-'Quarterly YTD'!D26 -> -0.006486 | I26: -0.026782 | J26: 0.0468 | K26: 0.004737 | L26: =D26-'Quarterly YTD'!H26 -> 0.002966 | M26: 0.005507 | N26: 0.019023 | O26: 0.029363 | P26: =E26-'Quarterly YTD'!L26 -> -0.049137 | Q26: -0.042869 | R26: 0.019751 | S26: =IF(AND(R26=0,Q26=0),0,IF(OR(Q26=0,Q26="NM",R26="NM"),"NM",IF(Q26<0,-(R26/Q26-1),R26/Q26-1))) -> 1.4607292 | T26: =IF(AND(R26=0,N26=0),0,IF(OR(N26=0,N26="NM",R26="NM"),"NM",IF(N26<0,-(R26/N26-1),R26/N26-1))) -> 0.038269463
A27: Exchange differences on translation of foreign operations | B27: -1.064477 | C27: 52.549161 | D27: 10.984271 | E27: -21.059859 | F27: =E27+'Quarterly YTD'!O27-'Quarterly YTD'!K27 -> -13.242169 | G27: 41.250916 | H27: =C27-'Quarterly YTD'!D27 -> -0.805271 | I27: 8.750888 | J27: 2.694295 | K27: -1.462074 | L27: =D27-'Quarterly YTD'!H27 -> 1.001162 | M27: 0.736417 | N27: -0.079767 | O27: -8.302599 | P27: =E27-'Quarterly YTD'!L27 -> -13.4139 | Q27: 9.290292 | R27: -0.815962 | S27: =IF(AND(R27=0,Q27=0),0,IF(OR(Q27=0,Q27="NM",R27="NM"),"NM",IF(Q27<0,-(R27/Q27-1),R27/Q27-1))) -> -1.0878295 | T27: =IF(AND(R27=0,N27=0),0,IF(OR(N27=0,N27="NM",R27="NM"),"NM",IF(N27<0,-(R27/N27-1),R27/N27-1))) -> -9.2293179
A28: Defined benefit plan actuarial gain | B28: -0.048464 | C28: 0.016915 | D28: 0.078297 | E28: 0.73497 | F28: =E28+'Quarterly YTD'!O28-'Quarterly YTD'!K28 -> 0.73497 | G28: 0 | H28: =C28-'Quarterly YTD'!D28 -> 0.016915 | I28: 0 | J28: 0 | K28: 0 | L28: =D28-'Quarterly YTD'!H28 -> 0.078297 | M28: 0 | N28: 0 | O28: 0 | P28: =E28-'Quarterly YTD'!L28 -> 0.73497 | Q28: 0 | R28: 0 | S28: =IF(AND(R28=0,Q28=0),0,IF(OR(Q28=0,Q28="NM",R28="NM"),"NM",IF(Q28<0,-(R28/Q28-1),R28/Q28-1))) -> 0 | T28: =IF(AND(R28=0,N28=0),0,IF(OR(N28=0,N28="NM",R28="NM"),"NM",IF(N28<0,-(R28/N28-1),R28/N28-1))) -> 0
A29: Total other comprehensive (loss)/gain | B29: =SUM(B27:B28) -> -1.112941 | C29: =SUM(C27:C28) -> 52.566076 | D29: =SUM(D27:D28) -> 11.062568 | E29: =SUM(E27:E28) -> -20.324889 | F29: =SUM(F27:F28) -> -12.507199 | G29: =G27 -> 41.250916 | H29: =SUM(H27:H28) -> -0.788356 | I29: =I27 -> 8.750888 | J29: =J27 -> 2.694295 | K29: =K27 -> -1.462074 | L29: =SUM(L27:L28) -> 1.079459 | M29: =M27 -> 0.736417 | N29: =N27 -> -0.079767 | O29: =O27 -> -8.302599 | P29: =SUM(P27:P28) -> -12.67893 | Q29: =Q27 -> 9.290292 | R29: =R27 -> -0.815962 | S29: =IF(AND(R29=0,Q29=0),0,IF(OR(Q29=0,Q29="NM",R29="NM"),"NM",IF(Q29<0,-(R29/Q29-1),R29/Q29-1))) -> -1.0878295 | T29: =IF(AND(R29=0,N29=0),0,IF(OR(N29=0,N29="NM",R29="NM"),"NM",IF(N29<0,-(R29/N29-1),R29/N29-1))) -> -9.2293179
A30: TOTAL COMPREHENSIVE LOSS FOR THE PERIOD | B30: =B24+B29 -> -62.90009 | C30: =C24+C29 -> -62.919886 | D30: =D24+D29 -> -92.668453 | E30: =E24+E29 -> 10.097676 | F30: =F24+F29 -> 21.919945 | G30: =G24+G29 -> 38.332157 | H30: =H24+H29 -> -39.966531 | I30: =I24+I29 -> -6.808827 | ... R30: =R24+R29 -> -6.393521 | S30: =IF(AND(R30=0,Q30=0),0,IF(OR(Q30=0,Q30="NM",R30="NM"),"NM",IF(Q30<0,-(R30/Q30-1),R30/Q30-1))) -> -0.43120864 | T30: =IF(AND(R30=0,N30=0),0,IF(OR(N30=0,N30="NM",R30="NM"),"NM",IF(N30<0,-(R30/N30-1),R30/N30-1))) -> 0.48991937
A31: Equity holders of the Company | B31: -63.024558 | C31: -62.963777 | D31: -92.602016 | E31: 10.148129 | F31: =E31+'Quarterly YTD'!O31-'Quarterly YTD'!K31 -> 21.893804 | G31: 38.271897 | H31: =C31-'Quarterly YTD'!D31 -> -39.982908 | I31: -6.873388 | J31: -20.371297 | K31: -28.93372 | L31: =D31-'Quarterly YTD'!H31 -> -36.423611 | M31: -10.135332 | N31: -12.487411 | O31: 15.302297 | P31: =E31-'Quarterly YTD'!L31 -> 17.468586 | Q31: -4.556704 | R31: -6.320375 | S31: =IF(AND(R31=0,Q31=0),0,IF(OR(Q31=0,Q31="NM",R31="NM"),"NM",IF(Q31<0,-(R31/Q31-1),R31/Q31-1))) -> -0.38704972 | T31: =IF(AND(R31=0,N31=0),0,IF(OR(N31=0,N31="NM",R31="NM"),"NM",IF(N31<0,-(R31/N31-1),R31/N31-1))) -> 0.49386026
A32: Non-controlling interests | B32: 0.124468 | C32: 0.043891 | D32: -0.066437 | E32: -0.050453 | F32: =E32+'Quarterly YTD'!O32-'Quarterly YTD'!K32 -> 0.026141 | G32: 0.06026 | H32: =C32-'Quarterly YTD'!D32 -> 0.016377 | I32: 0.064561 | J32: -0.114176 | K32: -0.01117 | L32: =D32-'Quarterly YTD'!H32 -> -0.005652 | M32: -0.013332 | N32: -0.046923 | O32: -0.077667 | P32: =E32-'Quarterly YTD'!L32 -> 0.087468 | Q32: 0.089486 | R32: -0.073146 | S32: =IF(AND(R32=0,Q32=0),0,IF(OR(Q32=0,Q32="NM",R32="NM"),"NM",IF(Q32<0,-(R32/Q32-1),R32/Q32-1))) -> -1.8174016 | T32: =IF(AND(R32=0,N32=0),0,IF(OR(N32=0,N32="NM",R32="NM"),"NM",IF(N32<0,-(R32/N32-1),R32/N32-1))) -> -0.55885174
A34: Cash Flow Statement
A35: Loss before income tax from continuing operations | B35: -61.29357 | C35: -104.03337 | D35: -97.036347 | E35: 36.387585 | F35: =E35+'Quarterly YTD'!O35-'Quarterly YTD'!K35 -> 44.361632 | G35: ='Quarterly YTD'!D35-'Quarterly YTD'!C35 -> -6.434 | H35: =C35-'Quarterly YTD'!D35 -> -33.322611 | I35: -14.364613 | J35: ='Quarterly YTD'!G35-I35 -> -22.049789 | K35: ='Quarterly YTD'!H35-'Quarterly YTD'!G35 -> -25.598074 | L35: =D35-'Quarterly YTD'!H35 -> -35.023871 | M35: -10.274124 | N35: -11.758368 | O35: ='Quarterly YTD'!L35-'Quarterly YTD'!K35 -> 26.547532 | P35: =E35-'Quarterly YTD'!L35 -> 31.872545 | Q35: -11.421043 | R35: -2.637402
A36: Profit/(loss) from discontinued operations | B36: 0.397799 | C36: 0.001763 | D36: 0.042832 | E36: 0.042544 | F36: =E36+'Quarterly YTD'!O36-'Quarterly YTD'!K36 -> 0.003499 | G36: ='Quarterly YTD'!D36-'Quarterly YTD'!C36 -> -0.0208 | H36: =C36-'Quarterly YTD'!D36 -> 0.01314 | I36: -0.026877 | J36: ='Quarterly YTD'!G36-I36 -> 0.029646 | K36: ='Quarterly YTD'!H36-'Quarterly YTD'!G36 -> 0.003847 | L36: =D36-'Quarterly YTD'!H36 -> 0.036216 | M36: 0.00869 | N36: 0.026362 | O36: ='Quarterly YTD'!L36-'Quarterly YTD'!K36 -> -0.039343 | P36: =E36-'Quarterly YTD'!L36 -> 0.046835 | Q36: -0.005043 | R36: 0.00105
A37: Depreciation on tangible assets | B37: 42.745142 | C37: 47.380285 | D37: 48.614609 | E37: 50.741037 | F37: =E37+'Quarterly YTD'!O37-'Quarterly YTD'!K37 -> 56.226568 | G37: ='Quarterly YTD'!D37-'Quarterly YTD'!C37 -> 10.386751 | H37: =C37-'Quarterly YTD'!D37 -> 11.997254 | I37: 12.244525 | J37: ='Quarterly YTD'!G37-I37 -> 13.211034 | K37: ='Quarterly YTD'!H37-'Quarterly YTD'!G37 -> 10.236228 | L37: =D37-'Quarterly YTD'!H37 -> 12.922822 | M37: 12.306473 | N37: 11.951909 | O37: ='Quarterly YTD'!L37-'Quarterly YTD'!K37 -> 13.19391 | P37: =E37-'Quarterly YTD'!L37 -> 13.288745 | Q37: 15.027019 | R37: 14.716894
A38: Amortization of intangible assets | B38: 11.955373 | C38: 15.925177 | D38: 20.609792 | E38: 19.385894 | F38: =E38+'Quarterly YTD'!O38-'Quarterly YTD'!K38 -> 18.961141 | G38: ='Quarterly YTD'!D38-'Quarterly YTD'!C38 -> 4.173107 | H38: =C38-'Quarterly YTD'!D38 -> 4.928568 | I38: 5.009905 | J38: ='Quarterly YTD'!G38-I38 -> 5.304571 | K38: ='Quarterly YTD'!H38-'Quarterly YTD'!G38 -> 5.122623 | L38: =D38-'Quarterly YTD'!H38 -> 5.172693 | M38: 4.898694 | N38: 5.10543 | O38: ='Quarterly YTD'!L38-'Quarterly YTD'!K38 -> 5.151362 | P38: =E38-'Quarterly YTD'!L38 -> 4.230408 | Q38: 4.784049 | R38: 4.795322
A39: (Write-back) Provision for expected credit losses on trade receivables | B39: 0 | C39: 0 | D39: 0 | E39: 0 | F39: =E39+'Quarterly YTD'!O39-'Quarterly YTD'!K39 -> 0 | G39: ='Quarterly YTD'!D39-'Quarterly YTD'!C39 -> 0 | H39: =C39-'Quarterly YTD'!D39 -> 0 | I39: 0 | J39: ='Quarterly YTD'!G39-I39 -> 0.082283 | K39: ='Quarterly YTD'!H39-'Quarterly YTD'!G39 -> -0.082283 | L39: =D39-'Quarterly YTD'!H39 -> 0 | M39: 0 | N39: 0 | O39: ='Quarterly YTD'!L39-'Quarterly YTD'!K39+0.034141 -> 0.034141 | P39: =E39-'Quarterly YTD'!L39 -> 0 | Q39: 0 | R39: 0
A40: Provision for expected credit losses on trade receivables | B40: 1.070047 | C40: -1.024685 | D40: 0.849054 | E40: 0.615199 | F40: =E40+'Quarterly YTD'!O40-'Quarterly YTD'!K40 -> 0.615199 | G40: ='Quarterly YTD'!D40-'Quarterly YTD'!C40 -> 0.008508 | H40: =C40-'Quarterly YTD'!D40 -> -1.056003 | I40: 0.010468 | J40: ='Quarterly YTD'!G40-I40 -> -0.010468 | K40: ='Quarterly YTD'!H40-'Quarterly YTD'!G40 -> 0.537341 | L40: =D40-'Quarterly YTD'!H40 -> 0.311713 | M40: -0.039965 | N40: 0 | O40: ='Quarterly YTD'!L40-'Quarterly YTD'!K40 -> 0.001079 | P40: =E40-'Quarterly YTD'!L40 -> 0.61412 | Q40: 0.115606 | R40: 0
A41: Re-measurement gain on long-term liability | B41: 0 | C41: 0 | D41: -0.195467 | E41: 0 | F41: =E41+'Quarterly YTD'!O41-'Quarterly YTD'!K41 -> 0 | G41: ='Quarterly YTD'!D41-'Quarterly YTD'!C41 -> 0 | H41: =C41-'Quarterly YTD'!D41 -> 0 | I41: 0 | J41: ='Quarterly YTD'!G41-I41 -> 0 | K41: ='Quarterly YTD'!H41-'Quarterly YTD'!G41 -> 0 | L41: =D41-'Quarterly YTD'!H41 -> -0.195467 | M41: 0 | N41: 0 | O41: ='Quarterly YTD'!L41-'Quarterly YTD'!K41 -> 0 | P41: =E41-'Quarterly YTD'!L41 -> 0 | Q41: 0 | R41: 0
...

Sheet Quarterly YTD
A1: $mm, Dec year-end | B1: FY22 | C1: 1H23 | D1: 3Q23 | E1: FY23 | F1: 1Q24 | G1: 1H24 | H1: 3Q24 | I1: FY24 | J1: 1Q25 | K1: 1H25 | L1: 3Q25 | M1: FY25 | N1: 1Q26 | O1: 1H26
A2: Income Statement
A3: Revenues | B3: 308.10876 | C3: 192.91752 | D3: 264.09102 | E3: 356.19708 | F3: 85.804548 | G3: 174.60041 | H3: 262.65717 | I3: 355.99368 | J3: 93.498313 | K3: 193.80809 | L3: 300.56417 | M3: 408.64877 | N3: 114.34153 | O3: 230.83109
A4: Operating costs and commissions | B4: -136.08515 | C4: -78.961943 | D4: -108.12842 | E4: -139.63505 | F4: -31.334551 | G4: -69.10429 | H4: -110.56408 | I4: -145.86452 | J4: -34.165761 | K4: -70.122326 | L4: -105.63809 | M4: -144.11926 | N4: -37.420421 | O4: -75.354043
A5: Administrative, marketing and selling expenses | B5: -108.12485 | C5: -59.152889 | D5: -79.602924 | E5: -115.29811 | F5: -28.487093 | G5: -56.969784 | H5: -88.377712 | I5: -130.95791 | J5: -30.456847 | K5: -65.173595 | L5: -91.610392 | M5: -130.081 | N5: -37.877638 | O5: -77.460163
A6: Depreciation of tangible assets | B6: -42.745142 | C6: -24.99628 | D6: -35.383031 | E6: -47.380285 | F6: -12.244525 | G6: -25.455559 | H6: -35.691787 | I6: -48.614609 | J6: -12.306473 | K6: -24.258382 | L6: -37.452292 | M6: -50.741037 | N6: -15.027019 | O6: -29.743913
A7: Amortization of intangible assets | B7: -11.955373 | C7: -6.823502 | D7: -10.996609 | E7: -15.925177 | F7: -5.009905 | G7: -10.314476 | H7: -15.437099 | I7: -20.609792 | J7: -4.898694 | K7: -10.004124 | L7: -15.155486 | M7: -19.385894 | N7: -4.784049 | O7: -9.579371
A8: (Provision)/write-back for expected credit losses on trade receivables | B8: 0 | C8: 0 | D8: 0 | E8: 0 | F8: 0 | G8: 0 | H8: 0 | I8: 0 | J8: 0.039965 | K8: 0 | L8: 0 | M8: 0 | N8: -0.115606 | O8: 0
A9: Write-back/(provision) for expected credit losses on trade receivables | B9: -1.660354 | C9: -0.02281 | D9: -0.031318 | E9: 1.024685 | F9: -0.008613 | G9: -0.082283 | H9: -0.537341 | I9: -0.904712 | J9: 0 | K9: 0.034141 | L9: -0.001079 | M9: -0.605485 | N9: 0 | O9: 0.42104
A10: Provision for expected credit losses on balances due from related parties | B10: -0.390413 | C10: 0 | D10: 0 | E10: 0 | F10: 0 | G10: 0 | H10: -0.12936 | I10: -0.12936 | J10: 0 | K10: -0.038687 | L10: -0.052032 | M10: -0.065328 | N10: -0.338567 | O10: -0.405935
A11: Receivables written off | B11: 0 | C11: 0 | D11: 0 | E11: 0 | F11: 0 | G11: 0 | H11: 0 | I11: -0.072471 | J11: 0 | K11: 0 | L11: 0 | M11: -0.06976 | N11: 0 | O11: -0.015132
A12: Other gain/(loss), net | B12: 8.760054 | C12: -0.58548 | D12: 0.063861 | E12: 12.047365 | F12: 0.289148 | G12: -0.413988 | H12: 1.374868 | I12: 1.444997 | J12: 0.095351 | K12: -0.085878 | L12: 1.052799 | M12: 4.922003 | N12: -0.272845 | O12: 0.81925
A13: OPERATING PROFIT | B13: =SUM(B3:B7)+SUM(B9:B10)+B12 -> 15.907529 | C13: =SUM(C3:C7)+C9+C12 -> 22.374611 | D13: =SUM(D3:D7)+SUM(D9:D10)+D12 -> 30.012577 | E13: =SUM(E3:E7)+SUM(E9:E12) -> 51.030502 | F13: =SUM(F3:F7)+F9+F12 -> 9.009009 | G13: =SUM(G3:G7)+G9+G12 -> 12.260034 | H13: =SUM(H3:H7)+SUM(H9:H10)+H12 -> 13.294664 | I13: =SUM(I3:I7)+SUM(I9:I12) -> 10.285312 | J13: =SUM(J3:J8)+J10+J12 -> 11.805854 | K13: =SUM(K3:K7)+SUM(K9:K12) -> 24.159237 | L13: =SUM(L3:L7)+SUM(L9:L10)+L12 -> 51.707597 | M13: =SUM(M3:M7)+SUM(M9:M12) -> 68.503009 | N13: =SUM(N3:N8)+N10+N12 -> 18.505385 | O13: =SUM(O3:O7)+SUM(O9:O12) -> 39.51282
A14: Interest income on balances due from related parties | B14: 1.932958 | C14: 0 | D14: 0 | E14: 2.126254 | F14: 0 | G14: 0 | H14: 0 | I14: 2.33888 | J14: 0 | K14: 0 | L14: 0 | M14: 2.572767 | N14: 0 | O14: 0
A15: Interest income on balances due from a related party | B15: 0 | C15: 1.063127 | D15: 1.594691 | E15: 0 | F15: 0.58472 | G15: 1.16944 | H15: 1.75416 | I15: 0 | J15: 0.643189 | K15: 1.286384 | L15: 1.929576 | M15: 0 | N15: 0.707511 | O15: 1.415022
A16: Other interest income | B16: 0.187722 | C16: 0.076418 | D16: 0.115142 | E16: 0.156096 | F16: 0.040809 | G16: 0.079141 | H16: 0.116258 | I16: 0.329062 | J16: 0.109547 | K16: 0.157281 | L16: 0.23018 | M16: 0.269998 | N16: 0.236924 | O16: 0.388668
A17: Finance costs, net | B17: -55.213244 | C17: -34.55915 | D17: -48.250221 | E17: -64.737849 | F17: -15.328047 | G17: -30.738515 | H17: -46.371001 | I17: -74.276529 | J17: -17.043553 | K17: -34.228359 | L17: -51.969835 | M17: -71.039195 | N17: -20.252271 | O17: -40.973293
A18: Loss on exchange, net | B18: -24.108535 | C18: -85.59763 | D18: -83.482307 | E18: -114.15174 | F18: -12.388792 | G18: -23.156639 | H18: -33.511939 | I18: -39.271284 | J18: -5.577573 | K18: -13.178134 | L18: 2.205623 | M18: 37.680522 | N18: -13.410153 | O18: -17.192096
A19: Net (loss)/gain on net monetary position | B19: 0 | C19: 32.365867 | D19: 29.299361 | E19: 21.543365 | F19: 3.717688 | G19: 3.972137 | H19: 2.705382 | I19: 3.558212 | J19: -0.211588 | K19: -0.228901 | L19: 0.411899 | M19: -1.599516 | N19: 2.791561 | O19: 2.790434
A20: LOSS BEFORE INCOME TAX FROM CONTINUING OPERATIONS | B20: =SUM(B13:B14)+SUM(B16:B18) -> -61.29357 | C20: =C13+SUM(C15:C19) -> -64.276757 | D20: =D13+SUM(D15:D19) -> -70.710757 | E20: =SUM(E13:E14)+SUM(E16:E19) -> -104.03337 | F20: =F13+SUM(F15:F19) -> -14.364613 | G20: =G13+SUM(G15:G19) -> -36.414402 | H20: =H13+SUM(H15:H19) -> -62.012476 | I20: =SUM(I13:I14)+SUM(I16:I19) -> -97.036347 | J20: =J13+SUM(J15:J19) -> -10.274124 | K20: =K13+SUM(K15:K19) -> -22.032492 | L20: =L13+SUM(L15:L19) -> 4.51504 | M20: =SUM(M13:M14)+SUM(M16:M19) -> 36.387585 | N20: =N13+SUM(N15:N19) -> -11.421043 | O20: =O13+SUM(O15:O19) -> -14.058445
A21: Income tax expense | B21: -0.891378 | C21: -9.121694 | D21: -5.585653 | E21: -11.454357 | F21: -1.168225 | G21: -2.32785 | H21: -4.216439 | I21: -6.737506 | J21: -0.619647 | K21: -1.342208 | L21: -4.323168 | M21: -6.007564 | N21: -2.331424 | O21: -5.272631
A22: LOSS FOR THE PERIOD FROM CONTINUING OPERATIONS | B22: =SUM(B20:B21) -> -62.184948 | C22: =SUM(C20:C21) -> -73.398451 | D22: =SUM(D20:D21) -> -76.29641 | E22: =SUM(E20:E21) -> -115.48772 | F22: =SUM(F20:F21) -> -15.532838 | G22: =SUM(G20:G21) -> -38.742252 | H22: =SUM(H20:H21) -> -66.228915 | I22: =SUM(I20:I21) -> -103.77385 | ... O22: =SUM(O20:O21) -> -19.331076
A23: Profit/(loss) for the period from discontinued operations | B23: 0.397799 | C23: 0.009423 | D23: -0.011377 | E23: 0.001763 | F23: -0.026877 | G23: 0.002769 | H23: 0.006616 | I23: 0.042832 | J23: 0.00869 | K23: 0.035052 | L23: -0.004291 | M23: 0.042544 | N23: -0.005043 | O23: -0.003993
A24: LOSS FOR THE PERIOD | B24: =SUM(B22:B23) -> -61.787149 | C24: =SUM(C22:C23) -> -73.389028 | D24: =SUM(D22:D23) -> -76.307787 | E24: =SUM(E22:E23) -> -115.48596 | F24: =SUM(F22:F23) -> -15.559715 | G24: =SUM(G22:G23) -> -38.739483 | H24: =SUM(H22:H23) -> -66.222299 | I24: =SUM(I22:I23) -> -103.73102 | ... O24: =SUM(O22:O23) -> -19.335069
A25: Equity holders of the Company | B25: -61.744696 | C25: -73.402102 | D25: -76.296464 | E25: -115.46815 | F25: -15.532933 | G25: -38.759501 | H25: -66.247054 | I25: -103.75874 | J25: -10.890588 | K25: -23.364178 | L25: 0.133688 | M25: 30.417809 | N25: -13.714641 | O25: -19.311951
A26: Non-controlling interests | B26: -0.042453 | C26: 0.013074 | D26: -0.011323 | E26: -0.017809 | F26: -0.026782 | G26: 0.020018 | H26: 0.024755 | I26: 0.027721 | J26: 0.005507 | K26: 0.02453 | L26: 0.053893 | M26: 0.004756 | N26: -0.042869 | O26: -0.023118
A27: Exchange differences on translation of foreign operations | B27: -1.064477 | C27: 12.103516 | D27: 53.354432 | E27: 52.549161 | F27: 8.750888 | G27: 11.445183 | H27: 9.983109 | I27: 10.984271 | J27: 0.736417 | K27: 0.65664 | L27: -7.645959 | M27: -21.059859 | N27: 9.290292 | O27: 8.47433
A28: Defined benefit plan actuarial gain | B28: -0.048464 | C28: 0 | D28: 0 | E28: 0.016915 | F28: 0 | G28: 0 | H28: 0 | I28: 0.078297 | J28: 0 | K28: 0 | L28: 0 | M28: 0.73497 | N28: 0 | O28: 0
A29: Total other comprehensive (loss)/gain | B29: =SUM(B27:B28) -> -1.112941 | C29: =C27 -> 12.103516 | D29: =D27 -> 53.354432 | E29: =SUM(E27:E28) -> 52.566076 | F29: =F27 -> 8.750888 | G29: =G27 -> 11.445183 | H29: =H27 -> 9.983109 | I29: =SUM(I27:I28) -> 11.062568 | J29: =J27 -> 0.736417 | K29: =K27 -> 0.65664 | L29: =L27 -> -7.645959 | M29: =SUM(M27:M28) -> -20.324889 | N29: =N27 -> 9.290292 | O29: =O27 -> 8.47433
A30: TOTAL COMPREHENSIVE LOSS FOR THE PERIOD | B30: =B24+B29 -> -62.90009 | C30: =C24+C29 -> -61.285512 | D30: =D24+D29 -> -22.953355 | E30: =E24+E29 -> -62.919886 | F30: =F24+F29 -> -6.808827 | G30: =G24+G29 -> -27.2943 | H30: =H24+H29 -> -56.23919 | I30: =I24+I29 -> -92.668453 | ... O30: =O24+O29 -> -10.860739
A31: Equity holders of the Company | B31: -63.024558 | C31: -61.252766 | D31: -22.980869 | E31: -62.963777 | F31: -6.873388 | G31: -27.244685 | H31: -56.178405 | I31: -92.602016 | J31: -10.135332 | K31: -22.622754 | L31: -7.320457 | M31: 10.148129 | N31: -4.556704 | O31: -10.877079
A32: Non-controlling interests | B32: 0.124468 | C32: -0.032746 | D32: 0.027514 | E32: 0.043891 | F32: 0.064561 | G32: -0.049615 | H32: -0.060785 | I32: -0.066437 | J32: -0.013332 | K32: -0.060254 | L32: -0.137921 | M32: -0.050453 | N32: 0.089486 | O32: 0.01634
A34: Cash Flow Statement
A35: Loss before income tax from continuing operations | B35: -61.29357 | C35: -64.276757 | D35: -70.710757 | E35: -104.03337 | F35: -14.364613 | G35: -36.414402 | H35: -62.012476 | I35: -97.036347 | J35: -10.274124 | K35: -22.032492 | L35: 4.51504 | M35: 36.387585 | N35: -11.421043 | O35: -14.058445
A36: Profit/(loss) from discontinued operations | B36: 0.397799 | C36: 0.009423 | D36: -0.011377 | E36: 0.001763 | F36: -0.026877 | G36: 0.002769 | H36: 0.006616 | I36: 0.042832 | J36: 0.00869 | K36: 0.035052 | L36: -0.004291 | M36: 0.042544 | N36: -0.005043 | O36: -0.003993
A37: Depreciation on tangible assets | B37: 42.745142 | C37: 24.99628 | D37: 35.383031 | E37: 47.380285 | F37: 12.244525 | G37: 25.455559 | H37: 35.691787 | I37: 48.614609 | J37: 12.306473 | K37: 24.258382 | L37: 37.452292 | M37: 50.741037 | N37: 15.027019 | O37: 29.743913
A38: Amortization of intangible assets | B38: 11.955373 | C38: 6.823502 | D38: 10.996609 | E38: 15.925177 | F38: 5.009905 | G38: 10.314476 | H38: 15.437099 | I38: 20.609792 | J38: 4.898694 | K38: 10.004124 | L38: 15.155486 | M38: 19.385894 | N38: 4.784049 | O38: 9.579371
A39: (Write-back) Provision for expected credit losses on trade receivables | B39: 0 | C39: 0 | D39: 0 | E39: 0 | F39: 0 | G39: 0.082283 | H39: 0 | I39: 0 | J39: 0 | K39: 0 | L39: 0 | M39: 0 | N39: 0 | O39: 0
A40: Provision for expected credit losses on trade receivables | B40: 1.070047 | C40: 0.02281 | D40: 0.031318 | E40: -1.024685 | F40: 0.010468 | G40: 0 | H40: 0.537341 | I40: 0.849054 | J40: -0.039965 | K40: 0 | L40: 0.001079 | M40: 0.615199 | N40: 0.115606 | O40: 0
A41: Re-measurement gain on long-term liability | B41: 0 | C41: 0 | D41: 0 | E41: 0 | F41: 0 | G41: 0 | H41: 0 | I41: -0.195467 | J41: 0 | K41: 0 | L41: 0 | M41: 0 | N41: 0 | O41: 0
...

Sheet Rolling LTM
A1: $mm, Dec year-end | B1: FY22 | C1: 2Q23 | D1: 3Q23 | E1: FY23 | F1: 1Q24 | G1: 2Q24 | H1: 3Q24 | I1: FY24 | J1: 1Q25 | K1: 2Q25 | L1: 3Q25 | M1: FY25 | N1: 1Q26 | O1: 2Q26
A2: Income Statement
A3: Revenues | B3: 308.10876 | E3: 356.19708 | G3: =E3+'Quarterly YTD'!G3-'Quarterly YTD'!C3 -> 337.87998 | H3: =E3+'Quarterly YTD'!H3-'Quarterly YTD'!D3 -> 354.76324 | I3: 355.99368 | J3: =I3+'Quarterly YTD'!J3-'Quarterly YTD'!F3 -> 363.68745 | K3: =I3+'Quarterly YTD'!K3-'Quarterly YTD'!G3 -> 375.20136 | L3: =I3+'Quarterly YTD'!L3-'Quarterly YTD'!H3 -> 393.90068 | M3: 408.64877 | N3: =M3+'Quarterly YTD'!N3-'Quarterly YTD'!J3 -> 429.49199 | O3: =M3+'Quarterly YTD'!O3-'Quarterly YTD'!K3 -> 445.67177
A4: Operating costs and commissions | B4: -136.08515 | E4: -139.63505 | G4: =E4+'Quarterly YTD'!G4-'Quarterly YTD'!C4 -> -129.7774 | H4: =E4+'Quarterly YTD'!H4-'Quarterly YTD'!D4 -> -142.07071 | I4: -145.86452 | J4: =I4+'Quarterly YTD'!J4-'Quarterly YTD'!F4 -> -148.69573 | K4: =I4+'Quarterly YTD'!K4-'Quarterly YTD'!G4 -> -146.88255 | L4: =I4+'Quarterly YTD'!L4-'Quarterly YTD'!H4 -> -140.93853 | M4: -144.11926 | N4: =M4+'Quarterly YTD'!N4-'Quarterly YTD'!J4 -> -147.37392 | O4: =M4+'Quarterly YTD'!O4-'Quarterly YTD'!K4 -> -149.35098
A5: Administrative, marketing and selling expenses | B5: -108.12485 | E5: -115.29811 | G5: =E5+'Quarterly YTD'!G5-'Quarterly YTD'!C5 -> -113.11501 | H5: =E5+'Quarterly YTD'!H5-'Quarterly YTD'!D5 -> -124.0729 | I5: -130.95791 | J5: =I5+'Quarterly YTD'!J5-'Quarterly YTD'!F5 -> -132.92766 | K5: =I5+'Quarterly YTD'!K5-'Quarterly YTD'!G5 -> -139.16172 | L5: =I5+'Quarterly YTD'!L5-'Quarterly YTD'!H5 -> -134.19059 | M5: -130.081 | N5: =M5+'Quarterly YTD'!N5-'Quarterly YTD'!J5 -> -137.50179 | O5: =M5+'Quarterly YTD'!O5-'Quarterly YTD'!K5 -> -142.36757
A6: Depreciation of tangible assets | B6: -42.745142 | E6: -47.380285 | G6: =E6+'Quarterly YTD'!G6-'Quarterly YTD'!C6 -> -47.839564 | H6: =E6+'Quarterly YTD'!H6-'Quarterly YTD'!D6 -> -47.689041 | I6: -48.614609 | J6: =I6+'Quarterly YTD'!J6-'Quarterly YTD'!F6 -> -48.676557 | K6: =I6+'Quarterly YTD'!K6-'Quarterly YTD'!G6 -> -47.417432 | L6: =I6+'Quarterly YTD'!L6-'Quarterly YTD'!H6 -> -50.375114 | M6: -50.741037 | N6: =M6+'Quarterly YTD'!N6-'Quarterly YTD'!J6 -> -53.461583 | O6: =M6+'Quarterly YTD'!O6-'Quarterly YTD'!K6 -> -56.226568
A7: Amortization of intangible assets | B7: -11.955373 | E7: -15.925177 | G7: =E7+'Quarterly YTD'!G7-'Quarterly YTD'!C7 -> -19.416151 | H7: =E7+'Quarterly YTD'!H7-'Quarterly YTD'!D7 -> -20.365667 | I7: -20.609792 | J7: =I7+'Quarterly YTD'!J7-'Quarterly YTD'!F7 -> -20.498581 | K7: =I7+'Quarterly YTD'!K7-'Quarterly YTD'!G7 -> -20.29944 | L7: =I7+'Quarterly YTD'!L7-'Quarterly YTD'!H7 -> -20.328179 | M7: -19.385894 | N7: =M7+'Quarterly YTD'!N7-'Quarterly YTD'!J7 -> -19.271249 | O7: =M7+'Quarterly YTD'!O7-'Quarterly YTD'!K7 -> -18.961141
A8: (Provision)/write-back for expected credit losses on trade receivables | B8: 0 | E8: 0 | G8: =E8+'Quarterly YTD'!G8-'Quarterly YTD'!C8 -> 0 | H8: =E8+'Quarterly YTD'!H8-'Quarterly YTD'!D8 -> 0 | I8: 0 | J8: =I8+'Quarterly YTD'!J8-'Quarterly YTD'!F8 -> 0.039965 | K8: =I8+'Quarterly YTD'!K8-'Quarterly YTD'!G8 -> 0 | L8: =I8+'Quarterly YTD'!L8-'Quarterly YTD'!H8 -> 0 | M8: 0 | N8: =M8+'Quarterly YTD'!N8-'Quarterly YTD'!J8 -> -0.155571 | O8: =M8+'Quarterly YTD'!O8-'Quarterly YTD'!K8 -> 0
A9: Write-back/(provision) for expected credit losses on trade receivables | B9: -1.660354 | E9: 1.024685 | G9: =E9+'Quarterly YTD'!G9-'Quarterly YTD'!C9 -> 0.965212 | H9: =E9+'Quarterly YTD'!H9-'Quarterly YTD'!D9 -> 0.518662 | I9: -0.904712 | J9: =I9+'Quarterly YTD'!J9-'Quarterly YTD'!F9 -> -0.896099 | K9: =I9+'Quarterly YTD'!K9-'Quarterly YTD'!G9 -> -0.788288 | L9: =I9+'Quarterly YTD'!L9-'Quarterly YTD'!H9 -> -0.36845 | M9: -0.605485 | N9: =M9+'Quarterly YTD'!N9-'Quarterly YTD'!J9 -> -0.605485 | O9: =M9+'Quarterly YTD'!O9-'Quarterly YTD'!K9 -> -0.218586
A10: Provision for expected credit losses on balances due from related parties | B10: -0.390413 | E10: 0 | G10: =E10+'Quarterly YTD'!G10-'Quarterly YTD'!C10 -> 0 | H10: =E10+'Quarterly YTD'!H10-'Quarterly YTD'!D10 -> -0.12936 | I10: -0.12936 | J10: =I10+'Quarterly YTD'!J10-'Quarterly YTD'!F10 -> -0.12936 | K10: =I10+'Quarterly YTD'!K10-'Quarterly YTD'!G10 -> -0.168047 | L10: =I10+'Quarterly YTD'!L10-'Quarterly YTD'!H10 -> -0.052032 | M10: -0.065328 | N10: =M10+'Quarterly YTD'!N10-'Quarterly YTD'!J10 -> -0.403895 | O10: =M10+'Quarterly YTD'!O10-'Quarterly YTD'!K10 -> -0.432576
A11: Receivables written off | B11: 0 | E11: 0 | G11: =E11+'Quarterly YTD'!G11-'Quarterly YTD'!C11 -> 0 | H11: =E11+'Quarterly YTD'!H11-'Quarterly YTD'!D11 -> 0 | I11: -0.072471 | J11: =I11+'Quarterly YTD'!J11-'Quarterly YTD'!F11 -> -0.072471 | K11: =I11+'Quarterly YTD'!K11-'Quarterly YTD'!G11 -> -0.072471 | L11: =I11+'Quarterly YTD'!L11-'Quarterly YTD'!H11 -> -0.072471 | M11: -0.06976 | N11: =M11+'Quarterly YTD'!N11-'Quarterly YTD'!J11 -> -0.06976 | O11: =M11+'Quarterly YTD'!O11-'Quarterly YTD'!K11 -> -0.084892
A12: Other gain/(loss), net | B12: 8.760054 | E12: 12.047365 | G12: =E12+'Quarterly YTD'!G12-'Quarterly YTD'!C12 -> 12.218857 | H12: =E12+'Quarterly YTD'!H12-'Quarterly YTD'!D12 -> 13.358372 | I12: 1.444997 | J12: =I12+'Quarterly YTD'!J12-'Quarterly YTD'!F12 -> 1.2512 | K12: =I12+'Quarterly YTD'!K12-'Quarterly YTD'!G12 -> 1.773107 | L12: =I12+'Quarterly YTD'!L12-'Quarterly YTD'!H12 -> 1.122928 | M12: 4.922003 | N12: =M12+'Quarterly YTD'!N12-'Quarterly YTD'!J12 -> 4.553807 | O12: =M12+'Quarterly YTD'!O12-'Quarterly YTD'!K12 -> 5.827131
A13: OPERATING PROFIT | B13: =SUM(B3:B7)+SUM(B9:B10)+B12 -> 15.907529 | E13: =SUM(E3:E7)+SUM(E9:E12) -> 51.030502 | G13: =E13+'Quarterly YTD'!G13-'Quarterly YTD'!C13 -> 40.915925 | H13: =E13+'Quarterly YTD'!H13-'Quarterly YTD'!D13 -> 34.312589 | I13: =SUM(I3:I7)+SUM(I9:I12) -> 10.285312 | J13: =I13+'Quarterly YTD'!J13-'Quarterly YTD'!F13 -> 13.082157 | K13: =I13+'Quarterly YTD'!K13-'Quarterly YTD'!G13 -> 22.184515 | L13: =I13+'Quarterly YTD'!L13-'Quarterly YTD'!H13 -> 48.698245 | M13: =SUM(M3:M7)+SUM(M9:M12) -> 68.503009 | N13: =M13+'Quarterly YTD'!N13-'Quarterly YTD'!J13 -> 75.20254 | O13: =M13+'Quarterly YTD'!O13-'Quarterly YTD'!K13 -> 83.856592
A14: Interest income on balances due from related parties | B14: 1.932958 | E14: 2.126254 | G14: =E14+'Quarterly YTD'!G14-'Quarterly YTD'!C14 -> 2.126254 | H14: =E14+'Quarterly YTD'!H14-'Quarterly YTD'!D14 -> 2.126254 | I14: 2.33888 | J14: =I14+'Quarterly YTD'!J14-'Quarterly YTD'!F14 -> 2.33888 | K14: =I14+'Quarterly YTD'!K14-'Quarterly YTD'!G14 -> 2.33888 | L14: =I14+'Quarterly YTD'!L14-'Quarterly YTD'!H14 -> 2.33888 | M14: 2.572767 | N14: =M14+'Quarterly YTD'!N14-'Quarterly YTD'!J14 -> 2.572767 | O14: =M14+'Quarterly YTD'!O14-'Quarterly YTD'!K14 -> 2.572767
A15: Interest income on balances due from a related party | B15: 0 | E15: 0 | G15: =E15+'Quarterly YTD'!G15-'Quarterly YTD'!C15 -> 0.106313 | H15: =E15+'Quarterly YTD'!H15-'Quarterly YTD'!D15 -> 0.159469 | I15: 0 | J15: =I15+'Quarterly YTD'!J15-'Quarterly YTD'!F15 -> 0.058469 | K15: =I15+'Quarterly YTD'!K15-'Quarterly YTD'!G15 -> 0.116944 | L15: =I15+'Quarterly YTD'!L15-'Quarterly YTD'!H15 -> 0.175416 | M15: 0 | N15: =M15+'Quarterly YTD'!N15-'Quarterly YTD'!J15 -> 0.064322 | O15: =M15+'Quarterly YTD'!O15-'Quarterly YTD'!K15 -> 0.128638
A16: Other interest income | B16: 0.187722 | E16: 0.156096 | G16: =E16+'Quarterly YTD'!G16-'Quarterly YTD'!C16 -> 0.158819 | H16: =E16+'Quarterly YTD'!H16-'Quarterly YTD'!D16 -> 0.157212 | I16: 0.329062 | J16: =I16+'Quarterly YTD'!J16-'Quarterly YTD'!F16 -> 0.3978 | K16: =I16+'Quarterly YTD'!K16-'Quarterly YTD'!G16 -> 0.407202 | L16: =I16+'Quarterly YTD'!L16-'Quarterly YTD'!H16 -> 0.442984 | M16: 0.269998 | N16: =M16+'Quarterly YTD'!N16-'Quarterly YTD'!J16 -> 0.397375 | O16: =M16+'Quarterly YTD'!O16-'Quarterly YTD'!K16 -> 0.501385
A17: Finance costs, net | B17: -55.213244 | E17: -64.737849 | G17: =E17+'Quarterly YTD'!G17-'Quarterly YTD'!C17 -> -60.917214 | H17: =E17+'Quarterly YTD'!H17-'Quarterly YTD'!D17 -> -62.858629 | I17: -74.276529 | J17: =I17+'Quarterly YTD'!J17-'Quarterly YTD'!F17 -> -75.992035 | K17: =I17+'Quarterly YTD'!K17-'Quarterly YTD'!G17 -> -77.766373 | L17: =I17+'Quarterly YTD'!L17-'Quarterly YTD'!H17 -> -79.875363 | M17: -71.039195 | N17: =M17+'Quarterly YTD'!N17-'Quarterly YTD'!J17 -> -74.247913 | O17: =M17+'Quarterly YTD'!O17-'Quarterly YTD'!K17 -> -77.784129
A18: Loss on exchange, net | B18: -24.108535 | E18: -114.15174 | G18: =E18+'Quarterly YTD'!G18-'Quarterly YTD'!C18 -> -51.710745 | H18: =E18+'Quarterly YTD'!H18-'Quarterly YTD'!D18 -> -64.181368 | I18: -39.271284 | J18: =I18+'Quarterly YTD'!J18-'Quarterly YTD'!F18 -> -32.460065 | K18: =I18+'Quarterly YTD'!K18-'Quarterly YTD'!G18 -> -29.292779 | L18: =I18+'Quarterly YTD'!L18-'Quarterly YTD'!H18 -> -3.553722 | M18: 37.680522 | N18: =M18+'Quarterly YTD'!N18-'Quarterly YTD'!J18 -> 29.847942 | O18: =M18+'Quarterly YTD'!O18-'Quarterly YTD'!K18 -> 33.66656
A19: Net (loss)/gain on net monetary position | B19: 0 | E19: 21.543365 | G19: =E19+'Quarterly YTD'!G19-'Quarterly YTD'!C19 -> -6.850365 | H19: =E19+'Quarterly YTD'!H19-'Quarterly YTD'!D19 -> -5.050614 | I19: 3.558212 | J19: =I19+'Quarterly YTD'!J19-'Quarterly YTD'!F19 -> -0.371064 | K19: =I19+'Quarterly YTD'!K19-'Quarterly YTD'!G19 -> -0.642826 | L19: =I19+'Quarterly YTD'!L19-'Quarterly YTD'!H19 -> 1.264729 | M19: -1.599516 | N19: =M19+'Quarterly YTD'!N19-'Quarterly YTD'!J19 -> 1.403633 | O19: =M19+'Quarterly YTD'!O19-'Quarterly YTD'!K19 -> 1.419819
A20: LOSS BEFORE INCOME TAX FROM CONTINUING OPERATIONS | B20: =SUM(B13:B14)+SUM(B16:B18) -> -61.29357 | E20: =SUM(E13:E14)+SUM(E16:E19) -> -104.03337 | G20: =E20+'Quarterly YTD'!G20-'Quarterly YTD'!C20 -> -76.171013 | H20: =E20+'Quarterly YTD'!H20-'Quarterly YTD'!D20 -> -95.335087 | I20: =SUM(I13:I14)+SUM(I16:I19) -> -97.036347 | J20: =I20+'Quarterly YTD'!J20-'Quarterly YTD'!F20 -> -92.945858 | K20: =I20+'Quarterly YTD'!K20-'Quarterly YTD'!G20 -> -82.654437 | L20: =I20+'Quarterly YTD'!L20-'Quarterly YTD'!H20 -> -30.508831 | M20: =SUM(M13:M14)+SUM(M16:M19) -> 36.387585 | N20: =M20+'Quarterly YTD'!N20-'Quarterly YTD'!J20 -> 35.240666 | O20: =M20+'Quarterly YTD'!O20-'Quarterly YTD'!K20 -> 44.361632
A21: Income tax expense | B21: -0.891378 | E21: -11.454357 | G21: =E21+'Quarterly YTD'!G21-'Quarterly YTD'!C21 -> -4.660513 | H21: =E21+'Quarterly YTD'!H21-'Quarterly YTD'!D21 -> -10.085143 | I21: -6.737506 | J21: =I21+'Quarterly YTD'!J21-'Quarterly YTD'!F21 -> -6.188928 | K21: =I21+'Quarterly YTD'!K21-'Quarterly YTD'!G21 -> -5.751864 | L21: =I21+'Quarterly YTD'!L21-'Quarterly YTD'!H21 -> -6.844235 | M21: -6.007564 | N21: =M21+'Quarterly YTD'!N21-'Quarterly YTD'!J21 -> -7.719341 | O21: =M21+'Quarterly YTD'!O21-'Quarterly YTD'!K21 -> -9.937987
A22: LOSS FOR THE PERIOD FROM CONTINUING OPERATIONS | B22: =SUM(B20:B21) -> -62.184948 | E22: =SUM(E20:E21) -> -115.48772 | G22: =SUM(G20:G21) -> -80.831526 | H22: =SUM(H20:H21) -> -105.42023 | I22: =SUM(I20:I21) -> -103.77385 | J22: =SUM(J20:J21) -> -99.134786 | K22: =SUM(K20:K21) -> -88.406301 | L22: =SUM(L20:L21) -> -37.353066 | M22: =SUM(M20:M21) -> 30.380021 | N22: =SUM(N20:N21) -> 27.521325 | O22: =SUM(O20:O21) -> 34.423645
A23: Profit/(loss) for the period from discontinued operations | B23: 0.397799 | E23: 0.001763 | G23: =E23+'Quarterly YTD'!G23-'Quarterly YTD'!C23 -> -0.004891 | H23: =E23+'Quarterly YTD'!H23-'Quarterly YTD'!D23 -> 0.019756 | I23: 0.042832 | J23: =I23+'Quarterly YTD'!J23-'Quarterly YTD'!F23 -> 0.078399 | K23: =I23+'Quarterly YTD'!K23-'Quarterly YTD'!G23 -> 0.075115 | L23: =I23+'Quarterly YTD'!L23-'Quarterly YTD'!H23 -> 0.031925 | M23: 0.042544 | N23: =M23+'Quarterly YTD'!N23-'Quarterly YTD'!J23 -> 0.028811 | O23: =M23+'Quarterly YTD'!O23-'Quarterly YTD'!K23 -> 0.003499
A24: LOSS FOR THE PERIOD | B24: =SUM(B22:B23) -> -61.787149 | E24: =SUM(E22:E23) -> -115.48596 | G24: =SUM(G22:G23) -> -80.836417 | H24: =SUM(H22:H23) -> -105.40047 | I24: =SUM(I22:I23) -> -103.73102 | J24: =SUM(J22:J23) -> -99.056387 | K24: =SUM(K22:K23) -> -88.331186 | L24: =SUM(L22:L23) -> -37.321141 | M24: =SUM(M22:M23) -> 30.422565 | N24: =SUM(N22:N23) -> 27.550136 | O24: =SUM(O22:O23) -> 34.427144
A25: Equity holders of the Company | B25: -61.744696 | E25: -115.46815 | G25: =E25+'Quarterly YTD'!G25-'Quarterly YTD'!C25 -> -80.825552 | H25: =E25+'Quarterly YTD'!H25-'Quarterly YTD'!D25 -> -105.41874 | I25: -103.75874 | J25: =I25+'Quarterly YTD'!J25-'Quarterly YTD'!F25 -> -99.116397 | K25: =I25+'Quarterly YTD'!K25-'Quarterly YTD'!G25 -> -88.363419 | L25: =I25+'Quarterly YTD'!L25-'Quarterly YTD'!H25 -> -37.378 | M25: 30.417809 | N25: =M25+'Quarterly YTD'!N25-'Quarterly YTD'!J25 -> 27.593756 | O25: =M25+'Quarterly YTD'!O25-'Quarterly YTD'!K25 -> 34.470036
A26: Non-controlling interests | B26: -0.042453 | E26: -0.017809 | G26: =E26+'Quarterly YTD'!G26-'Quarterly YTD'!C26 -> -0.010865 | H26: =E26+'Quarterly YTD'!H26-'Quarterly YTD'!D26 -> 0.018269 | I26: 0.027721 | J26: =I26+'Quarterly YTD'!J26-'Quarterly YTD'!F26 -> 0.06001 | K26: =I26+'Quarterly YTD'!K26-'Quarterly YTD'!G26 -> 0.032233 | L26: =I26+'Quarterly YTD'!L26-'Quarterly YTD'!H26 -> 0.056859 | M26: 0.004756 | N26: =M26+'Quarterly YTD'!N26-'Quarterly YTD'!J26 -> -0.04362 | O26: =M26+'Quarterly YTD'!O26-'Quarterly YTD'!K26 -> -0.042892
A27: Exchange differences on translation of foreign operations | B27: -1.064477 | E27: 52.549161 | G27: =E27+'Quarterly YTD'!G27-'Quarterly YTD'!C27 -> 51.890828 | H27: =E27+'Quarterly YTD'!H27-'Quarterly YTD'!D27 -> 9.177838 | I27: 10.984271 | J27: =I27+'Quarterly YTD'!J27-'Quarterly YTD'!F27 -> 2.9698 | K27: =I27+'Quarterly YTD'!K27-'Quarterly YTD'!G27 -> 0.195728 | L27: =I27+'Quarterly YTD'!L27-'Quarterly YTD'!H27 -> -6.644797 | M27: -21.059859 | N27: =M27+'Quarterly YTD'!N27-'Quarterly YTD'!J27 -> -12.505984 | O27: =M27+'Quarterly YTD'!O27-'Quarterly YTD'!K27 -> -13.242169
A28: Defined benefit plan actuarial gain | B28: -0.048464 | E28: 0.016915 | G28: =E28+'Quarterly YTD'!G28-'Quarterly YTD'!C28 -> 0.016915 | H28: =E28+'Quarterly YTD'!H28-'Quarterly YTD'!D28 -> 0.016915 | I28: 0.078297 | J28: =I28+'Quarterly YTD'!J28-'Quarterly YTD'!F28 -> 0.078297 | K28: =I28+'Quarterly YTD'!K28-'Quarterly YTD'!G28 -> 0.078297 | L28: =I28+'Quarterly YTD'!L28-'Quarterly YTD'!H28 -> 0.078297 | M28: 0.73497 | N28: =M28+'Quarterly YTD'!N28-'Quarterly YTD'!J28 -> 0.73497 | O28: =M28+'Quarterly YTD'!O28-'Quarterly YTD'!K28 -> 0.73497
A29: Total other comprehensive (loss)/gain | B29: =SUM(B27:B28) -> -1.112941 | E29: =SUM(E27:E28) -> 52.566076 | G29: =SUM(G27:G28) -> 51.907743 | H29: =SUM(H27:H28) -> 9.194753 | I29: =SUM(I27:I28) -> 11.062568 | J29: =SUM(J27:J28) -> 3.048097 | K29: =SUM(K27:K28) -> 0.274025 | L29: =SUM(L27:L28) -> -6.5665 | M29: =SUM(M27:M28) -> -20.324889 | N29: =SUM(N27:N28) -> -11.771014 | O29: =SUM(O27:O28) -> -12.507199
A30: TOTAL COMPREHENSIVE LOSS FOR THE PERIOD | B30: =B24+B29 -> -62.90009 | E30: =E24+E29 -> -62.919886 | G30: =G24+G29 -> -28.928674 | H30: =H24+H29 -> -96.205721 | I30: =I24+I29 -> -92.668453 | J30: =J24+J29 -> -96.00829 | K30: =K24+K29 -> -88.057161 | L30: =L24+L29 -> -43.887641 | M30: =M24+M29 -> 10.097676 | N30: =N24+N29 -> 15.779122 | O30: =O24+O29 -> 21.919945
A31: Equity holders of the Company | B31: -63.024558 | E31: -62.963777 | G31: =E31+'Quarterly YTD'!G31-'Quarterly YTD'!C31 -> -28.955696 | H31: =E31+'Quarterly YTD'!H31-'Quarterly YTD'!D31 -> -96.161313 | I31: -92.602016 | J31: =I31+'Quarterly YTD'!J31-'Quarterly YTD'!F31 -> -95.86396 | K31: =I31+'Quarterly YTD'!K31-'Quarterly YTD'!G31 -> -87.980085 | L31: =I31+'Quarterly YTD'!L31-'Quarterly YTD'!H31 -> -43.744068 | M31: 10.148129 | N31: =M31+'Quarterly YTD'!N31-'Quarterly YTD'!J31 -> 15.726757 | O31: =M31+'Quarterly YTD'!O31-'Quarterly YTD'!K31 -> 21.893804
A32: Non-controlling interests | B32: 0.124468 | E32: 0.043891 | G32: =E32+'Quarterly YTD'!G32-'Quarterly YTD'!C32 -> 0.027022 | H32: =E32+'Quarterly YTD'!H32-'Quarterly YTD'!D32 -> -0.044408 | I32: -0.066437 | J32: =I32+'Quarterly YTD'!J32-'Quarterly YTD'!F32 -> -0.14433 | K32: =I32+'Quarterly YTD'!K32-'Quarterly YTD'!G32 -> -0.077076 | L32: =I32+'Quarterly YTD'!L32-'Quarterly YTD'!H32 -> -0.143573 | M32: -0.050453 | N32: =M32+'Quarterly YTD'!N32-'Quarterly YTD'!J32 -> 0.052365 | O32: =M32+'Quarterly YTD'!O32-'Quarterly YTD'!K32 -> 0.026141
A34: Cash Flow Statement
A35: Loss before income tax from continuing operations | B35: -61.29357 | E35: -104.03337 | G35: =E35+'Quarterly YTD'!G35-'Quarterly YTD'!C35 -> -76.171013 | H35: =E35+'Quarterly YTD'!H35-'Quarterly YTD'!D35 -> -95.335087 | I35: -97.036347 | J35: =I35+'Quarterly YTD'!J35-'Quarterly YTD'!F35 -> -92.945858 | K35: =I35+'Quarterly YTD'!K35-'Quarterly YTD'!G35 -> -82.654437 | L35: =I35+'Quarterly YTD'!L35-'Quarterly YTD'!H35 -> -30.508831 | M35: 36.387585 | N35: =M35+'Quarterly YTD'!N35-'Quarterly YTD'!J35 -> 35.240666 | O35: =M35+'Quarterly YTD'!O35-'Quarterly YTD'!K35 -> 44.361632
A36: Profit/(loss) from discontinued operations | B36: 0.397799 | E36: 0.001763 | G36: =E36+'Quarterly YTD'!G36-'Quarterly YTD'!C36 -> -0.004891 | H36: =E36+'Quarterly YTD'!H36-'Quarterly YTD'!D36 -> 0.019756 | I36: 0.042832 | J36: =I36+'Quarterly YTD'!J36-'Quarterly YTD'!F36 -> 0.078399 | K36: =I36+'Quarterly YTD'!K36-'Quarterly YTD'!G36 -> 0.075115 | L36: =I36+'Quarterly YTD'!L36-'Quarterly YTD'!H36 -> 0.031925 | M36: 0.042544 | N36: =M36+'Quarterly YTD'!N36-'Quarterly YTD'!J36 -> 0.028811 | O36: =M36+'Quarterly YTD'!O36-'Quarterly YTD'!K36 -> 0.003499
A37: Depreciation on tangible assets | B37: 42.745142 | E37: 47.380285 | G37: =E37+'Quarterly YTD'!G37-'Quarterly YTD'!C37 -> 47.839564 | H37: =E37+'Quarterly YTD'!H37-'Quarterly YTD'!D37 -> 47.689041 | I37: 48.614609 | J37: =I37+'Quarterly YTD'!J37-'Quarterly YTD'!F37 -> 48.676557 | K37: =I37+'Quarterly YTD'!K37-'Quarterly YTD'!G37 -> 47.417432 | L37: =I37+'Quarterly YTD'!L37-'Quarterly YTD'!H37 -> 50.375114 | M37: 50.741037 | N37: =M37+'Quarterly YTD'!N37-'Quarterly YTD'!J37 -> 53.461583 | O37: =M37+'Quarterly YTD'!O37-'Quarterly YTD'!K37 -> 56.226568
A38: Amortization of intangible assets | B38: 11.955373 | E38: 15.925177 | G38: =E38+'Quarterly YTD'!G38-'Quarterly YTD'!C38 -> 19.416151 | H38: =E38+'Quarterly YTD'!H38-'Quarterly YTD'!D38 -> 20.365667 | I38: 20.609792 | J38: =I38+'Quarterly YTD'!J38-'Quarterly YTD'!F38 -> 20.498581 | K38: =I38+'Quarterly YTD'!K38-'Quarterly YTD'!G38 -> 20.29944 | L38: =I38+'Quarterly YTD'!L38-'Quarterly YTD'!H38 -> 20.328179 | M38: 19.385894 | N38: =M38+'Quarterly YTD'!N38-'Quarterly YTD'!J38 -> 19.271249 | O38: =M38+'Quarterly YTD'!O38-'Quarterly YTD'!K38 -> 18.961141
A39: (Write-back) Provision for expected credit losses on trade receivables | B39: 0 | E39: 0 | G39: =E39+'Quarterly YTD'!G39-'Quarterly YTD'!C39 -> 0.082283 | H39: =E39+'Quarterly YTD'!H39-'Quarterly YTD'!D39 -> 0 | I39: 0 | J39: =I39+'Quarterly YTD'!J39-'Quarterly YTD'!F39 -> 0 | K39: =I39+'Quarterly YTD'!K39-'Quarterly YTD'!G39 -> -0.082283 | L39: =I39+'Quarterly YTD'!L39-'Quarterly YTD'!H39 -> 0 | M39: 0 | N39: =M39+'Quarterly YTD'!N39-'Quarterly YTD'!J39 -> 0 | O39: =M39+'Quarterly YTD'!O39-'Quarterly YTD'!K39 -> 0
A40: Provision for expected credit losses on trade receivables | B40: 1.070047 | E40: -1.024685 | G40: =E40+'Quarterly YTD'!G40-'Quarterly YTD'!C40 -> -1.047495 | H40: =E40+'Quarterly YTD'!H40-'Quarterly YTD'!D40 -> -0.518662 | I40: 0.849054 | J40: =I40+'Quarterly YTD'!J40-'Quarterly YTD'!F40 -> 0.798621 | K40: =I40+'Quarterly YTD'!K40-'Quarterly YTD'!G40 -> 0.849054 | L40: =I40+'Quarterly YTD'!L40-'Quarterly YTD'!H40 -> 0.312792 | M40: 0.615199 | N40: =M40+'Quarterly YTD'!N40-'Quarterly YTD'!J40 -> 0.77077 | O40: =M40+'Quarterly YTD'!O40-'Quarterly YTD'!K40 -> 0.615199
A41: Re-measurement gain on long-term liability | B41: 0 | E41: 0 | G41: =E41+'Quarterly YTD'!G41-'Quarterly YTD'!C41 -> 0 | H41: =E41+'Quarterly YTD'!H41-'Quarterly YTD'!D41 -> 0 | I41: -0.195467 | J41: =I41+'Quarterly YTD'!J41-'Quarterly YTD'!F41 -> -0.195467 | K41: =I41+'Quarterly YTD'!K41-'Quarterly YTD'!G41 -> -0.195467 | L41: =I41+'Quarterly YTD'!L41-'Quarterly YTD'!H41 -> -0.195467 | M41: 0 | N41: =M41+'Quarterly YTD'!N41-'Quarterly YTD'!J41 -> 0 | O41: =M41+'Quarterly YTD'!O41-'Quarterly YTD'!K41 -> 0
...
