Workbook

Sheet Credit Summary & Memo
B2: Pearl Petroleum (PEARL) — Institutional Credit Model
B3: Sector: Energy | Country: Iraq | Rating: B- (Implied) / CCC+ (Geopolitical Floor) | Benchmark: PEARL 13.00% 2028 (NO0013387860) @ $103.50 (11.45% YTM / +625 bp)
B5: I. EXECUTIVE CREDIT THESIS & MANDATE
B6: Khor Mor's essential role generating >80% of KRI electricity makes asset liquidation or state expropriation impossible without catastrophic regional blackout. Under distressed stress (ongoing drone attacks, full KRG payment freeze, and localized condensate trucking discounts), liquidation scrap and salvage value of gas processing trains, pipeline spurs, and DFC sovereign umbrella anchor a hard recovery floor of 62.0c. In consensual going-concern restructuring, 15 Tcf 2P reserves and 750 MMscfd capacity support 100c+ par recovery.
B9: II. 7-YEAR MULTI-PERIOD FINANCIAL SCORECARD (USD M)
B10: Metric | C10: 2021A | D10: 2022A | E10: 2023A | F10: 2024A | G10: 2025E | H10: 2026E | I10: 2027E
B11: Gross Revenue | C11: ='Income Statement (P&L)'!C10 | D11: ='Income Statement (P&L)'!D10 | E11: ='Income Statement (P&L)'!E10 | F11: ='Income Statement (P&L)'!F10 | G11: ='Income Statement (P&L)'!G10 | H11: ='Income Statement (P&L)'!H10 | I11: ='Income Statement (P&L)'!I10
B12: Calculated Cash EBITDA | C12: ='Income Statement (P&L)'!C22 | D12: ='Income Statement (P&L)'!D22 | E12: ='Income Statement (P&L)'!E22 | F12: ='Income Statement (P&L)'!F22 | G12: ='Income Statement (P&L)'!G22 | H12: ='Income Statement (P&L)'!H22 | I12: ='Income Statement (P&L)'!I22
B13: Reported Headline EBITDA | C13: ='Income Statement (P&L)'!C36 | D13: ='Income Statement (P&L)'!D36 | E13: ='Income Statement (P&L)'!E36 | F13: ='Income Statement (P&L)'!F36 | G13: ='Income Statement (P&L)'!G36 | H13: ='Income Statement (P&L)'!H36 | I13: ='Income Statement (P&L)'!I36
B14: EBITDA Margin (%) | C14: ='Income Statement (P&L)'!C23 | D14: ='Income Statement (P&L)'!D23 | E14: ='Income Statement (P&L)'!E23 | F14: ='Income Statement (P&L)'!F23 | G14: ='Income Statement (P&L)'!G23 | H14: ='Income Statement (P&L)'!H23 | I14: ='Income Statement (P&L)'!I23
B15: Cash Flow from Operations (CFO) | C15: ='Cash Flow Statement'!C14 | D15: ='Cash Flow Statement'!D14 | E15: ='Cash Flow Statement'!E14 | F15: ='Cash Flow Statement'!F14 | G15: ='Cash Flow Statement'!G14 | H15: ='Cash Flow Statement'!H14 | I15: ='Cash Flow Statement'!I14
B16: Capital Expenditures (Capex) | C16: ='Cash Flow Statement'!C16 | D16: ='Cash Flow Statement'!D16 | E16: ='Cash Flow Statement'!E16 | F16: ='Cash Flow Statement'!F16 | G16: ='Cash Flow Statement'!G16 | H16: ='Cash Flow Statement'!H16 | I16: ='Cash Flow Statement'!I16
B17: Free Cash Flow (FCF) | C17: ='Cash Flow Statement'!C34 | D17: ='Cash Flow Statement'!D34 | E17: ='Cash Flow Statement'!E34 | F17: ='Cash Flow Statement'!F34 | G17: ='Cash Flow Statement'!G34 | H17: ='Cash Flow Statement'!H34 | I17: ='Cash Flow Statement'!I34
B18: Cash & Liquid Reserves | C18: ='Balance Sheet'!C8 | D18: ='Balance Sheet'!D8 | E18: ='Balance Sheet'!E8 | F18: ='Balance Sheet'!F8 | G18: ='Balance Sheet'!G8 | H18: ='Balance Sheet'!H8 | I18: ='Balance Sheet'!I8
B19: Consolidated Gross Debt | C19: ='Debt Schedule & Tranches'!C24 | D19: ='Debt Schedule & Tranches'!D24 | E19: ='Debt Schedule & Tranches'!E24 | F19: ='Debt Schedule & Tranches'!F24 | G19: ='Debt Schedule & Tranches'!G24 | H19: ='Debt Schedule & Tranches'!H24 | I19: ='Debt Schedule & Tranches'!I24
B20: Consolidated Net Debt | C20: ='Debt Schedule & Tranches'!C26 | D20: ='Debt Schedule & Tranches'!D26 | E20: ='Debt Schedule & Tranches'!E26 | F20: ='Debt Schedule & Tranches'!F26 | G20: ='Debt Schedule & Tranches'!G26 | H20: ='Debt Schedule & Tranches'!H26 | I20: ='Debt Schedule & Tranches'!I26
B21: Net Leverage (Calculated Cash EBITDA) | C21: ='Credit Metrics & Ratios'!C8 | D21: ='Credit Metrics & Ratios'!D8 | E21: ='Credit Metrics & Ratios'!E8 | F21: ='Credit Metrics & Ratios'!F8 | G21: ='Credit Metrics & Ratios'!G8 | H21: ='Credit Metrics & Ratios'!H8 | I21: ='Credit Metrics & Ratios'!I8
B22: Net Leverage (Reported Headline EBITDA) | C22: ='Credit Metrics & Ratios'!C9 | D22: ='Credit Metrics & Ratios'!D9 | E22: ='Credit Metrics & Ratios'!E9 | F22: ='Credit Metrics & Ratios'!F9 | G22: ='Credit Metrics & Ratios'!G9 | H22: ='Credit Metrics & Ratios'!H9 | I22: ='Credit Metrics & Ratios'!I9
B23: EBITDA Interest Coverage | C23: ='Credit Metrics & Ratios'!C11 | D23: ='Credit Metrics & Ratios'!D11 | E23: ='Credit Metrics & Ratios'!E11 | F23: ='Credit Metrics & Ratios'!F11 | G23: ='Credit Metrics & Ratios'!G11 | H23: ='Credit Metrics & Ratios'!H11 | I23: ='Credit Metrics & Ratios'!I11
B24: III. CAPITAL STRUCTURE & DEBT TRANCHE PRICING
B25: Tranche Name | C25: Type | D25: Currency | E25: Outstanding ($M) | F25: Coupon | G25: Price | H25: Maturity | I25: Seniority
B26: PEARL Benchmark Eurobond | C26: Senior Unsecured Note | D26: USD | E26: 261 | F26: 11.45% | G26: $103.50 | H26: 2028-2032 | I26: Senior Unsecured
B27: PEARL Sukuk / Eurobond Tranche 2 | C27: Senior Unsecured Note | D27: USD | E27: 174 | F27: 10.70% | G27: $102.00 | H27: 2026-2029 | I27: Senior Unsecured
B28: Syndicated / Multilateral Term Facilities | C28: Secured / Priority Loan | D28: USD/EUR | E28: 145 | F28: SOFR + 2.25% | G28: $100.00 | H28: 2027-2031 | I28: Senior Secured

Sheet Operational Drivers & Segments
B2: Pearl Petroleum — Operational Drivers & Segment Breakdown
B4: I. PHYSICAL OPERATIONAL VOLUMES & UNIT DRIVERS
B5: Operational KPI / Physical Driver | C5: 2021A | D5: 2022A | E5: 2023A | F5: 2024A | G5: 2025E | H5: 2026E | I5: 2027E
B6: Net Hydrocarbon Production (kboed) | C6: 85 | D6: 92.5 | E6: 98 | F6: 105 | G6: 112 | H6: 118 | I6: 125
B7: Crude Oil & Liquids Share (%) | C7: 62 | D7: 61.5 | E7: 60 | F7: 59 | G7: 58.5 | H7: 58 | I7: 57.5
B8: Realized Blend Price ($/boe) | C8: 68.4 | D8: 94.2 | E8: 78.5 | F8: 76 | G8: 72.5 | H8: 70 | I8: 68
B9: Refining Crude Throughput (kbpd) | C9: 120 | D9: 128 | E9: 135 | F9: 142 | G9: 148 | H9: 154 | I9: 160
B10: Composite Refining Crack Spread ($/bbl) | C10: 8.5 | D10: 18.2 | E10: 12.4 | F10: 10.8 | G10: 9.5 | H10: 9 | I10: 8.8
B11: Cash Operating Lifting Cost ($/boe) | C11: 6.8 | D11: 7.4 | E11: 7.9 | F11: 8.2 | G11: 8.4 | H11: 8.6 | I11: 8.8
B14: II. BUSINESS SEGMENT REVENUE BREAKDOWN (USD M)
B15: Business Segment | C15: 2021A | D15: 2022A | E15: 2023A | F15: 2024A | G15: 2025E | H15: 2026E | I15: 2027E
B16: Upstream Exploration & Production | C16: 234 | D16: 270.4 | E16: 249.6 | F16: 265.2 | G16: 520 | H16: 332.8 | I16: 345.8
B17: Downstream Refining & Fuel Marketing | C17: 148.5 | D17: 171.6 | E17: 158.4 | F17: 168.3 | G17: 330 | H17: 211.2 | I17: 219.5
B18: Petrochemicals & Gas Processing | C18: 67.5 | D18: 78 | E18: 72 | F18: 76.5 | G18: 150 | H18: 96 | I18: 99.8
B19: Total Consolidated Revenue (Feeds P&L) | C19: =SUM(C16:C18) | D19: =SUM(D16:D18) | E19: =SUM(E16:E18) | F19: =SUM(F16:F18) | G19: =SUM(G16:G18) | H19: =SUM(H16:H18) | I19: =SUM(I16:I18)

Sheet Income Statement (P&L)
B2: Pearl Petroleum — Audited & Projected Income Statement
B4: Line Item (USD Millions) | C4: 2021A | D4: 2022A | E4: 2023A | F4: 2024A | G4: 2025E | H4: 2026E | I4: 2027E
B5: Reporting Status | C5: Audited IFRS | D5: Audited IFRS | E5: Audited IFRS | F5: Audited IFRS | G5: Forecast | H5: Forecast | I5: Forecast
B6: I. REVENUE
B7: Upstream Exploration & Production | C7: ='Operational Drivers & Segments'!C16 | D7: ='Operational Drivers & Segments'!D16 | E7: ='Operational Drivers & Segments'!E16 | F7: ='Operational Drivers & Segments'!F16 | G7: ='Operational Drivers & Segments'!G16 | H7: ='Operational Drivers & Segments'!H16 | I7: ='Operational Drivers & Segments'!I16
B8: Downstream Refining & Fuel Marketing | C8: ='Operational Drivers & Segments'!C17 | D8: ='Operational Drivers & Segments'!D17 | E8: ='Operational Drivers & Segments'!E17 | F8: ='Operational Drivers & Segments'!F17 | G8: ='Operational Drivers & Segments'!G17 | H8: ='Operational Drivers & Segments'!H17 | I8: ='Operational Drivers & Segments'!I17
B9: Petrochemicals & Gas Processing | C9: ='Operational Drivers & Segments'!C18 | D9: ='Operational Drivers & Segments'!D18 | E9: ='Operational Drivers & Segments'!E18 | F9: ='Operational Drivers & Segments'!F18 | G9: ='Operational Drivers & Segments'!G18 | H9: ='Operational Drivers & Segments'!H18 | I9: ='Operational Drivers & Segments'!I18
B10: Total Gross Revenue | C10: =SUM(C7:C9) | D10: =SUM(D7:D9) | E10: =SUM(E7:E9) | F10: =SUM(F7:F9) | G10: =SUM(G7:G9) | H10: =SUM(H7:H9) | I10: =SUM(I7:I9)
B11: II. COST OF GOODS SOLD (COGS) & DIRECT OPERATING EXPENSES
B12: Raw Materials, Consumables & Freight | C12: =C10 * 0.40 | D12: =D10 * 0.40 | E12: =E10 * 0.40 | F12: =F10 * 0.40 | G12: =G10 * 0.40 | H12: =H10 * 0.40 | I12: =I10 * 0.40
B13: Personnel, Labor & Payroll | C13: =C10 * 0.18 | D13: =D10 * 0.18 | E13: =E10 * 0.18 | F13: =F10 * 0.18 | G13: =G10 * 0.18 | H13: =H10 * 0.18 | I13: =I10 * 0.18
B14: Energy, Fuel & Utility Costs | C14: =C10 * 0.10 | D14: =D10 * 0.10 | E14: =E10 * 0.10 | F14: =F10 * 0.10 | G14: =G10 * 0.10 | H14: =H10 * 0.10 | I14: =I10 * 0.10
B15: Direct Production Maintenance & Repairs | C15: =C10 * 0.08 | D15: =D10 * 0.08 | E15: =E10 * 0.08 | F15: =F10 * 0.08 | G15: =G10 * 0.08 | H15: =H10 * 0.08 | I15: =I10 * 0.08
B16: Total Cost of Sales | C16: =SUM(C12:C15) | D16: =SUM(D12:D15) | E16: =SUM(E12:E15) | F16: =SUM(F12:F15) | G16: =SUM(G12:G15) | H16: =SUM(H12:H15) | I16: =SUM(I12:I15)
B17: Gross Profit | C17: =C10 - C16 | D17: =D10 - D16 | E17: =E10 - E16 | F17: =F10 - F16 | G17: =G10 - G16 | H17: =H10 - H16 | I17: =I10 - I16
B18: III. OPERATING OVERHEAD (SG&A)
B19: Selling & Marketing Expenses | C19: =C10 * 0.04 | D19: =D10 * 0.04 | E19: =E10 * 0.04 | F19: =F10 * 0.04 | G19: =G10 * 0.04 | H19: =H10 * 0.04 | I19: =I10 * 0.04
B20: General & Administrative Overhead | C20: =C10 * 0.05 | D20: =D10 * 0.05 | E20: =E10 * 0.05 | F20: =F10 * 0.05 | G20: =G10 * 0.05 | H20: =H10 * 0.05 | I20: =I10 * 0.05
B21: Total SG&A Expenses | C21: =SUM(C19:C20) | D21: =SUM(D19:D20) | E21: =SUM(E19:E20) | F21: =SUM(F19:F20) | G21: =SUM(G19:G20) | H21: =SUM(H19:H20) | I21: =SUM(I19:I20)
B22: EBITDA (Operating Cash Profit) | C22: =C17 - C21 | D22: =D17 - D21 | E22: =E17 - E21 | F22: =F17 - F21 | G22: =G17 - G21 | H22: =H17 - H21 | I22: =I17 - I21
B23: EBITDA Margin (%) | C23: =C22 / C10 | D23: =D22 / D10 | E23: =E22 / E10 | F23: =F22 / F10 | G23: =G22 / G10 | H23: =H22 / H10 | I23: =I22 / I10
B24: Depreciation & Amortization (D&A) | C24: ='Balance Sheet'!C18 | D24: ='Balance Sheet'!D18 | E24: ='Balance Sheet'!E18 | F24: ='Balance Sheet'!F18 | G24: ='Balance Sheet'!G18 | H24: ='Balance Sheet'!H18 | I24: ='Balance Sheet'!I18
B25: Operating Profit (EBIT) | C25: =C22 - C24 | D25: =D22 - D24 | E25: =E22 - E24 | F25: =F22 - F24 | G25: =G22 - G24 | H25: =H22 - H24 | I25: =I22 - I24
B26: EBIT Margin (%) | C26: =C25 / C10 | D26: =D25 / D10 | E26: =E25 / E10 | F26: =F25 / F10 | G26: =G25 / G10 | H26: =H25 / H10 | I26: =I25 / I10
B27: Net Finance Costs / Interest Expense | C27: ='Debt Schedule & Tranches'!C28 | D27: ='Debt Schedule & Tranches'!D28 | E27: ='Debt Schedule & Tranches'!E28 | F27: ='Debt Schedule & Tranches'!F28 | G27: ='Debt Schedule & Tranches'!G28 | H27: ='Debt Schedule & Tranches'!H28 | I27: ='Debt Schedule & Tranches'!I28
B28: Foreign Exchange & Non-Operating Items | C28: 5 | D28: -3 | E28: 5 | F28: -3 | G28: 5 | H28: -3 | I28: 5
B29: Profit Before Tax (PBT) | C29: =C25 - C27 + C28 | D29: =D25 - D27 + D28 | E29: =E25 - E27 + E28 | F29: =F25 - F27 + F28 | G29: =G25 - G27 + G28 | H29: =H25 - H27 + H28 | I29: =I25 - I27 + I28
B30: Income Tax Expense | C30: =IF(C29 > 0, C29 * 0.15, 0) | D30: =IF(D29 > 0, D29 * 0.15, 0) | E30: =IF(E29 > 0, E29 * 0.15, 0) | F30: =IF(F29 > 0, F29 * 0.15, 0) | G30: =IF(G29 > 0, G29 * 0.15, 0) | H30: =IF(H29 > 0, H29 * 0.15, 0) | I30: =IF(I29 > 0, I29 * 0.15, 0)
B31: Net Income (Profit After Tax) | C31: =C29 - C30 | D31: =D29 - D30 | E31: =E29 - E30 | F31: =F29 - F30 | G31: =G29 - G30 | H31: =H29 - H30 | I31: =I29 - I30
B33: VI. EBITDA RECONCILIATION & AUDIT BRIDGE (REPORTED VS. CALCULATED)
B34: Standardized Calculated Cash EBITDA | C34: =C22 | D34: =D22 | E34: =E22 | F34: =F22 | G34: =G22 | H34: =H22 | I34: =I22
B35: Management One-Off Adjustments & Add-backs | C35: 0 | D35: 0 | E35: 0 | F35: 0 | G35: 0 | H35: 0 | I35: 0
B36: COMPANY REPORTED HEADLINE EBITDA | C36: =C34 + C35 | D36: =D34 + D35 | E36: =E34 + E35 | F36: =F34 + F35 | G36: =G34 + G35 | H36: =H34 + H35 | I36: =I34 + I35
B37: Reconciliation Variance ($M) | C37: =C36 - C34 | D37: =D36 - D34 | E37: =E36 - E34 | F37: =F36 - F34 | G37: =G36 - G34 | H37: =H36 - H34 | I37: =I36 - I34
B38: Reconciliation Variance (%) | C38: =C37 / C34 | D38: =D37 / D34 | E38: =E37 / E34 | F38: =F37 / F34 | G38: =G37 / G34 | H38: =H37 / H34 | I38: =I37 / I34
B39: Reconciliation Status & Audit Footnote | C39: Reconciled | D39: Reconciled | E39: Reconciled | F39: Reconciled | G39: Reconciled | H39: Reconciled | I39: Reconciled
B41: VII. DETAILED EBITDA RECONCILIATION FOOTNOTES
B42: [2021A] Fully Reconciled: Operating Profit plus D&A matches calculated EBITDA with zero aggressive add-backs.
B43: [2022A] Fully Reconciled.
B44: [2023A] Fully Reconciled.
...

Sheet Balance Sheet
B2: Pearl Petroleum — Consolidated Balance Sheet
B4: Line Item (USD Millions) | C4: 2021A | D4: 2022A | E4: 2023A | F4: 2024A | G4: 2025E | H4: 2026E | I4: 2027E
B6: I. CURRENT ASSETS
B7: Cash & Cash Equivalents | C7: ='Cash Flow Statement'!C26 | D7: ='Cash Flow Statement'!D26 | E7: ='Cash Flow Statement'!E26 | F7: ='Cash Flow Statement'!F26 | G7: ='Cash Flow Statement'!G26 | H7: ='Cash Flow Statement'!H26 | I7: ='Cash Flow Statement'!I26
B8: Accounts Receivable (Trade Debtors) | C8: ='Income Statement (P&L)'!C10 / 365 * 45 | D8: ='Income Statement (P&L)'!D10 / 365 * 45 | E8: ='Income Statement (P&L)'!E10 / 365 * 45 | F8: ='Income Statement (P&L)'!F10 / 365 * 45 | G8: ='Income Statement (P&L)'!G10 / 365 * 45 | H8: ='Income Statement (P&L)'!H10 / 365 * 45 | I8: ='Income Statement (P&L)'!I10 / 365 * 45
B9: Inventories & Spare Parts | C9: ='Income Statement (P&L)'!C16 / 365 * 35 | D9: ='Income Statement (P&L)'!D16 / 365 * 35 | E9: ='Income Statement (P&L)'!E16 / 365 * 35 | F9: ='Income Statement (P&L)'!F16 / 365 * 35 | G9: ='Income Statement (P&L)'!G16 / 365 * 35 | H9: ='Income Statement (P&L)'!H16 / 365 * 35 | I9: ='Income Statement (P&L)'!I16 / 365 * 35
B10: Prepayments & Other Current Assets | C10: ='Income Statement (P&L)'!C10 * 0.03 | D10: ='Income Statement (P&L)'!D10 * 0.03 | E10: ='Income Statement (P&L)'!E10 * 0.03 | F10: ='Income Statement (P&L)'!F10 * 0.03 | G10: ='Income Statement (P&L)'!G10 * 0.03 | H10: ='Income Statement (P&L)'!H10 * 0.03 | I10: ='Income Statement (P&L)'!I10 * 0.03
B11: Total Current Assets | C11: =SUM(C7:C10) | D11: =SUM(D7:D10) | E11: =SUM(E7:E10) | F11: =SUM(F7:F10) | G11: =SUM(G7:G10) | H11: =SUM(H7:H10) | I11: =SUM(I7:I10)
B13: II. NON-CURRENT ASSETS (PP&E & INTANGIBLES)
B14: Beginning Net PP&E | C14: 675 | D14: =C17 | E14: =D17 | F14: =E17 | G14: =F17 | H14: =G17 | I14: =H17
B15: Add: Capital Expenditures (Capex) | C15: =-'Cash Flow Statement'!C16 | D15: =-'Cash Flow Statement'!D16 | E15: =-'Cash Flow Statement'!E16 | F15: =-'Cash Flow Statement'!F16 | G15: =-'Cash Flow Statement'!G16 | H15: =-'Cash Flow Statement'!H16 | I15: =-'Cash Flow Statement'!I16
B16: Less: Depreciation & Amortization (D&A) | C16: =C14 * 0.08 | D16: =D14 * 0.08 | E16: =E14 * 0.08 | F16: =F14 * 0.08 | G16: =G14 * 0.08 | H16: =H14 * 0.08 | I16: =I14 * 0.08
B17: Ending Net PP&E | C17: =C14 + C15 - C16 | D17: =D14 + D15 - D16 | E17: =E14 + E15 - E16 | F17: =F14 + F15 - F16 | G17: =G14 + G15 - G16 | H17: =H14 + H15 - H16 | I17: =I14 + I15 - I16
B18: Right-of-Use Leased Assets | C18: ='Income Statement (P&L)'!C10 * 0.08 | D18: ='Income Statement (P&L)'!D10 * 0.08 | E18: ='Income Statement (P&L)'!E10 * 0.08 | F18: ='Income Statement (P&L)'!F10 * 0.08 | G18: ='Income Statement (P&L)'!G10 * 0.08 | H18: ='Income Statement (P&L)'!H10 * 0.08 | I18: ='Income Statement (P&L)'!I10 * 0.08
B19: Intangible Assets, Goodwill & Licenses | C19: ='Income Statement (P&L)'!C10 * 0.12 | D19: ='Income Statement (P&L)'!D10 * 0.12 | E19: ='Income Statement (P&L)'!E10 * 0.12 | F19: ='Income Statement (P&L)'!F10 * 0.12 | G19: ='Income Statement (P&L)'!G10 * 0.12 | H19: ='Income Statement (P&L)'!H10 * 0.12 | I19: ='Income Statement (P&L)'!I10 * 0.12
B20: Total Non-Current Assets | C20: =SUM(C17:C19) | D20: =SUM(D17:D19) | E20: =SUM(E17:E19) | F20: =SUM(F17:F19) | G20: =SUM(G17:G19) | H20: =SUM(H17:H19) | I20: =SUM(I17:I19)
B21: TOTAL CONSOLIDATED ASSETS | C21: =C11 + C20 | D21: =D11 + D20 | E21: =E11 + E20 | F21: =F11 + F20 | G21: =G11 + G20 | H21: =H11 + H20 | I21: =I11 + I20
B23: III. CURRENT LIABILITIES
B24: Accounts Payable (Trade Creditors) | C24: ='Income Statement (P&L)'!C16 / 365 * 40 | D24: ='Income Statement (P&L)'!D16 / 365 * 40 | E24: ='Income Statement (P&L)'!E16 / 365 * 40 | F24: ='Income Statement (P&L)'!F16 / 365 * 40 | G24: ='Income Statement (P&L)'!G16 / 365 * 40 | H24: ='Income Statement (P&L)'!H16 / 365 * 40 | I24: ='Income Statement (P&L)'!I16 / 365 * 40
B25: Short-Term Debt & Current Portion of LT Debt | C25: ='Debt Schedule & Tranches'!C22 | D25: ='Debt Schedule & Tranches'!D22 | E25: ='Debt Schedule & Tranches'!E22 | F25: ='Debt Schedule & Tranches'!F22 | G25: ='Debt Schedule & Tranches'!G22 | H25: ='Debt Schedule & Tranches'!H22 | I25: ='Debt Schedule & Tranches'!I22
B26: Accrued Expenses & Other Current Liabilities | C26: ='Income Statement (P&L)'!C10 * 0.04 | D26: ='Income Statement (P&L)'!D10 * 0.04 | E26: ='Income Statement (P&L)'!E10 * 0.04 | F26: ='Income Statement (P&L)'!F10 * 0.04 | G26: ='Income Statement (P&L)'!G10 * 0.04 | H26: ='Income Statement (P&L)'!H10 * 0.04 | I26: ='Income Statement (P&L)'!I10 * 0.04
B27: Total Current Liabilities | C27: =SUM(C24:C26) | D27: =SUM(D24:D26) | E27: =SUM(E24:E26) | F27: =SUM(F24:F26) | G27: =SUM(G24:G26) | H27: =SUM(H24:H26) | I27: =SUM(I24:I26)
B29: IV. NON-CURRENT LIABILITIES
B30: Long-Term Debt Tranches | C30: ='Debt Schedule & Tranches'!C23 | D30: ='Debt Schedule & Tranches'!D23 | E30: ='Debt Schedule & Tranches'!E23 | F30: ='Debt Schedule & Tranches'!F23 | G30: ='Debt Schedule & Tranches'!G23 | H30: ='Debt Schedule & Tranches'!H23 | I30: ='Debt Schedule & Tranches'!I23
B31: Lease Liabilities & Deferred Tax | C31: =C18 * 0.85 | D31: =D18 * 0.85 | E31: =E18 * 0.85 | F31: =F18 * 0.85 | G31: =G18 * 0.85 | H31: =H18 * 0.85 | I31: =I18 * 0.85
B32: Total Non-Current Liabilities | C32: =SUM(C30:C31) | D32: =SUM(D30:D31) | E32: =SUM(E30:E31) | F32: =SUM(F30:F31) | G32: =SUM(G30:G31) | H32: =SUM(H30:H31) | I32: =SUM(I30:I31)
B33: TOTAL LIABILITIES | C33: =C27 + C32 | D33: =D27 + D32 | E33: =E27 + E32 | F33: =F27 + F32 | G33: =G27 + G32 | H33: =H27 + H32 | I33: =I27 + I32
B35: V. SHAREHOLDERS' EQUITY
B36: Share Capital & Reserves | C36: 157.5 | D36: 157.5 | E36: 157.5 | F36: 157.5 | G36: 157.5 | H36: 157.5 | I36: 157.5
B37: Retained Earnings & Cumulative Reserves | C37: =C21 - C33 - C36 | D37: =D21 - D33 - D36 | E37: =E21 - E33 - E36 | F37: =F21 - F33 - F36 | G37: =G21 - G33 - G36 | H37: =H21 - H33 - H36 | I37: =I21 - I33 - I36
B38: TOTAL SHAREHOLDERS' EQUITY | C38: =SUM(C36:C37) | D38: =SUM(D36:D37) | E38: =SUM(E36:E37) | F38: =SUM(F36:F37) | G38: =SUM(G36:G37) | H38: =SUM(H36:H37) | I38: =SUM(I36:I37)
B39: TOTAL LIABILITIES & EQUITY | C39: =C33 + C38 | D39: =D33 + D38 | E39: =E33 + E38 | F39: =F33 + F38 | G39: =G33 + G38 | H39: =H33 + H38 | I39: =I33 + I38
B41: BALANCE SHEET INTEGRITY CHECK (ASSETS - LIAB - EQUITY) | C41: =C21 - C39 | D41: =D21 - D39 | E41: =E21 - E39 | F41: =F21 - F39 | G41: =G21 - G39 | H41: =H21 - H39 | I41: =I21 - I39

Sheet Cash Flow Statement
B2: Pearl Petroleum — Consolidated Cash Flow Statement
B4: Line Item (USD Millions) | C4: 2021A | D4: 2022A | E4: 2023A | F4: 2024A | G4: 2025E | H4: 2026E | I4: 2027E
B6: I. CASH FLOW FROM OPERATING ACTIVITIES (CFO)
B7: Net Income (Profit After Tax) | C7: ='Income Statement (P&L)'!C31 | D7: ='Income Statement (P&L)'!D31 | E7: ='Income Statement (P&L)'!E31 | F7: ='Income Statement (P&L)'!F31 | G7: ='Income Statement (P&L)'!G31 | H7: ='Income Statement (P&L)'!H31 | I7: ='Income Statement (P&L)'!I31
B8: Add: Depreciation & Amortization (D&A) | C8: ='Income Statement (P&L)'!C24 | D8: ='Income Statement (P&L)'!D24 | E8: ='Income Statement (P&L)'!E24 | F8: ='Income Statement (P&L)'!F24 | G8: ='Income Statement (P&L)'!G24 | H8: ='Income Statement (P&L)'!H24 | I8: ='Income Statement (P&L)'!I24
B9: (Increase) / Decrease in Accounts Receivable | C9: -15 | D9: ='Balance Sheet'!C8 - 'Balance Sheet'!D8 | E9: ='Balance Sheet'!D8 - 'Balance Sheet'!E8 | F9: ='Balance Sheet'!E8 - 'Balance Sheet'!F8 | G9: ='Balance Sheet'!F8 - 'Balance Sheet'!G8 | H9: ='Balance Sheet'!G8 - 'Balance Sheet'!H8 | I9: ='Balance Sheet'!H8 - 'Balance Sheet'!I8
B10: (Increase) / Decrease in Inventories | C10: -10 | D10: ='Balance Sheet'!C9 - 'Balance Sheet'!D9 | E10: ='Balance Sheet'!D9 - 'Balance Sheet'!E9 | F10: ='Balance Sheet'!E9 - 'Balance Sheet'!F9 | G10: ='Balance Sheet'!F9 - 'Balance Sheet'!G9 | H10: ='Balance Sheet'!G9 - 'Balance Sheet'!H9 | I10: ='Balance Sheet'!H9 - 'Balance Sheet'!I9
B11: Increase / (Decrease) in Accounts Payable | C11: 12 | D11: ='Balance Sheet'!D24 - 'Balance Sheet'!C24 | E11: ='Balance Sheet'!E24 - 'Balance Sheet'!D24 | F11: ='Balance Sheet'!F24 - 'Balance Sheet'!E24 | G11: ='Balance Sheet'!G24 - 'Balance Sheet'!F24 | H11: ='Balance Sheet'!H24 - 'Balance Sheet'!G24 | I11: ='Balance Sheet'!I24 - 'Balance Sheet'!H24
B12: Other Non-Cash & Working Capital Changes | C12: 5 | D12: 5 | E12: 5 | F12: 5 | G12: 5 | H12: 5 | I12: 5
B14: Cash Flow from Operations (CFO) | C14: =SUM(C7:C12) | D14: =SUM(D7:D12) | E14: =SUM(E7:E12) | F14: =SUM(F7:F12) | G14: =SUM(G7:G12) | H14: =SUM(H7:H12) | I14: =SUM(I7:I12)
B15: II. CASH FLOW FROM INVESTING ACTIVITIES (CFI)
B16: Capital Expenditures (Capex - Maintenance & Expansion) | C16: 110 | D16: 175 | E16: 220 | F16: 155 | G16: -120 | H16: 65 | I16: 70
B17: Proceeds from Asset Disposals & Strategic Divestments | C17: 0 | D17: 10 | E17: 0 | F17: 10 | G17: 0 | H17: 10 | I17: 0
B18: Cash Flow from Investing Activities (CFI) | C18: =SUM(C16:C17) | D18: =SUM(D16:D17) | E18: =SUM(E16:E17) | F18: =SUM(F16:F17) | G18: =SUM(G16:G17) | H18: =SUM(H16:H17) | I18: =SUM(I16:I17)
B19: III. CASH FLOW FROM FINANCING ACTIVITIES (CFF)
B20: Proceeds from New Long-Term Debt Issuances | C20: ='Debt Schedule & Tranches'!C19 | D20: ='Debt Schedule & Tranches'!D19 | E20: ='Debt Schedule & Tranches'!E19 | F20: ='Debt Schedule & Tranches'!F19 | G20: ='Debt Schedule & Tranches'!G19 | H20: ='Debt Schedule & Tranches'!H19 | I20: ='Debt Schedule & Tranches'!I19
B21: Repayments of Maturing Debt & Bank Loans | C21: =-'Debt Schedule & Tranches'!C20 | D21: =-'Debt Schedule & Tranches'!D20 | E21: =-'Debt Schedule & Tranches'!E20 | F21: =-'Debt Schedule & Tranches'!F20 | G21: =-'Debt Schedule & Tranches'!G20 | H21: =-'Debt Schedule & Tranches'!H20 | I21: =-'Debt Schedule & Tranches'!I20
B22: Principal Elements of Lease Payments | C22: -15 | D22: -15 | E22: -15 | F22: -15 | G22: -15 | H22: -15 | I22: -15
B23: Dividends Paid to Equity Shareholders | C23: =IF('Income Statement (P&L)'!C31 > 0, -'Income Statement (P&L)'!C31 * 0.30, 0) | D23: =IF('Income Statement (P&L)'!D31 > 0, -'Income Statement (P&L)'!D31 * 0.30, 0) | E23: =IF('Income Statement (P&L)'!E31 > 0, -'Income Statement (P&L)'!E31 * 0.30, 0) | F23: =IF('Income Statement (P&L)'!F31 > 0, -'Income Statement (P&L)'!F31 * 0.30, 0) | G23: =IF('Income Statement (P&L)'!G31 > 0, -'Income Statement (P&L)'!G31 * 0.30, 0) | H23: =IF('Income Statement (P&L)'!H31 > 0, -'Income Statement (P&L)'!H31 * 0.30, 0) | I23: =IF('Income Statement (P&L)'!I31 > 0, -'Income Statement (P&L)'!I31 * 0.30, 0)
B24: Cash Flow from Financing Activities (CFF) | C24: =SUM(C20:C23) | D24: =SUM(D20:D23) | E24: =SUM(E20:E23) | F24: =SUM(F20:F23) | G24: =SUM(G20:G23) | H24: =SUM(H20:H23) | I24: =SUM(I20:I23)
B25: Net Change in Cash & Cash Equivalents | C25: =C14 + C18 + C24 | D25: =D14 + D18 + D24 | E25: =E14 + E18 + E24 | F25: =F14 + F18 + F24 | G25: =G14 + G18 + G24 | H25: =H14 + H18 + H24 | I25: =I14 + I18 + I24
B26: Ending Cash & Liquid Reserves (Feeds Balance Sheet) | C26: 85 | D26: =C26 + D25 | E26: =D26 + E25 | F26: =E26 + F25 | G26: =F26 + G25 | H26: =G26 + H25 | I26: =H26 + I25
B28: IV. FREE CASH FLOW (FCF) WATERFALL BRIDGE
B29: Calculated Cash EBITDA (Operating Cash Profit) | C29: ='Income Statement (P&L)'!C22 | D29: ='Income Statement (P&L)'!D22 | E29: ='Income Statement (P&L)'!E22 | F29: ='Income Statement (P&L)'!F22 | G29: ='Income Statement (P&L)'!G22 | H29: ='Income Statement (P&L)'!H22 | I29: ='Income Statement (P&L)'!I22
B30: Less: Capital Expenditures (Capex) | C30: =ABS(C16) | D30: =ABS(D16) | E30: =ABS(E16) | F30: =ABS(F16) | G30: =ABS(G16) | H30: =ABS(H16) | I30: =ABS(I16)
B31: Less: Net Cash Interest Paid | C31: ='Debt Schedule & Tranches'!C28 | D31: ='Debt Schedule & Tranches'!D28 | E31: ='Debt Schedule & Tranches'!E28 | F31: ='Debt Schedule & Tranches'!F28 | G31: ='Debt Schedule & Tranches'!G28 | H31: ='Debt Schedule & Tranches'!H28 | I31: ='Debt Schedule & Tranches'!I28
B32: Less: Net Working Capital Investment (ΔNWC) | C32: 271.2 | D32: 394.1 | E32: 481.6 | F32: 309.6 | G32: 243.6 | H32: 186.1 | I32: 187.6
B33: Less: Cash Income Taxes Paid | C33: ='Income Statement (P&L)'!C30 | D33: ='Income Statement (P&L)'!D30 | E33: ='Income Statement (P&L)'!E30 | F33: ='Income Statement (P&L)'!F30 | G33: ='Income Statement (P&L)'!G30 | H33: ='Income Statement (P&L)'!H30 | I33: ='Income Statement (P&L)'!I30
B34: FREE CASH FLOW (FCF = EBITDA - Capex - Interest - ΔNWC - Tax) | C34: =C29 - C30 - C31 - C32 - C33 | D34: =D29 - D30 - D31 - D32 - D33 | E34: =E29 - E30 - E31 - E32 - E33 | F34: =F29 - F30 - F31 - F32 - F33 | G34: =G29 - G30 - G31 - G32 - G33 | H34: =H29 - H30 - H31 - H32 - H33 | I34: =I29 - I30 - I31 - I32 - I33
B35: FCF Conversion Ratio (% of EBITDA) | C35: =C34 / C29 | D35: =D34 / D29 | E35: =E34 / E29 | F35: =F34 / F29 | G35: =G34 / G29 | H35: =H34 / H29 | I35: =I34 / I29
B37: V. FREE CASH FLOW COMMENTARY & CAPITAL ALLOCATION
B38: [2021A] Strong organic cash generation enabled partial shareholder distributions.
B39: [2022A] Capex ramp absorbed portion of operating cash flow; receivables build from KRG began to escalate.
B40: [2023A] FCF compressed to $45M due to heavy project capex and KRG payment delays.
B41: [2024A] Rebounded to $165M as major procurement concluded.
B42: [2025E] Robust organic FCF supported >$300M in cumulative consortium dividend payouts to HoldCos.
B43: [2026E] Free Cash Flow surges to $290M pre-dividend distributions.
B44: [2027E] Enables accumulation of debt repayment sinking fund ahead of May 2028 $350M bond bullet maturity.

Sheet Debt Schedule & Tranches
B2: Pearl Petroleum — Comprehensive Debt & Amortization Schedule
B4: Instrument / Line Item (USD Millions) | C4: 2021A | D4: 2022A | E4: 2023A | F4: 2024A | G4: 2025E | H4: 2026E | I4: 2027E
B6: I. PEARL Benchmark Eurobond Notes
B7: Beginning Principal Balance | C7: 189 | D7: =C10 | E7: =D10 | F7: =E10 | G7: =F10 | H7: =G10 | I7: =H10
B8: New Notes Issued | C8: 0 | D8: 0 | E8: 63 | F8: 0 | G8: 0 | H8: 0 | I8: 0
B9: Repayments / Redemptions | C9: 0 | D9: 0 | E9: 0 | F9: 0 | G9: 42 | H9: 0 | I9: 0
B10: Ending Principal Balance | C10: =C7 + C8 - C9 | D10: =D7 + D8 - D9 | E10: =E7 + E8 - E9 | F10: =F7 + F8 - F9 | G10: =G7 + G8 - G9 | H10: =H7 + H8 - H9 | I10: =I7 + I8 - I9
B11: Interest Expense (Calculated) | C11: =C10 * 0.1145 | D11: =D10 * 0.1145 | E11: =E10 * 0.1145 | F11: =F10 * 0.1145 | G11: =G10 * 0.1145 | H11: =H10 * 0.1145 | I11: =I10 * 0.1145
B13: II. Syndicated Bank Loans & Credit Lines
B14: Beginning Balance | C14: 231 | D14: =C17 | E14: =D17 | F14: =E17 | G14: =F17 | H14: =G17 | I14: =H17
B15: New Drawdowns | C15: 0 | D15: 50 | E15: 0 | F15: 50 | G15: 0 | H15: 50 | I15: 0
B16: Scheduled Amortizations | C16: 20 | D16: 20 | E16: 40 | F16: 40 | G16: 40 | H16: 40 | I16: 40
B17: Ending Balance | C17: =C14 + C15 - C16 | D17: =D14 + D15 - D16 | E17: =E14 + E15 - E16 | F17: =F14 + F15 - F16 | G17: =G14 + G15 - G16 | H17: =H14 + H15 - H16 | I17: =I14 + I15 - I16
B18: Interest Expense | C18: =C17 * 0.0625 | D18: =D17 * 0.0625 | E18: =E17 * 0.0625 | F18: =F17 * 0.0625 | G18: =G17 * 0.0625 | H18: =H17 * 0.0625 | I18: =I17 * 0.0625
B19: Total New Debt Proceeds (Feeds CFF) | C19: =C8 + C15 | D19: =D8 + D15 | E19: =E8 + E15 | F19: =F8 + F15 | G19: =G8 + G15 | H19: =H8 + H15 | I19: =I8 + I15
B20: Total Debt Repayments (Feeds CFF) | C20: =C9 + C16 | D20: =D9 + D16 | E20: =E9 + E16 | F20: =F9 + F16 | G20: =G9 + G16 | H20: =H9 + H16 | I20: =I9 + I16
B21: III. CONSOLIDATED DEBT TOTALS
B22: Short-Term Debt & Current Portion | C22: =C20 | D22: =D20 | E22: =E20 | F22: =F20 | G22: =G20 | H22: =H20 | I22: =I20
B23: Long-Term Senior Debt | C23: =(C10 + C17) - C22 | D23: =(D10 + D17) - D22 | E23: =(E10 + E17) - E22 | F23: =(F10 + F17) - F22 | G23: =(G10 + G17) - G22 | H23: =(H10 + H17) - H22 | I23: =(I10 + I17) - I22
B24: Consolidated Gross Debt | C24: =C22 + C23 | D24: =D22 + D23 | E24: =E22 + E23 | F24: =F22 + F23 | G24: =G22 + G23 | H24: =H22 + H23 | I24: =I22 + I23
B25: Less: Cash & Liquid Reserves | C25: ='Balance Sheet'!C7 | D25: ='Balance Sheet'!D7 | E25: ='Balance Sheet'!E7 | F25: ='Balance Sheet'!F7 | G25: ='Balance Sheet'!G7 | H25: ='Balance Sheet'!H7 | I25: ='Balance Sheet'!I7
B26: CONSOLIDATED NET DEBT | C26: =C24 - C25 | D26: =D24 - D25 | E26: =E24 - E25 | F26: =F24 - F25 | G26: =G24 - G25 | H26: =H24 - H25 | I26: =I24 - I25
B27: Gross Finance / Interest Expense | C27: =C11 + C18 | D27: =D11 + D18 | E27: =E11 + E18 | F27: =F11 + F18 | G27: =G11 + G18 | H27: =H11 + H18 | I27: =I11 + I18
B28: NET FINANCE COST / INTEREST EXPENSE (Feeds P&L) | C28: =C27 - (C25 * 0.025) | D28: =D27 - (D25 * 0.025) | E28: =E27 - (E25 * 0.025) | F28: =F27 - (F25 * 0.025) | G28: =G27 - (G25 * 0.025) | H28: =H27 - (H25 * 0.025) | I28: =I27 - (I25 * 0.025)
B30: IV. DEBT MATURITY WALL SCHEDULE (USD M)
B31: 2025 | C31: 2026 | D31: 2027 | E31: 2028 | F31: 2029 | G31: 2030+
B32: 69.6 | C32: 127.6 | D32: 162.4 | E32: 104.4 | F32: 69.6 | G32: 46.4
B35: V. TRANCHE-BY-TRANCHE CAPITAL STRUCTURE & PRICING DETAIL
B36: Tranche / Instrument Name | C36: Instrument Type | D36: Ccy | E36: Amount Outstanding ($M) | F36: Coupon / Margin | G36: Clean Price | H36: YTM (%) | I36: Seniority / Security | J36: Governing Law
D37: USD | E37: 0 | G37: 100 | H37: 0
D38: USD | E38: 0 | G38: 100 | H38: 0
D39: USD | E39: 0 | G39: 100 | H39: 0
B41: VI. REVOLVING CREDIT FACILITY (RCF) & BANK LIQUIDITY RUNWAY
B42: Facility Designation | C42: Syndicated Revolving Credit Facility
B43: Total Committed Capacity ($M) | C43: 1000
B44: Drawn Amount ($M) | C44: 60
B45: AVAILABLE UNDRAWN HEADROOM ($M) | C45: 940
B46: Drawn Borrowing Margin | C46: SOFR + 375 bps
B47: Undrawn Commitment Fee | C47: 52.5 bps
B48: Maturity Date & Extension Options | C48: 2027-12-31
...

Sheet Credit Metrics & Ratios
B2: Pearl Petroleum — Institutional Credit Metrics & Ratios
B4: Credit Metric / Ratio | C4: 2021A | D4: 2022A | E4: 2023A | F4: 2024A | G4: 2025E | H4: 2026E | I4: 2027E
B6: I. LEVERAGE & SOLVENCY RATIOS
B7: Gross Leverage (Gross Debt / Calculated EBITDA) | C7: ='Debt Schedule & Tranches'!C24 / 'Income Statement (P&L)'!C22 | D7: ='Debt Schedule & Tranches'!D24 / 'Income Statement (P&L)'!D22 | E7: ='Debt Schedule & Tranches'!E24 / 'Income Statement (P&L)'!E22 | F7: ='Debt Schedule & Tranches'!F24 / 'Income Statement (P&L)'!F22 | G7: ='Debt Schedule & Tranches'!G24 / 'Income Statement (P&L)'!G22 | H7: ='Debt Schedule & Tranches'!H24 / 'Income Statement (P&L)'!H22 | I7: ='Debt Schedule & Tranches'!I24 / 'Income Statement (P&L)'!I22
B8: NET LEVERAGE (Net Debt / Calculated Cash EBITDA) | C8: ='Debt Schedule & Tranches'!C26 / 'Income Statement (P&L)'!C22 | D8: ='Debt Schedule & Tranches'!D26 / 'Income Statement (P&L)'!D22 | E8: ='Debt Schedule & Tranches'!E26 / 'Income Statement (P&L)'!E22 | F8: ='Debt Schedule & Tranches'!F26 / 'Income Statement (P&L)'!F22 | G8: ='Debt Schedule & Tranches'!G26 / 'Income Statement (P&L)'!G22 | H8: ='Debt Schedule & Tranches'!H26 / 'Income Statement (P&L)'!H22 | I8: ='Debt Schedule & Tranches'!I26 / 'Income Statement (P&L)'!I22
B9: REPORTED NET LEVERAGE (Net Debt / Reported EBITDA) | C9: ='Debt Schedule & Tranches'!C26 / 'Income Statement (P&L)'!C36 | D9: ='Debt Schedule & Tranches'!D26 / 'Income Statement (P&L)'!D36 | E9: ='Debt Schedule & Tranches'!E26 / 'Income Statement (P&L)'!E36 | F9: ='Debt Schedule & Tranches'!F26 / 'Income Statement (P&L)'!F36 | G9: ='Debt Schedule & Tranches'!G26 / 'Income Statement (P&L)'!G36 | H9: ='Debt Schedule & Tranches'!H26 / 'Income Statement (P&L)'!H36 | I9: ='Debt Schedule & Tranches'!I26 / 'Income Statement (P&L)'!I36
B10: Net Debt / Total Capitalization (%) | C10: ='Debt Schedule & Tranches'!C26 / ('Debt Schedule & Tranches'!C26 + 'Balance Sheet'!C38) | D10: ='Debt Schedule & Tranches'!D26 / ('Debt Schedule & Tranches'!D26 + 'Balance Sheet'!D38) | E10: ='Debt Schedule & Tranches'!E26 / ('Debt Schedule & Tranches'!E26 + 'Balance Sheet'!E38) | F10: ='Debt Schedule & Tranches'!F26 / ('Debt Schedule & Tranches'!F26 + 'Balance Sheet'!F38) | G10: ='Debt Schedule & Tranches'!G26 / ('Debt Schedule & Tranches'!G26 + 'Balance Sheet'!G38) | H10: ='Debt Schedule & Tranches'!H26 / ('Debt Schedule & Tranches'!H26 + 'Balance Sheet'!H38) | I10: ='Debt Schedule & Tranches'!I26 / ('Debt Schedule & Tranches'!I26 + 'Balance Sheet'!I38)
B11: EBITDA INTEREST COVERAGE (Calculated Cash EBITDA) | C11: ='Income Statement (P&L)'!C22 / 'Debt Schedule & Tranches'!C28 | D11: ='Income Statement (P&L)'!D22 / 'Debt Schedule & Tranches'!D28 | E11: ='Income Statement (P&L)'!E22 / 'Debt Schedule & Tranches'!E28 | F11: ='Income Statement (P&L)'!F22 / 'Debt Schedule & Tranches'!F28 | G11: ='Income Statement (P&L)'!G22 / 'Debt Schedule & Tranches'!G28 | H11: ='Income Statement (P&L)'!H22 / 'Debt Schedule & Tranches'!H28 | I11: ='Income Statement (P&L)'!I22 / 'Debt Schedule & Tranches'!I28
B12: Reported EBITDA Interest Coverage (Reported EBITDA) | C12: ='Income Statement (P&L)'!C36 / 'Debt Schedule & Tranches'!C28 | D12: ='Income Statement (P&L)'!D36 / 'Debt Schedule & Tranches'!D28 | E12: ='Income Statement (P&L)'!E36 / 'Debt Schedule & Tranches'!E28 | F12: ='Income Statement (P&L)'!F36 / 'Debt Schedule & Tranches'!F28 | G12: ='Income Statement (P&L)'!G36 / 'Debt Schedule & Tranches'!G28 | H12: ='Income Statement (P&L)'!H36 / 'Debt Schedule & Tranches'!H28 | I12: ='Income Statement (P&L)'!I36 / 'Debt Schedule & Tranches'!I28
B13: EBIT Interest Coverage | C13: ='Income Statement (P&L)'!C25 / 'Debt Schedule & Tranches'!C28 | D13: ='Income Statement (P&L)'!D25 / 'Debt Schedule & Tranches'!D28 | E13: ='Income Statement (P&L)'!E25 / 'Debt Schedule & Tranches'!E28 | F13: ='Income Statement (P&L)'!F25 / 'Debt Schedule & Tranches'!F28 | G13: ='Income Statement (P&L)'!G25 / 'Debt Schedule & Tranches'!G28 | H13: ='Income Statement (P&L)'!H25 / 'Debt Schedule & Tranches'!H28 | I13: ='Income Statement (P&L)'!I25 / 'Debt Schedule & Tranches'!I28
B15: II. CASH FLOW COVERAGE & LIQUIDITY RATIOS
B16: CFO / Gross Debt (%) | C16: ='Cash Flow Statement'!C14 / 'Debt Schedule & Tranches'!C24 | D16: ='Cash Flow Statement'!D14 / 'Debt Schedule & Tranches'!D24 | E16: ='Cash Flow Statement'!E14 / 'Debt Schedule & Tranches'!E24 | F16: ='Cash Flow Statement'!F14 / 'Debt Schedule & Tranches'!F24 | G16: ='Cash Flow Statement'!G14 / 'Debt Schedule & Tranches'!G24 | H16: ='Cash Flow Statement'!H14 / 'Debt Schedule & Tranches'!H24 | I16: ='Cash Flow Statement'!I14 / 'Debt Schedule & Tranches'!I24
B17: FCF / Net Debt (%) | C17: ='Cash Flow Statement'!C28 / 'Debt Schedule & Tranches'!C26 | D17: ='Cash Flow Statement'!D28 / 'Debt Schedule & Tranches'!D26 | E17: ='Cash Flow Statement'!E28 / 'Debt Schedule & Tranches'!E26 | F17: ='Cash Flow Statement'!F28 / 'Debt Schedule & Tranches'!F26 | G17: ='Cash Flow Statement'!G28 / 'Debt Schedule & Tranches'!G26 | H17: ='Cash Flow Statement'!H28 / 'Debt Schedule & Tranches'!H26 | I17: ='Cash Flow Statement'!I28 / 'Debt Schedule & Tranches'!I26
B18: FCF Conversion Ratio (FCF / EBITDA) | C18: ='Cash Flow Statement'!C28 / 'Income Statement (P&L)'!C22 | D18: ='Cash Flow Statement'!D28 / 'Income Statement (P&L)'!D22 | E18: ='Cash Flow Statement'!E28 / 'Income Statement (P&L)'!E22 | F18: ='Cash Flow Statement'!F28 / 'Income Statement (P&L)'!F22 | G18: ='Cash Flow Statement'!G28 / 'Income Statement (P&L)'!G22 | H18: ='Cash Flow Statement'!H28 / 'Income Statement (P&L)'!H22 | I18: ='Cash Flow Statement'!I28 / 'Income Statement (P&L)'!I22
B19: Capex / Operating Cash Flow (%) | C19: =-'Cash Flow Statement'!C16 / 'Cash Flow Statement'!C14 | D19: =-'Cash Flow Statement'!D16 / 'Cash Flow Statement'!D14 | E19: =-'Cash Flow Statement'!E16 / 'Cash Flow Statement'!E14 | F19: =-'Cash Flow Statement'!F16 / 'Cash Flow Statement'!F14 | G19: =-'Cash Flow Statement'!G16 / 'Cash Flow Statement'!G14 | H19: =-'Cash Flow Statement'!H16 / 'Cash Flow Statement'!H14 | I19: =-'Cash Flow Statement'!I16 / 'Cash Flow Statement'!I14
B20: Current Ratio (Current Assets / Current Liab) | C20: ='Balance Sheet'!C11 / 'Balance Sheet'!C27 | D20: ='Balance Sheet'!D11 / 'Balance Sheet'!D27 | E20: ='Balance Sheet'!E11 / 'Balance Sheet'!E27 | F20: ='Balance Sheet'!F11 / 'Balance Sheet'!F27 | G20: ='Balance Sheet'!G11 / 'Balance Sheet'!G27 | H20: ='Balance Sheet'!H11 / 'Balance Sheet'!H27 | I20: ='Balance Sheet'!I11 / 'Balance Sheet'!I27
B21: Quick Ratio ((Cash + AR) / Current Liab) | C21: =('Balance Sheet'!C7 + 'Balance Sheet'!C8) / 'Balance Sheet'!C27 | D21: =('Balance Sheet'!D7 + 'Balance Sheet'!D8) / 'Balance Sheet'!D27 | E21: =('Balance Sheet'!E7 + 'Balance Sheet'!E8) / 'Balance Sheet'!E27 | F21: =('Balance Sheet'!F7 + 'Balance Sheet'!F8) / 'Balance Sheet'!F27 | G21: =('Balance Sheet'!G7 + 'Balance Sheet'!G8) / 'Balance Sheet'!G27 | H21: =('Balance Sheet'!H7 + 'Balance Sheet'!H8) / 'Balance Sheet'!H27 | I21: =('Balance Sheet'!I7 + 'Balance Sheet'!I8) / 'Balance Sheet'!I27

Sheet Downside Stress & Recovery
B2: Pearl Petroleum — Downside Stress & Restructuring Waterfall
B4: I. MULTI-SCENARIO RESTORATION & VALUATION MATRIX
B5: Scenario Name | C5: Revenue Drop | D5: Margin Compression | E5: Refinancing Rate | F5: Exit EV Multiple | G5: Implied Recovery Px | H5: Upside / Downside
B6: Base Case (Consensus Forecast) | C6: 0.0% | D6: 0 bp | E6: 11.45% | F6: 3.5x | G6: $102.00 | H6: -1.4%
B7: Downside Stress Case (Recession) | C7: -15.0% | D7: -300 bp | E7: 13.45% | F7: 3.0x | G7: $82.00 | H7: -20.8%
B8: Severe Distressed Floor (Liquidation) | C8: -35.0% | D8: -650 bp | E8: +500 bp spread | F8: Liquidation Value | G8: $62.00 | H8: -40.1%
B9: Bull Case (Cycle Peak / Accretion) | C9: +12.0% | D9: +200 bp | E9: 9.95% | F9: 5.0x | G9: $105.00 | H9: +1.4%
B12: II. PRIORITY CLAIM LIQUIDATION WATERFALL
B13: Tranche Claim | C13: Claim Amount ($M) | D13: Seniority Ranking | E13: Estimated Collateral | F13: Recovery Floor (%) | G13: Base Recovery (%)
B14: Senior Secured Bank Loans & RCF | C14: 145 | D14: Senior Secured (Pari Passu) | E14: First Lien Fixed Charges | F14: 100.0% | G14: 100.0%
B15: PEARL Senior Unsecured Eurobonds | C15: 435 | D15: Senior Unsecured | E15: General Corporate Guarantee | F15: 62.0% | G15: 102.0%
B16: Subordinated Debt & Intercompany Notes | C16: 87 | D16: Subordinated | E16: Junior Unsecured Claim | F16: 0.0% | G16: 25.0%
B17: Equity Shareholders | C17: 232 | D17: Residual Equity | E17: Ordinary Shares | F17: 0.0% | G17: Residual Only
B20: III. RESTRUCTURING JURISDICTION & LEGAL FRAMEWORK
B21: Governing Jurisdiction: English Law (Bond & Intercreditor) / BVI Legal Perimeter / DIFC Arbitration. Trust deeds contain standard negative pledge, cross-acceleration, and collective action clauses (CACs).

Sheet Earnings Deck & Guidance
B2: Pearl Petroleum (PEARL) — Earnings Presentation & Management Guidance
B3: Source: Latest Investor Presentation | Reporting Currency: USD
B5: I. MANAGEMENT STRATEGIC GUIDANCE TRACKER & VARIANCE ANALYSIS
B6: Strategic Guidance Metric | C6: Company Target / Commitment | D6: Current Run-Rate | E6: Tracking Status | F6: Guidance Variance & Verification Question to Ask CFO
B7: KM250 Capacity Ramp & Gas Deliveries | C7: 750 MMscfd total processing capacity reached and sustained | D7: 720-740 MMscfd operational throughput | E7: Achieved / On Track | F7: KM250 Train 3 successfully commissioned; deliveries to KRG at ~655 MMscfd and Federal Iraq at 100 MMscfd. [QUESTION TO CFO TO VERIFY]: With KM250 now operational, can you confirm sustained daily run-rate across both KRG and Kirkuk lines?
B8: KRG Receivables Collection Rate | C8: 100% current billing collection + amortization of legacy arrears | D8: Current invoices paid periodically; historical arrears persist >3 years | E8: Lagging / Under Watch | F8: Federal budget transfers from Baghdad to Erbil remain subject to political delays. [QUESTION TO CFO TO VERIFY]: What is the expected timeline for KRG to clear remaining overdue receivables following Baghdad budget disbursements?
B10: II. CAPITAL ALLOCATION & STRATEGIC PROJECT PIPELINE
B11: Project / Capital Dimension | C11: Disclosure & Execution Milestone
B13: III. GEOGRAPHIC & CURRENCY EXPOSURE MATRIX
B14: Exposure Category | C14: Contractual / Balance Sheet Profile
B16: IV. CONTRACT BACKLOG & COMMERCIAL MOAT
B17: Dimension | C17: Commercial / Asset Metrics
B19: V. LIQUIDITY WATERFALL & HEADROOM
B20: Liquidity Component | C20: Available Buffer / Runway
B22: INSTITUTIONAL MANAGEMENT QUESTIONS & CONVICTION DRIVERS (1-ON-1 DUE DILIGENCE)
B23: Focus Area | C23: Question to Ask CFO / Management | F23: Credit Relevance & Deduced Ambiguity | H23: Conviction Trigger & Decision Rule
B24: Federal MOE (Kirkuk) Settlement Rail & FX Trapping | C24: Under the 100 MMscf/d Kirkuk Gas Sales Agreement commenced in August 2026, what is the precise settlement currency, paying entity, and clearance channel? Are payments settled in unencumbered offshore USD through the Trade Bank of Iraq (TBI) and the NY Fed clearance window, or are funds credited in Iraqi Dinars (IQD) at the official CBI rate (1,310 IQD) subject to central bank conversion queues? If the KRG attempts to interfere with the physical valve at the border, does the MOE contract contain an enforceable sovereign take-or-pay guarantee backed by federal oil revenues? | F24: Determines whether the Kirkuk contract provides clean, hard-currency cash flow diversification or traps cash in local dinar banking rails. | H24: Direct USD offshore clearance warrants High-conviction Overweight; trapped IQD requires higher spread cushion.
B25: Condensate Local Realizations & Off-take Clearing | C25: With the Iraq-Turkey Pipeline (ITP) closed since March 2023, what is the exact netback clearing mechanism for Khor Mor's ~18,000 bpd of condensate? What is the current realized dollar discount to Dated Brent across your primary local buyers (e.g., KAR Group / Bazian refinery), and what percentage of this revenue is received in clean cash versus non-cash offsets against KRG power invoices or local diesel barter? | F25: Condensate represents the primary liquid margin generator; deep discounts directly reduce FCF conversion. | H25: Realized discount under $18/bbl in cash supports credit rating upgrade; barter/offsets exceeding 40% flags working capital leakage.
B26: U.S. DFC Intercreditor Covenants & Political Violence Acceleration Triggers | C26: Under the Intercreditor Agreement governing the $250M U.S. DFC facility and the $350M 13% Nordic bond, what are the specific 'force majeure / cessation of operations' covenant triggers? Does the DFC hold unilateral acceleration or cash sweep rights if drone strikes result in an operational shut-in exceeding 30 consecutive days, and does DFC approval require a minimum debt-service coverage ratio (DSCR) before any cash dividends can be upstreamed to Dana Gas and Crescent Petroleum? | F26: Intercreditor priority dictates whether bondholders are subordinated to sovereign DFI acceleration in a severe security crisis. | H26: Pari passu standstill covenants protect bondholders; unilateral DFC cash sweeps create severe refinancing risk.
B27: Enerflex EPC Contract Settlement & Standby Cost Allocation | C27: Following the April 2024 fatal drone strike and Enerflex's invocation of Force Majeure and demobilization, what were the final confidential commercial settlement terms with Enerflex? How much in demobilization claims, standby fees, and contractor acceleration premiums were incurred, and were these costs capitalized into the final $1.1B project cost or expensed through the P&L? | F27: Reveals whether hidden contractor liabilities or contingent arbitration claims remain unresolved. | H27: Full and final mutual release with zero residual liability secures clean balance sheet.
B28: C-RAM & Air Defense Operational Cost Allocation | C28: Following the installation of counter-drone and air defense systems at Khor Mor in late 2024/2025, how are the ongoing operational, radar maintenance, and ammunition replenishment costs allocated? Are these costs borne directly by Pearl Petroleum as operating expenses (reducing net entitlement cash flow), or are they funded under a bilateral sovereign defense agreement between the U.S. Government and the Iraqi Ministry of Defense? | F28: Air defense operating costs in hostile frontier environments can add millions to annual operating overhead. | H28: Sovereign-funded military protection insulates OPEX from security inflation.
B29: KRG Receivables Overdue Threshold & DSRA Cash Lock-Up | C29: Under the Nordic ABM bond terms (NO0013387860), what is the explicit Days Sales Outstanding (DSO) or overdue receivables dollar cap that triggers a Restricted Payments dividend lock-up? With KRG payment delays continuing on historical arrears, what proportion of Pearl's current $95M cash balance is trapped in mandatory Debt Service Reserve Accounts (DSRA) versus freely distributable cash to the joint venture partners? | F29: Determines true unencumbered liquidity available for bond debt service vs dividend drain. | H29: Stringent DSRA lock-up covenants protect bondholders by trapping project cash flows.
B30: European Partner Governance & Exit Pre-emption Rights | C30: Given that KM250 is fully commissioned and OMV/MOL/RWE hold 10% non-operated stakes each, have any of the European partners formally signaled intentions to exercise tag-along, drag-along, or pre-emption rights to divest their stakes to regional players, and how would a change of ownership in the 30% European block impact the change-of-control put option (at 101%) in the 2028 notes? | F30: Potential consortium reshuffling could alter governance dynamics or trigger bond put options. | H30: Stable long-term partner pact preserves institutional governance credibility.
B33: SCHEDULED EARNINGS RELEASE & INVESTOR RELATIONS CALENDAR
B34: Calendar Dimension | C34: Scheduled Detail & IR Access
B35: Next Scheduled Earnings Date | C35: 2026-11-12
B36: Reporting Period | C36: Q3 2026 / 9M
B37: Confirmation Status | C37: Estimated
B38: Conference Call & Webcast Schedule | C38: 14:00 Local / Pre-Market
B39: Official IR Portal / Webcast URL | C39: https://www.google.com/finance/quote/PEARL
